#usda 1.0
(
    customLayerData = {
        dictionary omni_layer = {
            dictionary locked = {
            }
            dictionary muteness = {
            }
        }
    }
    defaultPrim = "quadruped_robot"
    doc = """Generated from Composed Stage of root layer /home/gpuuser/GitHub/Intelligent-robot-design/generations/generation_2/robot_13.usda
"""
    metersPerUnit = 1
    upAxis = "Z"
)

def Xform "quadruped_robot"
{
    quatd xformOp:orient = (1, 0, 0, 0)
    double3 xformOp:scale = (1, 1, 1)
    double3 xformOp:translate = (0, 0, 0)
    uniform token[] xformOpOrder = ["xformOp:translate", "xformOp:orient", "xformOp:scale"]

    def Scope "Looks"
    {
    }

    def Xform "base" (
        apiSchemas = ["PhysicsRigidBodyAPI", "PhysicsMassAPI", "PhysicsArticulationRootAPI", "PhysxArticulationAPI"]
    )
    {
        point3f physics:centerOfMass = (0, 0, -0.005)
        float3 physics:diagonalInertia = (0.000028984412, 0.000028984412, 0.000028984412)
        float physics:mass = 1.7390648
        quatf physics:principalAxes = (1, 0, 0, 0)
        bool physxArticulation:enabledSelfCollisions = 1
        int physxArticulation:solverPositionIterationCount = 32
        int physxArticulation:solverVelocityIterationCount = 1
        quatd xformOp:orient = (1, 0, 0, 0)
        double3 xformOp:scale = (1, 1, 1)
        double3 xformOp:translate = (0, 0, 0)
        uniform token[] xformOpOrder = ["xformOp:translate", "xformOp:orient", "xformOp:scale"]

        def Cube "visuals"
        {
            float3[] extent = [(-0.005, -0.005, -0.005), (0.005, 0.005, 0.005)]
            double size = 1
            quatd xformOp:orient = (1, 0, 0, 0)
            double3 xformOp:scale = (0.009999999776482582, 0.009999999776482582, 0.009999999776482582)
            double3 xformOp:translate = (0, 0, 0)
            uniform token[] xformOpOrder = ["xformOp:translate", "xformOp:orient", "xformOp:scale"]
        }

        def Cube "collisions" (
            apiSchemas = ["PhysicsCollisionAPI"]
        )
        {
            float3[] extent = [(-0.005, -0.005, -0.005), (0.005, 0.005, 0.005)]
            uniform token purpose = "guide"
            double size = 1
            quatd xformOp:orient = (1, 0, 0, 0)
            double3 xformOp:scale = (0.009999999776482582, 0.009999999776482582, 0.009999999776482582)
            double3 xformOp:translate = (0, 0, 0)
            uniform token[] xformOpOrder = ["xformOp:translate", "xformOp:orient", "xformOp:scale"]
        }

        def PhysicsFixedJoint "floating_base"
        {
            rel physics:body0 = </quadruped_robot/base>
            rel physics:body1 = </quadruped_robot/trunk>
            float physics:breakForce = 3.4028235e38
            float physics:breakTorque = 3.4028235e38
            point3f physics:localPos0 = (0, 0, 0)
            point3f physics:localPos1 = (0, 0, 0)
            quatf physics:localRot0 = (1, 0, 0, 0)
            quatf physics:localRot1 = (1, 0, 0, 0)
        }
    }

    def Xform "trunk" (
        apiSchemas = ["PhysicsRigidBodyAPI", "PhysicsMassAPI"]
    )
    {
        point3f physics:centerOfMass = (0, 0, -0.089380965)
        float3 physics:diagonalInertia = (0.008294694, 0.008294694, 0.056595623)
        float physics:mass = 0.5114745
        quatf physics:principalAxes = (1, 0, 0, 0)
        quatd xformOp:orient = (1, 0, 0, 0)
        double3 xformOp:scale = (1, 1, 1)
        double3 xformOp:translate = (0, 0, 0)
        uniform token[] xformOpOrder = ["xformOp:translate", "xformOp:orient", "xformOp:scale"]

        def Cube "visuals"
        {
            float3[] extent = [(-0.53971565, -0.20164996, -0.089380965), (0.53971565, 0.20164996, 0.089380965)]
            double size = 1
            quatd xformOp:orient = (1, 0, 0, 0)
            double3 xformOp:scale = (1.0794312953948975, 0.4032999277114868, 0.17876192927360535)
            double3 xformOp:translate = (0, 0, 0)
            uniform token[] xformOpOrder = ["xformOp:translate", "xformOp:orient", "xformOp:scale"]
        }

        def Cube "collisions" (
            apiSchemas = ["PhysicsCollisionAPI"]
        )
        {
            float3[] extent = [(-0.53971565, -0.20164996, -0.089380965), (0.53971565, 0.20164996, 0.089380965)]
            uniform token purpose = "guide"
            double size = 1
            quatd xformOp:orient = (1, 0, 0, 0)
            double3 xformOp:scale = (1.0794312953948975, 0.4032999277114868, 0.17876192927360535)
            double3 xformOp:translate = (0, 0, 0)
            uniform token[] xformOpOrder = ["xformOp:translate", "xformOp:orient", "xformOp:scale"]
        }

        def PhysicsRevoluteJoint "FL_hip_joint" (
            apiSchemas = ["PhysxJointAPI", "PhysicsJointStateAPI:angular", "PhysicsDriveAPI:angular"]
        )
        {
            float drive:angular:physics:damping = 0
            float drive:angular:physics:maxForce = 60
            float drive:angular:physics:stiffness = 0
            uniform token drive:angular:physics:type = "force"
            uniform token physics:axis = "X"
            rel physics:body0 = </quadruped_robot/trunk>
            rel physics:body1 = </quadruped_robot/FL_hip>
            float physics:breakForce = 3.4028235e38
            float physics:breakTorque = 3.4028235e38
            point3f physics:localPos0 = (0.53971565, 0.20164996, -0.07150477)
            point3f physics:localPos1 = (0, 0, 0)
            quatf physics:localRot0 = (1, 0, 0, 0)
            quatf physics:localRot1 = (1, 0, 0, 0)
            float physics:lowerLimit = -180
            float physics:upperLimit = 180
            float physxJoint:maxJointVelocity = 3002.2988
        }

        def PhysicsRevoluteJoint "FR_hip_joint" (
            apiSchemas = ["PhysxJointAPI", "PhysicsJointStateAPI:angular", "PhysicsDriveAPI:angular"]
        )
        {
            float drive:angular:physics:damping = 0
            float drive:angular:physics:maxForce = 60
            float drive:angular:physics:stiffness = 0
            uniform token drive:angular:physics:type = "force"
            uniform token physics:axis = "X"
            rel physics:body0 = </quadruped_robot/trunk>
            rel physics:body1 = </quadruped_robot/FR_hip>
            float physics:breakForce = 3.4028235e38
            float physics:breakTorque = 3.4028235e38
            point3f physics:localPos0 = (0.53971565, -0.20164996, -0.07150477)
            point3f physics:localPos1 = (0, 0, 0)
            quatf physics:localRot0 = (1, 0, 0, 0)
            quatf physics:localRot1 = (1, 0, 0, 0)
            float physics:lowerLimit = -180
            float physics:upperLimit = 180
            float physxJoint:maxJointVelocity = 3002.2988
        }

        def PhysicsRevoluteJoint "RL_hip_joint" (
            apiSchemas = ["PhysxJointAPI", "PhysicsJointStateAPI:angular", "PhysicsDriveAPI:angular"]
        )
        {
            float drive:angular:physics:damping = 0
            float drive:angular:physics:maxForce = 60
            float drive:angular:physics:stiffness = 0
            uniform token drive:angular:physics:type = "force"
            uniform token physics:axis = "X"
            rel physics:body0 = </quadruped_robot/trunk>
            rel physics:body1 = </quadruped_robot/RL_hip>
            float physics:breakForce = 3.4028235e38
            float physics:breakTorque = 3.4028235e38
            point3f physics:localPos0 = (-0.53971565, 0.20164996, -0.07150477)
            point3f physics:localPos1 = (0, 0, 0)
            quatf physics:localRot0 = (1, 0, 0, 0)
            quatf physics:localRot1 = (1, 0, 0, 0)
            float physics:lowerLimit = -180
            float physics:upperLimit = 180
            float physxJoint:maxJointVelocity = 3002.2988
        }

        def PhysicsRevoluteJoint "RR_hip_joint" (
            apiSchemas = ["PhysxJointAPI", "PhysicsJointStateAPI:angular", "PhysicsDriveAPI:angular"]
        )
        {
            float drive:angular:physics:damping = 0
            float drive:angular:physics:maxForce = 60
            float drive:angular:physics:stiffness = 0
            uniform token drive:angular:physics:type = "force"
            uniform token physics:axis = "X"
            rel physics:body0 = </quadruped_robot/trunk>
            rel physics:body1 = </quadruped_robot/RR_hip>
            float physics:breakForce = 3.4028235e38
            float physics:breakTorque = 3.4028235e38
            point3f physics:localPos0 = (-0.53971565, -0.20164996, -0.07150477)
            point3f physics:localPos1 = (0, 0, 0)
            quatf physics:localRot0 = (1, 0, 0, 0)
            quatf physics:localRot1 = (1, 0, 0, 0)
            float physics:lowerLimit = -180
            float physics:upperLimit = 180
            float physxJoint:maxJointVelocity = 3002.2988
        }
    }

    def Xform "FL_hip" (
        apiSchemas = ["PhysicsRigidBodyAPI", "PhysicsMassAPI"]
    )
    {
        point3f physics:centerOfMass = (0, 0, 0.09741004)
        float3 physics:diagonalInertia = (0.003110339, 0.003110339, 0.003110339)
        float physics:mass = 0.81948364
        quatf physics:principalAxes = (1, 0, 0, 0)
        quatd xformOp:orient = (1, 0, 0, 0)
        double3 xformOp:scale = (1, 1, 1)
        double3 xformOp:translate = (0.5397156476974487, 0.2016499638557434, -0.07150477170944214)
        uniform token[] xformOpOrder = ["xformOp:translate", "xformOp:orient", "xformOp:scale"]

        def Sphere "visuals"
        {
            float3[] extent = [(-0.09741004, -0.09741004, -0.09741004), (0.09741004, 0.09741004, 0.09741004)]
            double radius = 0.09741003811359406
            quatd xformOp:orient = (1, 0, 0, 0)
            double3 xformOp:scale = (1, 1, 1)
            double3 xformOp:translate = (0, 0, 0)
            uniform token[] xformOpOrder = ["xformOp:translate", "xformOp:orient", "xformOp:scale"]
        }

        def Sphere "collisions" (
            apiSchemas = ["PhysicsCollisionAPI"]
        )
        {
            float3[] extent = [(-0.09741004, -0.09741004, -0.09741004), (0.09741004, 0.09741004, 0.09741004)]
            uniform token purpose = "guide"
            double radius = 0.09741003811359406
            quatd xformOp:orient = (1, 0, 0, 0)
            double3 xformOp:scale = (1, 1, 1)
            double3 xformOp:translate = (0, 0, 0)
            uniform token[] xformOpOrder = ["xformOp:translate", "xformOp:orient", "xformOp:scale"]
        }

        def PhysicsRevoluteJoint "FL_thigh_joint" (
            apiSchemas = ["PhysxJointAPI", "PhysicsJointStateAPI:angular", "PhysicsDriveAPI:angular"]
        )
        {
            float drive:angular:physics:damping = 0
            float drive:angular:physics:maxForce = 60
            float drive:angular:physics:stiffness = 0
            uniform token drive:angular:physics:type = "force"
            uniform token physics:axis = "Y"
            rel physics:body0 = </quadruped_robot/FL_hip>
            rel physics:body1 = </quadruped_robot/FL_thigh>
            float physics:breakForce = 3.4028235e38
            float physics:breakTorque = 3.4028235e38
            point3f physics:localPos0 = (0, 0, 0)
            point3f physics:localPos1 = (0, 0, 0)
            quatf physics:localRot0 = (1, 0, 0, 0)
            quatf physics:localRot1 = (1, 0, 0, 0)
            float physics:lowerLimit = -180
            float physics:upperLimit = 180
            float physxJoint:maxJointVelocity = 3002.2988
        }
    }

    def Xform "FL_thigh" (
        apiSchemas = ["PhysicsRigidBodyAPI", "PhysicsMassAPI"]
    )
    {
        point3f physics:centerOfMass = (0, 0, -0.2909403)
        float3 physics:diagonalInertia = (0.04919584, 0.04919584, 0.007630631)
        float physics:mass = 1.608359
        quatf physics:principalAxes = (1, 0, 0, 0)
        quatd xformOp:orient = (1, 0, 0, 0)
        double3 xformOp:scale = (1, 1, 1)
        double3 xformOp:translate = (0.5397156476974487, 0.2016499638557434, -0.07150477170944214)
        uniform token[] xformOpOrder = ["xformOp:translate", "xformOp:orient", "xformOp:scale"]

        def Cylinder "visuals"
        {
            uniform token axis = "Z"
            float3[] extent = [(-0.09741004, -0.09741004, -0.2909403), (0.09741004, 0.09741004, 0.2909403)]
            double height = 0.5818806290626526
            double radius = 0.09741003811359406
            quatd xformOp:orient = (1, 0, 0, 0)
            double3 xformOp:scale = (1, 1, 1)
            double3 xformOp:translate = (0, 0, -0.2909403145313263)
            uniform token[] xformOpOrder = ["xformOp:translate", "xformOp:orient", "xformOp:scale"]
        }

        def Cylinder "collisions" (
            apiSchemas = ["PhysicsCollisionAPI"]
        )
        {
            uniform token axis = "Z"
            float3[] extent = [(-0.09741004, -0.09741004, -0.2909403), (0.09741004, 0.09741004, 0.2909403)]
            double height = 0.5818806290626526
            uniform token purpose = "guide"
            double radius = 0.09741003811359406
            quatd xformOp:orient = (1, 0, 0, 0)
            double3 xformOp:scale = (1, 1, 1)
            double3 xformOp:translate = (0, 0, -0.2909403145313263)
            uniform token[] xformOpOrder = ["xformOp:translate", "xformOp:orient", "xformOp:scale"]
        }

        def PhysicsFixedJoint "FL_knee_joint"
        {
            rel physics:body0 = </quadruped_robot/FL_thigh>
            rel physics:body1 = </quadruped_robot/FL_knee>
            float physics:breakForce = 3.4028235e38
            float physics:breakTorque = 3.4028235e38
            point3f physics:localPos0 = (0, 0, -0.5818806)
            point3f physics:localPos1 = (0, 0, 0)
            quatf physics:localRot0 = (1, 0, 0, 0)
            quatf physics:localRot1 = (1, 0, 0, 0)
        }
    }

    def Xform "FL_knee" (
        apiSchemas = ["PhysicsRigidBodyAPI", "PhysicsMassAPI"]
    )
    {
        point3f physics:centerOfMass = (0, 0, 0.09741004)
        float3 physics:diagonalInertia = (0.0067478823, 0.0067478823, 0.0067478823)
        float physics:mass = 1.7778703
        quatf physics:principalAxes = (1, 0, 0, 0)
        quatd xformOp:orient = (1, 0, 0, 0)
        double3 xformOp:scale = (1, 1, 1)
        double3 xformOp:translate = (0.5397156476974487, 0.2016499638557434, -0.6533854007720947)
        uniform token[] xformOpOrder = ["xformOp:translate", "xformOp:orient", "xformOp:scale"]

        def Sphere "visuals"
        {
            float3[] extent = [(-0.09741004, -0.09741004, -0.09741004), (0.09741004, 0.09741004, 0.09741004)]
            double radius = 0.09741003811359406
            quatd xformOp:orient = (1, 0, 0, 0)
            double3 xformOp:scale = (1, 1, 1)
            double3 xformOp:translate = (0, 0, 0)
            uniform token[] xformOpOrder = ["xformOp:translate", "xformOp:orient", "xformOp:scale"]
        }

        def Sphere "collisions" (
            apiSchemas = ["PhysicsCollisionAPI"]
        )
        {
            float3[] extent = [(-0.09741004, -0.09741004, -0.09741004), (0.09741004, 0.09741004, 0.09741004)]
            uniform token purpose = "guide"
            double radius = 0.09741003811359406
            quatd xformOp:orient = (1, 0, 0, 0)
            double3 xformOp:scale = (1, 1, 1)
            double3 xformOp:translate = (0, 0, 0)
            uniform token[] xformOpOrder = ["xformOp:translate", "xformOp:orient", "xformOp:scale"]
        }

        def PhysicsRevoluteJoint "FL_calf_joint" (
            apiSchemas = ["PhysxJointAPI", "PhysicsJointStateAPI:angular", "PhysicsDriveAPI:angular"]
        )
        {
            float drive:angular:physics:damping = 0
            float drive:angular:physics:maxForce = 60
            float drive:angular:physics:stiffness = 0
            uniform token drive:angular:physics:type = "force"
            uniform token physics:axis = "Y"
            rel physics:body0 = </quadruped_robot/FL_knee>
            rel physics:body1 = </quadruped_robot/FL_calf>
            float physics:breakForce = 3.4028235e38
            float physics:breakTorque = 3.4028235e38
            point3f physics:localPos0 = (0, 0, 0)
            point3f physics:localPos1 = (0, 0, 0)
            quatf physics:localRot0 = (1, 0, 0, 0)
            quatf physics:localRot1 = (1, 0, 0, 0)
            float physics:lowerLimit = -180
            float physics:upperLimit = 180
            float physxJoint:maxJointVelocity = 3002.2988
        }
    }

    def Xform "FL_calf" (
        apiSchemas = ["PhysicsRigidBodyAPI", "PhysicsMassAPI"]
    )
    {
        point3f physics:centerOfMass = (0, 0, -0.23557721)
        float3 physics:diagonalInertia = (0.022606418, 0.022606418, 0.004656589)
        float physics:mass = 1.0961815
        quatf physics:principalAxes = (1, 0, 0, 0)
        quatd xformOp:orient = (1, 0, 0, 0)
        double3 xformOp:scale = (1, 1, 1)
        double3 xformOp:translate = (0.5397156476974487, 0.2016499638557434, -0.6533854007720947)
        uniform token[] xformOpOrder = ["xformOp:translate", "xformOp:orient", "xformOp:scale"]

        def Cylinder "visuals"
        {
            uniform token axis = "Z"
            float3[] extent = [(-0.09217385, -0.09217385, -0.23557721), (0.09217385, 0.09217385, 0.23557721)]
            double height = 0.47115442156791687
            double radius = 0.09217385202646255
            quatd xformOp:orient = (1, 0, 0, 0)
            double3 xformOp:scale = (1, 1, 1)
            double3 xformOp:translate = (0, 0, -0.23557721078395844)
            uniform token[] xformOpOrder = ["xformOp:translate", "xformOp:orient", "xformOp:scale"]
        }

        def Cylinder "collisions" (
            apiSchemas = ["PhysicsCollisionAPI"]
        )
        {
            uniform token axis = "Z"
            float3[] extent = [(-0.09217385, -0.09217385, -0.23557721), (0.09217385, 0.09217385, 0.23557721)]
            double height = 0.47115442156791687
            uniform token purpose = "guide"
            double radius = 0.09217385202646255
            quatd xformOp:orient = (1, 0, 0, 0)
            double3 xformOp:scale = (1, 1, 1)
            double3 xformOp:translate = (0, 0, -0.23557721078395844)
            uniform token[] xformOpOrder = ["xformOp:translate", "xformOp:orient", "xformOp:scale"]
        }

        def PhysicsFixedJoint "FL_foot_joint"
        {
            rel physics:body0 = </quadruped_robot/FL_calf>
            rel physics:body1 = </quadruped_robot/FL_foot>
            float physics:breakForce = 3.4028235e38
            float physics:breakTorque = 3.4028235e38
            point3f physics:localPos0 = (0, 0, -0.47115442)
            point3f physics:localPos1 = (0, 0, 0)
            quatf physics:localRot0 = (1, 0, 0, 0)
            quatf physics:localRot1 = (1, 0, 0, 0)
        }
    }

    def Xform "FL_foot" (
        apiSchemas = ["PhysicsRigidBodyAPI", "PhysicsMassAPI"]
    )
    {
        point3f physics:centerOfMass = (0, 0, 0.06452169)
        float3 physics:diagonalInertia = (0.0029897618, 0.0029897618, 0.0029897618)
        float physics:mass = 1.7954159
        quatf physics:principalAxes = (1, 0, 0, 0)
        quatd xformOp:orient = (1, 0, 0, 0)
        double3 xformOp:scale = (1, 1, 1)
        double3 xformOp:translate = (0.5397156476974487, 0.2016499638557434, -1.124539852142334)
        uniform token[] xformOpOrder = ["xformOp:translate", "xformOp:orient", "xformOp:scale"]

        def Sphere "visuals"
        {
            float3[] extent = [(-0.06452169, -0.06452169, -0.06452169), (0.06452169, 0.06452169, 0.06452169)]
            double radius = 0.06452169269323349
            quatd xformOp:orient = (1, 0, 0, 0)
            double3 xformOp:scale = (1, 1, 1)
            double3 xformOp:translate = (0, 0, 0)
            uniform token[] xformOpOrder = ["xformOp:translate", "xformOp:orient", "xformOp:scale"]
        }

        def Sphere "collisions" (
            apiSchemas = ["PhysicsCollisionAPI"]
        )
        {
            float3[] extent = [(-0.06452169, -0.06452169, -0.06452169), (0.06452169, 0.06452169, 0.06452169)]
            uniform token purpose = "guide"
            double radius = 0.06452169269323349
            quatd xformOp:orient = (1, 0, 0, 0)
            double3 xformOp:scale = (1, 1, 1)
            double3 xformOp:translate = (0, 0, 0)
            uniform token[] xformOpOrder = ["xformOp:translate", "xformOp:orient", "xformOp:scale"]
        }
    }

    def Xform "FR_hip" (
        apiSchemas = ["PhysicsRigidBodyAPI", "PhysicsMassAPI"]
    )
    {
        point3f physics:centerOfMass = (0, 0, 0.09741004)
        float3 physics:diagonalInertia = (0.0053495932, 0.0053495932, 0.0053495932)
        float physics:mass = 1.4094619
        quatf physics:principalAxes = (1, 0, 0, 0)
        quatd xformOp:orient = (1, 0, 0, 0)
        double3 xformOp:scale = (1, 1, 1)
        double3 xformOp:translate = (0.5397156476974487, -0.2016499638557434, -0.07150477170944214)
        uniform token[] xformOpOrder = ["xformOp:translate", "xformOp:orient", "xformOp:scale"]

        def Sphere "visuals"
        {
            float3[] extent = [(-0.09741004, -0.09741004, -0.09741004), (0.09741004, 0.09741004, 0.09741004)]
            double radius = 0.09741003811359406
            quatd xformOp:orient = (1, 0, 0, 0)
            double3 xformOp:scale = (1, 1, 1)
            double3 xformOp:translate = (0, 0, 0)
            uniform token[] xformOpOrder = ["xformOp:translate", "xformOp:orient", "xformOp:scale"]
        }

        def Sphere "collisions" (
            apiSchemas = ["PhysicsCollisionAPI"]
        )
        {
            float3[] extent = [(-0.09741004, -0.09741004, -0.09741004), (0.09741004, 0.09741004, 0.09741004)]
            uniform token purpose = "guide"
            double radius = 0.09741003811359406
            quatd xformOp:orient = (1, 0, 0, 0)
            double3 xformOp:scale = (1, 1, 1)
            double3 xformOp:translate = (0, 0, 0)
            uniform token[] xformOpOrder = ["xformOp:translate", "xformOp:orient", "xformOp:scale"]
        }

        def PhysicsRevoluteJoint "FR_thigh_joint" (
            apiSchemas = ["PhysxJointAPI", "PhysicsJointStateAPI:angular", "PhysicsDriveAPI:angular"]
        )
        {
            float drive:angular:physics:damping = 0
            float drive:angular:physics:maxForce = 60
            float drive:angular:physics:stiffness = 0
            uniform token drive:angular:physics:type = "force"
            uniform token physics:axis = "Y"
            rel physics:body0 = </quadruped_robot/FR_hip>
            rel physics:body1 = </quadruped_robot/FR_thigh>
            float physics:breakForce = 3.4028235e38
            float physics:breakTorque = 3.4028235e38
            point3f physics:localPos0 = (0, 0, 0)
            point3f physics:localPos1 = (0, 0, 0)
            quatf physics:localRot0 = (1, 0, 0, 0)
            quatf physics:localRot1 = (1, 0, 0, 0)
            float physics:lowerLimit = -180
            float physics:upperLimit = 180
            float physxJoint:maxJointVelocity = 3002.2988
        }
    }

    def Xform "FR_thigh" (
        apiSchemas = ["PhysicsRigidBodyAPI", "PhysicsMassAPI"]
    )
    {
        point3f physics:centerOfMass = (0, 0, -0.2909403)
        float3 physics:diagonalInertia = (0.047756333, 0.047756333, 0.007407353)
        float physics:mass = 1.5612972
        quatf physics:principalAxes = (1, 0, 0, 0)
        quatd xformOp:orient = (1, 0, 0, 0)
        double3 xformOp:scale = (1, 1, 1)
        double3 xformOp:translate = (0.5397156476974487, -0.2016499638557434, -0.07150477170944214)
        uniform token[] xformOpOrder = ["xformOp:translate", "xformOp:orient", "xformOp:scale"]

        def Cylinder "visuals"
        {
            uniform token axis = "Z"
            float3[] extent = [(-0.09741004, -0.09741004, -0.2909403), (0.09741004, 0.09741004, 0.2909403)]
            double height = 0.5818806290626526
            double radius = 0.09741003811359406
            quatd xformOp:orient = (1, 0, 0, 0)
            double3 xformOp:scale = (1, 1, 1)
            double3 xformOp:translate = (0, 0, -0.2909403145313263)
            uniform token[] xformOpOrder = ["xformOp:translate", "xformOp:orient", "xformOp:scale"]
        }

        def Cylinder "collisions" (
            apiSchemas = ["PhysicsCollisionAPI"]
        )
        {
            uniform token axis = "Z"
            float3[] extent = [(-0.09741004, -0.09741004, -0.2909403), (0.09741004, 0.09741004, 0.2909403)]
            double height = 0.5818806290626526
            uniform token purpose = "guide"
            double radius = 0.09741003811359406
            quatd xformOp:orient = (1, 0, 0, 0)
            double3 xformOp:scale = (1, 1, 1)
            double3 xformOp:translate = (0, 0, -0.2909403145313263)
            uniform token[] xformOpOrder = ["xformOp:translate", "xformOp:orient", "xformOp:scale"]
        }

        def PhysicsFixedJoint "FR_knee_joint"
        {
            rel physics:body0 = </quadruped_robot/FR_thigh>
            rel physics:body1 = </quadruped_robot/FR_knee>
            float physics:breakForce = 3.4028235e38
            float physics:breakTorque = 3.4028235e38
            point3f physics:localPos0 = (0, 0, -0.5818806)
            point3f physics:localPos1 = (0, 0, 0)
            quatf physics:localRot0 = (1, 0, 0, 0)
            quatf physics:localRot1 = (1, 0, 0, 0)
        }
    }

    def Xform "FR_knee" (
        apiSchemas = ["PhysicsRigidBodyAPI", "PhysicsMassAPI"]
    )
    {
        point3f physics:centerOfMass = (0, 0, 0.09741004)
        float3 physics:diagonalInertia = (0.0028020584, 0.0028020584, 0.0028020584)
        float physics:mass = 0.7382606
        quatf physics:principalAxes = (1, 0, 0, 0)
        quatd xformOp:orient = (1, 0, 0, 0)
        double3 xformOp:scale = (1, 1, 1)
        double3 xformOp:translate = (0.5397156476974487, -0.2016499638557434, -0.6533854007720947)
        uniform token[] xformOpOrder = ["xformOp:translate", "xformOp:orient", "xformOp:scale"]

        def Sphere "visuals"
        {
            float3[] extent = [(-0.09741004, -0.09741004, -0.09741004), (0.09741004, 0.09741004, 0.09741004)]
            double radius = 0.09741003811359406
            quatd xformOp:orient = (1, 0, 0, 0)
            double3 xformOp:scale = (1, 1, 1)
            double3 xformOp:translate = (0, 0, 0)
            uniform token[] xformOpOrder = ["xformOp:translate", "xformOp:orient", "xformOp:scale"]
        }

        def Sphere "collisions" (
            apiSchemas = ["PhysicsCollisionAPI"]
        )
        {
            float3[] extent = [(-0.09741004, -0.09741004, -0.09741004), (0.09741004, 0.09741004, 0.09741004)]
            uniform token purpose = "guide"
            double radius = 0.09741003811359406
            quatd xformOp:orient = (1, 0, 0, 0)
            double3 xformOp:scale = (1, 1, 1)
            double3 xformOp:translate = (0, 0, 0)
            uniform token[] xformOpOrder = ["xformOp:translate", "xformOp:orient", "xformOp:scale"]
        }

        def PhysicsRevoluteJoint "FR_calf_joint" (
            apiSchemas = ["PhysxJointAPI", "PhysicsJointStateAPI:angular", "PhysicsDriveAPI:angular"]
        )
        {
            float drive:angular:physics:damping = 0
            float drive:angular:physics:maxForce = 60
            float drive:angular:physics:stiffness = 0
            uniform token drive:angular:physics:type = "force"
            uniform token physics:axis = "Y"
            rel physics:body0 = </quadruped_robot/FR_knee>
            rel physics:body1 = </quadruped_robot/FR_calf>
            float physics:breakForce = 3.4028235e38
            float physics:breakTorque = 3.4028235e38
            point3f physics:localPos0 = (0, 0, 0)
            point3f physics:localPos1 = (0, 0, 0)
            quatf physics:localRot0 = (1, 0, 0, 0)
            quatf physics:localRot1 = (1, 0, 0, 0)
            float physics:lowerLimit = -180
            float physics:upperLimit = 180
            float physxJoint:maxJointVelocity = 3002.2988
        }
    }

    def Xform "FR_calf" (
        apiSchemas = ["PhysicsRigidBodyAPI", "PhysicsMassAPI"]
    )
    {
        point3f physics:centerOfMass = (0, 0, -0.23557721)
        float3 physics:diagonalInertia = (0.0139059005, 0.0139059005, 0.0028644109)
        float physics:mass = 0.6742949
        quatf physics:principalAxes = (1, 0, 0, 0)
        quatd xformOp:orient = (1, 0, 0, 0)
        double3 xformOp:scale = (1, 1, 1)
        double3 xformOp:translate = (0.5397156476974487, -0.2016499638557434, -0.6533854007720947)
        uniform token[] xformOpOrder = ["xformOp:translate", "xformOp:orient", "xformOp:scale"]

        def Cylinder "visuals"
        {
            uniform token axis = "Z"
            float3[] extent = [(-0.09217385, -0.09217385, -0.23557721), (0.09217385, 0.09217385, 0.23557721)]
            double height = 0.47115442156791687
            double radius = 0.09217385202646255
            quatd xformOp:orient = (1, 0, 0, 0)
            double3 xformOp:scale = (1, 1, 1)
            double3 xformOp:translate = (0, 0, -0.23557721078395844)
            uniform token[] xformOpOrder = ["xformOp:translate", "xformOp:orient", "xformOp:scale"]
        }

        def Cylinder "collisions" (
            apiSchemas = ["PhysicsCollisionAPI"]
        )
        {
            uniform token axis = "Z"
            float3[] extent = [(-0.09217385, -0.09217385, -0.23557721), (0.09217385, 0.09217385, 0.23557721)]
            double height = 0.47115442156791687
            uniform token purpose = "guide"
            double radius = 0.09217385202646255
            quatd xformOp:orient = (1, 0, 0, 0)
            double3 xformOp:scale = (1, 1, 1)
            double3 xformOp:translate = (0, 0, -0.23557721078395844)
            uniform token[] xformOpOrder = ["xformOp:translate", "xformOp:orient", "xformOp:scale"]
        }

        def PhysicsFixedJoint "FR_foot_joint"
        {
            rel physics:body0 = </quadruped_robot/FR_calf>
            rel physics:body1 = </quadruped_robot/FR_foot>
            float physics:breakForce = 3.4028235e38
            float physics:breakTorque = 3.4028235e38
            point3f physics:localPos0 = (0, 0, -0.47115442)
            point3f physics:localPos1 = (0, 0, 0)
            quatf physics:localRot0 = (1, 0, 0, 0)
            quatf physics:localRot1 = (1, 0, 0, 0)
        }
    }

    def Xform "FR_foot" (
        apiSchemas = ["PhysicsRigidBodyAPI", "PhysicsMassAPI"]
    )
    {
        point3f physics:centerOfMass = (0, 0, 0.06452169)
        float3 physics:diagonalInertia = (0.0026267918, 0.0026267918, 0.0026267918)
        float physics:mass = 1.5774447
        quatf physics:principalAxes = (1, 0, 0, 0)
        quatd xformOp:orient = (1, 0, 0, 0)
        double3 xformOp:scale = (1, 1, 1)
        double3 xformOp:translate = (0.5397156476974487, -0.2016499638557434, -1.124539852142334)
        uniform token[] xformOpOrder = ["xformOp:translate", "xformOp:orient", "xformOp:scale"]

        def Sphere "visuals"
        {
            float3[] extent = [(-0.06452169, -0.06452169, -0.06452169), (0.06452169, 0.06452169, 0.06452169)]
            double radius = 0.06452169269323349
            quatd xformOp:orient = (1, 0, 0, 0)
            double3 xformOp:scale = (1, 1, 1)
            double3 xformOp:translate = (0, 0, 0)
            uniform token[] xformOpOrder = ["xformOp:translate", "xformOp:orient", "xformOp:scale"]
        }

        def Sphere "collisions" (
            apiSchemas = ["PhysicsCollisionAPI"]
        )
        {
            float3[] extent = [(-0.06452169, -0.06452169, -0.06452169), (0.06452169, 0.06452169, 0.06452169)]
            uniform token purpose = "guide"
            double radius = 0.06452169269323349
            quatd xformOp:orient = (1, 0, 0, 0)
            double3 xformOp:scale = (1, 1, 1)
            double3 xformOp:translate = (0, 0, 0)
            uniform token[] xformOpOrder = ["xformOp:translate", "xformOp:orient", "xformOp:scale"]
        }
    }

    def Xform "RL_hip" (
        apiSchemas = ["PhysicsRigidBodyAPI", "PhysicsMassAPI"]
    )
    {
        point3f physics:centerOfMass = (0, 0, 0.08110928)
        float3 physics:diagonalInertia = (0.00321659, 0.00321659, 0.00321659)
        float physics:mass = 1.2223474
        quatf physics:principalAxes = (1, 0, 0, 0)
        quatd xformOp:orient = (1, 0, 0, 0)
        double3 xformOp:scale = (1, 1, 1)
        double3 xformOp:translate = (-0.5397156476974487, 0.2016499638557434, -0.07150477170944214)
        uniform token[] xformOpOrder = ["xformOp:translate", "xformOp:orient", "xformOp:scale"]

        def Sphere "visuals"
        {
            float3[] extent = [(-0.08110928, -0.08110928, -0.08110928), (0.08110928, 0.08110928, 0.08110928)]
            double radius = 0.08110927790403366
            quatd xformOp:orient = (1, 0, 0, 0)
            double3 xformOp:scale = (1, 1, 1)
            double3 xformOp:translate = (0, 0, 0)
            uniform token[] xformOpOrder = ["xformOp:translate", "xformOp:orient", "xformOp:scale"]
        }

        def Sphere "collisions" (
            apiSchemas = ["PhysicsCollisionAPI"]
        )
        {
            float3[] extent = [(-0.08110928, -0.08110928, -0.08110928), (0.08110928, 0.08110928, 0.08110928)]
            uniform token purpose = "guide"
            double radius = 0.08110927790403366
            quatd xformOp:orient = (1, 0, 0, 0)
            double3 xformOp:scale = (1, 1, 1)
            double3 xformOp:translate = (0, 0, 0)
            uniform token[] xformOpOrder = ["xformOp:translate", "xformOp:orient", "xformOp:scale"]
        }

        def PhysicsRevoluteJoint "RL_thigh_joint" (
            apiSchemas = ["PhysxJointAPI", "PhysicsJointStateAPI:angular", "PhysicsDriveAPI:angular"]
        )
        {
            float drive:angular:physics:damping = 0
            float drive:angular:physics:maxForce = 60
            float drive:angular:physics:stiffness = 0
            uniform token drive:angular:physics:type = "force"
            uniform token physics:axis = "Y"
            rel physics:body0 = </quadruped_robot/RL_hip>
            rel physics:body1 = </quadruped_robot/RL_thigh>
            float physics:breakForce = 3.4028235e38
            float physics:breakTorque = 3.4028235e38
            point3f physics:localPos0 = (0, 0, 0)
            point3f physics:localPos1 = (0, 0, 0)
            quatf physics:localRot0 = (1, 0, 0, 0)
            quatf physics:localRot1 = (1, 0, 0, 0)
            float physics:lowerLimit = -180
            float physics:upperLimit = 180
            float physxJoint:maxJointVelocity = 3002.2988
        }
    }

    def Xform "RL_thigh" (
        apiSchemas = ["PhysicsRigidBodyAPI", "PhysicsMassAPI"]
    )
    {
        point3f physics:centerOfMass = (0, 0, -0.20697032)
        float3 physics:diagonalInertia = (0.026024798, 0.026024798, 0.00537598)
        float physics:mass = 1.6343557
        quatf physics:principalAxes = (1, 0, 0, 0)
        quatd xformOp:orient = (1, 0, 0, 0)
        double3 xformOp:scale = (1, 1, 1)
        double3 xformOp:translate = (-0.5397156476974487, 0.2016499638557434, -0.07150477170944214)
        uniform token[] xformOpOrder = ["xformOp:translate", "xformOp:orient", "xformOp:scale"]

        def Cylinder "visuals"
        {
            uniform token axis = "Z"
            float3[] extent = [(-0.08110928, -0.08110928, -0.20697032), (0.08110928, 0.08110928, 0.20697032)]
            double height = 0.4139406383037567
            double radius = 0.08110927790403366
            quatd xformOp:orient = (1, 0, 0, 0)
            double3 xformOp:scale = (1, 1, 1)
            double3 xformOp:translate = (0, 0, -0.20697031915187836)
            uniform token[] xformOpOrder = ["xformOp:translate", "xformOp:orient", "xformOp:scale"]
        }

        def Cylinder "collisions" (
            apiSchemas = ["PhysicsCollisionAPI"]
        )
        {
            uniform token axis = "Z"
            float3[] extent = [(-0.08110928, -0.08110928, -0.20697032), (0.08110928, 0.08110928, 0.20697032)]
            double height = 0.4139406383037567
            uniform token purpose = "guide"
            double radius = 0.08110927790403366
            quatd xformOp:orient = (1, 0, 0, 0)
            double3 xformOp:scale = (1, 1, 1)
            double3 xformOp:translate = (0, 0, -0.20697031915187836)
            uniform token[] xformOpOrder = ["xformOp:translate", "xformOp:orient", "xformOp:scale"]
        }

        def PhysicsFixedJoint "RL_knee_joint"
        {
            rel physics:body0 = </quadruped_robot/RL_thigh>
            rel physics:body1 = </quadruped_robot/RL_knee>
            float physics:breakForce = 3.4028235e38
            float physics:breakTorque = 3.4028235e38
            point3f physics:localPos0 = (0, 0, -0.41394064)
            point3f physics:localPos1 = (0, 0, 0)
            quatf physics:localRot0 = (1, 0, 0, 0)
            quatf physics:localRot1 = (1, 0, 0, 0)
        }
    }

    def Xform "RL_knee" (
        apiSchemas = ["PhysicsRigidBodyAPI", "PhysicsMassAPI"]
    )
    {
        point3f physics:centerOfMass = (0, 0, 0.09738035)
        float3 physics:diagonalInertia = (0.0062466743, 0.0062466743, 0.0062466743)
        float physics:mass = 1.6468204
        quatf physics:principalAxes = (1, 0, 0, 0)
        quatd xformOp:orient = (1, 0, 0, 0)
        double3 xformOp:scale = (1, 1, 1)
        double3 xformOp:translate = (-0.5397156476974487, 0.2016499638557434, -0.48544541001319885)
        uniform token[] xformOpOrder = ["xformOp:translate", "xformOp:orient", "xformOp:scale"]

        def Sphere "visuals"
        {
            float3[] extent = [(-0.09738035, -0.09738035, -0.09738035), (0.09738035, 0.09738035, 0.09738035)]
            double radius = 0.09738034754991531
            quatd xformOp:orient = (1, 0, 0, 0)
            double3 xformOp:scale = (1, 1, 1)
            double3 xformOp:translate = (0, 0, 0)
            uniform token[] xformOpOrder = ["xformOp:translate", "xformOp:orient", "xformOp:scale"]
        }

        def Sphere "collisions" (
            apiSchemas = ["PhysicsCollisionAPI"]
        )
        {
            float3[] extent = [(-0.09738035, -0.09738035, -0.09738035), (0.09738035, 0.09738035, 0.09738035)]
            uniform token purpose = "guide"
            double radius = 0.09738034754991531
            quatd xformOp:orient = (1, 0, 0, 0)
            double3 xformOp:scale = (1, 1, 1)
            double3 xformOp:translate = (0, 0, 0)
            uniform token[] xformOpOrder = ["xformOp:translate", "xformOp:orient", "xformOp:scale"]
        }

        def PhysicsRevoluteJoint "RL_calf_joint" (
            apiSchemas = ["PhysxJointAPI", "PhysicsJointStateAPI:angular", "PhysicsDriveAPI:angular"]
        )
        {
            float drive:angular:physics:damping = 0
            float drive:angular:physics:maxForce = 60
            float drive:angular:physics:stiffness = 0
            uniform token drive:angular:physics:type = "force"
            uniform token physics:axis = "Y"
            rel physics:body0 = </quadruped_robot/RL_knee>
            rel physics:body1 = </quadruped_robot/RL_calf>
            float physics:breakForce = 3.4028235e38
            float physics:breakTorque = 3.4028235e38
            point3f physics:localPos0 = (0, 0, 0)
            point3f physics:localPos1 = (0, 0, 0)
            quatf physics:localRot0 = (1, 0, 0, 0)
            quatf physics:localRot1 = (1, 0, 0, 0)
            float physics:lowerLimit = -180
            float physics:upperLimit = 180
            float physxJoint:maxJointVelocity = 3002.2988
        }
    }

    def Xform "RL_calf" (
        apiSchemas = ["PhysicsRigidBodyAPI", "PhysicsMassAPI"]
    )
    {
        point3f physics:centerOfMass = (0, 0, -0.23519482)
        float3 physics:diagonalInertia = (0.018413052, 0.018413052, 0.0041954126)
        float physics:mass = 0.8848345
        quatf physics:principalAxes = (1, 0, 0, 0)
        quatd xformOp:orient = (1, 0, 0, 0)
        double3 xformOp:scale = (1, 1, 1)
        double3 xformOp:translate = (-0.5397156476974487, 0.2016499638557434, -0.48544541001319885)
        uniform token[] xformOpOrder = ["xformOp:translate", "xformOp:orient", "xformOp:scale"]

        def Cylinder "visuals"
        {
            uniform token axis = "Z"
            float3[] extent = [(-0.09738035, -0.09738035, -0.23519482), (0.09738035, 0.09738035, 0.23519482)]
            double height = 0.47038963437080383
            double radius = 0.09738034754991531
            quatd xformOp:orient = (1, 0, 0, 0)
            double3 xformOp:scale = (1, 1, 1)
            double3 xformOp:translate = (0, 0, -0.23519481718540192)
            uniform token[] xformOpOrder = ["xformOp:translate", "xformOp:orient", "xformOp:scale"]
        }

        def Cylinder "collisions" (
            apiSchemas = ["PhysicsCollisionAPI"]
        )
        {
            uniform token axis = "Z"
            float3[] extent = [(-0.09738035, -0.09738035, -0.23519482), (0.09738035, 0.09738035, 0.23519482)]
            double height = 0.47038963437080383
            uniform token purpose = "guide"
            double radius = 0.09738034754991531
            quatd xformOp:orient = (1, 0, 0, 0)
            double3 xformOp:scale = (1, 1, 1)
            double3 xformOp:translate = (0, 0, -0.23519481718540192)
            uniform token[] xformOpOrder = ["xformOp:translate", "xformOp:orient", "xformOp:scale"]
        }

        def PhysicsFixedJoint "RL_foot_joint"
        {
            rel physics:body0 = </quadruped_robot/RL_calf>
            rel physics:body1 = </quadruped_robot/RL_foot>
            float physics:breakForce = 3.4028235e38
            float physics:breakTorque = 3.4028235e38
            point3f physics:localPos0 = (0, 0, -0.47038963)
            point3f physics:localPos1 = (0, 0, 0)
            quatf physics:localRot0 = (1, 0, 0, 0)
            quatf physics:localRot1 = (1, 0, 0, 0)
        }
    }

    def Xform "RL_foot" (
        apiSchemas = ["PhysicsRigidBodyAPI", "PhysicsMassAPI"]
    )
    {
        point3f physics:centerOfMass = (0, 0, 0.06452169)
        float3 physics:diagonalInertia = (0.0022423319, 0.0022423319, 0.0022423319)
        float physics:mass = 1.3465682
        quatf physics:principalAxes = (1, 0, 0, 0)
        quatd xformOp:orient = (1, 0, 0, 0)
        double3 xformOp:scale = (1, 1, 1)
        double3 xformOp:translate = (-0.5397156476974487, 0.2016499638557434, -0.9558350443840027)
        uniform token[] xformOpOrder = ["xformOp:translate", "xformOp:orient", "xformOp:scale"]

        def Sphere "visuals"
        {
            float3[] extent = [(-0.06452169, -0.06452169, -0.06452169), (0.06452169, 0.06452169, 0.06452169)]
            double radius = 0.06452169269323349
            quatd xformOp:orient = (1, 0, 0, 0)
            double3 xformOp:scale = (1, 1, 1)
            double3 xformOp:translate = (0, 0, 0)
            uniform token[] xformOpOrder = ["xformOp:translate", "xformOp:orient", "xformOp:scale"]
        }

        def Sphere "collisions" (
            apiSchemas = ["PhysicsCollisionAPI"]
        )
        {
            float3[] extent = [(-0.06452169, -0.06452169, -0.06452169), (0.06452169, 0.06452169, 0.06452169)]
            uniform token purpose = "guide"
            double radius = 0.06452169269323349
            quatd xformOp:orient = (1, 0, 0, 0)
            double3 xformOp:scale = (1, 1, 1)
            double3 xformOp:translate = (0, 0, 0)
            uniform token[] xformOpOrder = ["xformOp:translate", "xformOp:orient", "xformOp:scale"]
        }
    }

    def Xform "RR_hip" (
        apiSchemas = ["PhysicsRigidBodyAPI", "PhysicsMassAPI"]
    )
    {
        point3f physics:centerOfMass = (0, 0, 0.08110928)
        float3 physics:diagonalInertia = (0.0047970186, 0.0047970186, 0.0047970186)
        float physics:mass = 1.8229314
        quatf physics:principalAxes = (1, 0, 0, 0)
        quatd xformOp:orient = (1, 0, 0, 0)
        double3 xformOp:scale = (1, 1, 1)
        double3 xformOp:translate = (-0.5397156476974487, -0.2016499638557434, -0.07150477170944214)
        uniform token[] xformOpOrder = ["xformOp:translate", "xformOp:orient", "xformOp:scale"]

        def Sphere "visuals"
        {
            float3[] extent = [(-0.08110928, -0.08110928, -0.08110928), (0.08110928, 0.08110928, 0.08110928)]
            double radius = 0.08110927790403366
            quatd xformOp:orient = (1, 0, 0, 0)
            double3 xformOp:scale = (1, 1, 1)
            double3 xformOp:translate = (0, 0, 0)
            uniform token[] xformOpOrder = ["xformOp:translate", "xformOp:orient", "xformOp:scale"]
        }

        def Sphere "collisions" (
            apiSchemas = ["PhysicsCollisionAPI"]
        )
        {
            float3[] extent = [(-0.08110928, -0.08110928, -0.08110928), (0.08110928, 0.08110928, 0.08110928)]
            uniform token purpose = "guide"
            double radius = 0.08110927790403366
            quatd xformOp:orient = (1, 0, 0, 0)
            double3 xformOp:scale = (1, 1, 1)
            double3 xformOp:translate = (0, 0, 0)
            uniform token[] xformOpOrder = ["xformOp:translate", "xformOp:orient", "xformOp:scale"]
        }

        def PhysicsRevoluteJoint "RR_thigh_joint" (
            apiSchemas = ["PhysxJointAPI", "PhysicsJointStateAPI:angular", "PhysicsDriveAPI:angular"]
        )
        {
            float drive:angular:physics:damping = 0
            float drive:angular:physics:maxForce = 60
            float drive:angular:physics:stiffness = 0
            uniform token drive:angular:physics:type = "force"
            uniform token physics:axis = "Y"
            rel physics:body0 = </quadruped_robot/RR_hip>
            rel physics:body1 = </quadruped_robot/RR_thigh>
            float physics:breakForce = 3.4028235e38
            float physics:breakTorque = 3.4028235e38
            point3f physics:localPos0 = (0, 0, 0)
            point3f physics:localPos1 = (0, 0, 0)
            quatf physics:localRot0 = (1, 0, 0, 0)
            quatf physics:localRot1 = (1, 0, 0, 0)
            float physics:lowerLimit = -180
            float physics:upperLimit = 180
            float physxJoint:maxJointVelocity = 3002.2988
        }
    }

    def Xform "RR_thigh" (
        apiSchemas = ["PhysicsRigidBodyAPI", "PhysicsMassAPI"]
    )
    {
        point3f physics:centerOfMass = (0, 0, -0.20697032)
        float3 physics:diagonalInertia = (0.028203208, 0.028203208, 0.0058259773)
        float physics:mass = 1.7711598
        quatf physics:principalAxes = (1, 0, 0, 0)
        quatd xformOp:orient = (1, 0, 0, 0)
        double3 xformOp:scale = (1, 1, 1)
        double3 xformOp:translate = (-0.5397156476974487, -0.2016499638557434, -0.07150477170944214)
        uniform token[] xformOpOrder = ["xformOp:translate", "xformOp:orient", "xformOp:scale"]

        def Cylinder "visuals"
        {
            uniform token axis = "Z"
            float3[] extent = [(-0.08110928, -0.08110928, -0.20697032), (0.08110928, 0.08110928, 0.20697032)]
            double height = 0.4139406383037567
            double radius = 0.08110927790403366
            quatd xformOp:orient = (1, 0, 0, 0)
            double3 xformOp:scale = (1, 1, 1)
            double3 xformOp:translate = (0, 0, -0.20697031915187836)
            uniform token[] xformOpOrder = ["xformOp:translate", "xformOp:orient", "xformOp:scale"]
        }

        def Cylinder "collisions" (
            apiSchemas = ["PhysicsCollisionAPI"]
        )
        {
            uniform token axis = "Z"
            float3[] extent = [(-0.08110928, -0.08110928, -0.20697032), (0.08110928, 0.08110928, 0.20697032)]
            double height = 0.4139406383037567
            uniform token purpose = "guide"
            double radius = 0.08110927790403366
            quatd xformOp:orient = (1, 0, 0, 0)
            double3 xformOp:scale = (1, 1, 1)
            double3 xformOp:translate = (0, 0, -0.20697031915187836)
            uniform token[] xformOpOrder = ["xformOp:translate", "xformOp:orient", "xformOp:scale"]
        }

        def PhysicsFixedJoint "RR_knee_joint"
        {
            rel physics:body0 = </quadruped_robot/RR_thigh>
            rel physics:body1 = </quadruped_robot/RR_knee>
            float physics:breakForce = 3.4028235e38
            float physics:breakTorque = 3.4028235e38
            point3f physics:localPos0 = (0, 0, -0.41394064)
            point3f physics:localPos1 = (0, 0, 0)
            quatf physics:localRot0 = (1, 0, 0, 0)
            quatf physics:localRot1 = (1, 0, 0, 0)
        }
    }

    def Xform "RR_knee" (
        apiSchemas = ["PhysicsRigidBodyAPI", "PhysicsMassAPI"]
    )
    {
        point3f physics:centerOfMass = (0, 0, 0.09738035)
        float3 physics:diagonalInertia = (0.006308236, 0.006308236, 0.006308236)
        float physics:mass = 1.6630499
        quatf physics:principalAxes = (1, 0, 0, 0)
        quatd xformOp:orient = (1, 0, 0, 0)
        double3 xformOp:scale = (1, 1, 1)
        double3 xformOp:translate = (-0.5397156476974487, -0.2016499638557434, -0.48544541001319885)
        uniform token[] xformOpOrder = ["xformOp:translate", "xformOp:orient", "xformOp:scale"]

        def Sphere "visuals"
        {
            float3[] extent = [(-0.09738035, -0.09738035, -0.09738035), (0.09738035, 0.09738035, 0.09738035)]
            double radius = 0.09738034754991531
            quatd xformOp:orient = (1, 0, 0, 0)
            double3 xformOp:scale = (1, 1, 1)
            double3 xformOp:translate = (0, 0, 0)
            uniform token[] xformOpOrder = ["xformOp:translate", "xformOp:orient", "xformOp:scale"]
        }

        def Sphere "collisions" (
            apiSchemas = ["PhysicsCollisionAPI"]
        )
        {
            float3[] extent = [(-0.09738035, -0.09738035, -0.09738035), (0.09738035, 0.09738035, 0.09738035)]
            uniform token purpose = "guide"
            double radius = 0.09738034754991531
            quatd xformOp:orient = (1, 0, 0, 0)
            double3 xformOp:scale = (1, 1, 1)
            double3 xformOp:translate = (0, 0, 0)
            uniform token[] xformOpOrder = ["xformOp:translate", "xformOp:orient", "xformOp:scale"]
        }

        def PhysicsRevoluteJoint "RR_calf_joint" (
            apiSchemas = ["PhysxJointAPI", "PhysicsJointStateAPI:angular", "PhysicsDriveAPI:angular"]
        )
        {
            float drive:angular:physics:damping = 0
            float drive:angular:physics:maxForce = 60
            float drive:angular:physics:stiffness = 0
            uniform token drive:angular:physics:type = "force"
            uniform token physics:axis = "Y"
            rel physics:body0 = </quadruped_robot/RR_knee>
            rel physics:body1 = </quadruped_robot/RR_calf>
            float physics:breakForce = 3.4028235e38
            float physics:breakTorque = 3.4028235e38
            point3f physics:localPos0 = (0, 0, 0)
            point3f physics:localPos1 = (0, 0, 0)
            quatf physics:localRot0 = (1, 0, 0, 0)
            quatf physics:localRot1 = (1, 0, 0, 0)
            float physics:lowerLimit = -180
            float physics:upperLimit = 180
            float physxJoint:maxJointVelocity = 3002.2988
        }
    }

    def Xform "RR_calf" (
        apiSchemas = ["PhysicsRigidBodyAPI", "PhysicsMassAPI"]
    )
    {
        point3f physics:centerOfMass = (0, 0, -0.23519482)
        float3 physics:diagonalInertia = (0.03206268, 0.03206268, 0.007305479)
        float physics:mass = 1.5407639
        quatf physics:principalAxes = (1, 0, 0, 0)
        quatd xformOp:orient = (1, 0, 0, 0)
        double3 xformOp:scale = (1, 1, 1)
        double3 xformOp:translate = (-0.5397156476974487, -0.2016499638557434, -0.48544541001319885)
        uniform token[] xformOpOrder = ["xformOp:translate", "xformOp:orient", "xformOp:scale"]

        def Cylinder "visuals"
        {
            uniform token axis = "Z"
            float3[] extent = [(-0.09738035, -0.09738035, -0.23519482), (0.09738035, 0.09738035, 0.23519482)]
            double height = 0.47038963437080383
            double radius = 0.09738034754991531
            quatd xformOp:orient = (1, 0, 0, 0)
            double3 xformOp:scale = (1, 1, 1)
            double3 xformOp:translate = (0, 0, -0.23519481718540192)
            uniform token[] xformOpOrder = ["xformOp:translate", "xformOp:orient", "xformOp:scale"]
        }

        def Cylinder "collisions" (
            apiSchemas = ["PhysicsCollisionAPI"]
        )
        {
            uniform token axis = "Z"
            float3[] extent = [(-0.09738035, -0.09738035, -0.23519482), (0.09738035, 0.09738035, 0.23519482)]
            double height = 0.47038963437080383
            uniform token purpose = "guide"
            double radius = 0.09738034754991531
            quatd xformOp:orient = (1, 0, 0, 0)
            double3 xformOp:scale = (1, 1, 1)
            double3 xformOp:translate = (0, 0, -0.23519481718540192)
            uniform token[] xformOpOrder = ["xformOp:translate", "xformOp:orient", "xformOp:scale"]
        }

        def PhysicsFixedJoint "RR_foot_joint"
        {
            rel physics:body0 = </quadruped_robot/RR_calf>
            rel physics:body1 = </quadruped_robot/RR_foot>
            float physics:breakForce = 3.4028235e38
            float physics:breakTorque = 3.4028235e38
            point3f physics:localPos0 = (0, 0, -0.47038963)
            point3f physics:localPos1 = (0, 0, 0)
            quatf physics:localRot0 = (1, 0, 0, 0)
            quatf physics:localRot1 = (1, 0, 0, 0)
        }
    }

    def Xform "RR_foot" (
        apiSchemas = ["PhysicsRigidBodyAPI", "PhysicsMassAPI"]
    )
    {
        point3f physics:centerOfMass = (0, 0, 0.06452169)
        float3 physics:diagonalInertia = (0.0032776294, 0.0032776294, 0.0032776294)
        float physics:mass = 1.9682866
        quatf physics:principalAxes = (1, 0, 0, 0)
        quatd xformOp:orient = (1, 0, 0, 0)
        double3 xformOp:scale = (1, 1, 1)
        double3 xformOp:translate = (-0.5397156476974487, -0.2016499638557434, -0.9558350443840027)
        uniform token[] xformOpOrder = ["xformOp:translate", "xformOp:orient", "xformOp:scale"]

        def Sphere "visuals"
        {
            float3[] extent = [(-0.06452169, -0.06452169, -0.06452169), (0.06452169, 0.06452169, 0.06452169)]
            double radius = 0.06452169269323349
            quatd xformOp:orient = (1, 0, 0, 0)
            double3 xformOp:scale = (1, 1, 1)
            double3 xformOp:translate = (0, 0, 0)
            uniform token[] xformOpOrder = ["xformOp:translate", "xformOp:orient", "xformOp:scale"]
        }

        def Sphere "collisions" (
            apiSchemas = ["PhysicsCollisionAPI"]
        )
        {
            float3[] extent = [(-0.06452169, -0.06452169, -0.06452169), (0.06452169, 0.06452169, 0.06452169)]
            uniform token purpose = "guide"
            double radius = 0.06452169269323349
            quatd xformOp:orient = (1, 0, 0, 0)
            double3 xformOp:scale = (1, 1, 1)
            double3 xformOp:translate = (0, 0, 0)
            uniform token[] xformOpOrder = ["xformOp:translate", "xformOp:orient", "xformOp:scale"]
        }
    }
}

