#usda 1.0
(
    customLayerData = {
        dictionary omni_layer = {
            dictionary locked = {
            }
            dictionary muteness = {
            }
        }
    }
    defaultPrim = "quadruped_robot"
    doc = """Generated from Composed Stage of root layer /home/gpuuser/GitHub/varyMorph/generations/generation_0/robot_2.usda
"""
    metersPerUnit = 1
    upAxis = "Z"
)

def Xform "quadruped_robot"
{
    quatd xformOp:orient = (1, 0, 0, 0)
    double3 xformOp:scale = (1, 1, 1)
    double3 xformOp:translate = (0, 0, 0)
    uniform token[] xformOpOrder = ["xformOp:translate", "xformOp:orient", "xformOp:scale"]

    def Scope "Looks"
    {
    }

    def Xform "base" (
        apiSchemas = ["PhysicsRigidBodyAPI", "PhysicsMassAPI", "PhysicsArticulationRootAPI", "PhysxArticulationAPI"]
    )
    {
        point3f physics:centerOfMass = (0, 0, -0.0039801556)
        float physics:mass = 1.1698323
        bool physxArticulation:enabledSelfCollisions = 1
        int physxArticulation:solverPositionIterationCount = 32
        int physxArticulation:solverVelocityIterationCount = 1
        quatd xformOp:orient = (1, 0, 0, 0)
        double3 xformOp:scale = (1, 1, 1)
        double3 xformOp:translate = (0, 0, 0)
        uniform token[] xformOpOrder = ["xformOp:translate", "xformOp:orient", "xformOp:scale"]

        def Cube "visuals"
        {
            float3[] extent = [(-0.005, -0.005, -0.005), (0.005, 0.005, 0.005)]
            double size = 1
            quatd xformOp:orient = (1, 0, 0, 0)
            double3 xformOp:scale = (0.009999999776482582, 0.009999999776482582, 0.009999999776482582)
            double3 xformOp:translate = (0, 0, 0)
            uniform token[] xformOpOrder = ["xformOp:translate", "xformOp:orient", "xformOp:scale"]
        }

        def Cube "collisions" (
            apiSchemas = ["PhysicsCollisionAPI"]
        )
        {
            float3[] extent = [(-0.005, -0.005, -0.005), (0.005, 0.005, 0.005)]
            uniform token purpose = "guide"
            double size = 1
            quatd xformOp:orient = (1, 0, 0, 0)
            double3 xformOp:scale = (0.009999999776482582, 0.009999999776482582, 0.009999999776482582)
            double3 xformOp:translate = (0, 0, 0)
            uniform token[] xformOpOrder = ["xformOp:translate", "xformOp:orient", "xformOp:scale"]
        }

        def PhysicsFixedJoint "floating_base"
        {
            rel physics:body0 = </quadruped_robot/base>
            rel physics:body1 = </quadruped_robot/trunk>
            float physics:breakForce = 3.4028235e38
            float physics:breakTorque = 3.4028235e38
            point3f physics:localPos0 = (0, 0, 0)
            point3f physics:localPos1 = (0, 0, 0)
            quatf physics:localRot0 = (1, 0, 0, 0)
            quatf physics:localRot1 = (1, 0, 0, 0)
        }
    }

    def Xform "trunk" (
        apiSchemas = ["PhysicsRigidBodyAPI", "PhysicsMassAPI"]
    )
    {
        point3f physics:centerOfMass = (0, 0, -0.1930851)
        float physics:mass = 1.4208739
        quatd xformOp:orient = (1, 0, 0, 0)
        double3 xformOp:scale = (1, 1, 1)
        double3 xformOp:translate = (0, 0, 0)
        uniform token[] xformOpOrder = ["xformOp:translate", "xformOp:orient", "xformOp:scale"]

        def Cube "visuals"
        {
            float3[] extent = [(-0.50827146, -0.3293201, -0.13554887), (0.50827146, 0.3293201, 0.13554887)]
            double size = 1
            quatd xformOp:orient = (1, 0, 0, 0)
            double3 xformOp:scale = (1.016542911529541, 0.6586402058601379, 0.27109774947166443)
            double3 xformOp:translate = (0, 0, 0)
            uniform token[] xformOpOrder = ["xformOp:translate", "xformOp:orient", "xformOp:scale"]
        }

        def Cube "collisions" (
            apiSchemas = ["PhysicsCollisionAPI"]
        )
        {
            float3[] extent = [(-0.50827146, -0.3293201, -0.13554887), (0.50827146, 0.3293201, 0.13554887)]
            uniform token purpose = "guide"
            double size = 1
            quatd xformOp:orient = (1, 0, 0, 0)
            double3 xformOp:scale = (1.016542911529541, 0.6586402058601379, 0.27109774947166443)
            double3 xformOp:translate = (0, 0, 0)
            uniform token[] xformOpOrder = ["xformOp:translate", "xformOp:orient", "xformOp:scale"]
        }

        def PhysicsRevoluteJoint "leg_0_hip_joint" (
            apiSchemas = ["PhysxJointAPI", "PhysicsJointStateAPI:angular", "PhysicsDriveAPI:angular"]
        )
        {
            float drive:angular:physics:damping = 0
            float drive:angular:physics:maxForce = 60
            float drive:angular:physics:stiffness = 0
            uniform token drive:angular:physics:type = "force"
            uniform token physics:axis = "X"
            rel physics:body0 = </quadruped_robot/trunk>
            rel physics:body1 = </quadruped_robot/leg_0_hip>
            float physics:breakForce = 3.4028235e38
            float physics:breakTorque = 3.4028235e38
            point3f physics:localPos0 = (0.50827146, -0.3293201, -0.1084391)
            point3f physics:localPos1 = (0, 0, 0)
            quatf physics:localRot0 = (1, 0, 0, 0)
            quatf physics:localRot1 = (1, 0, 0, 0)
            float physics:lowerLimit = -180
            float physics:upperLimit = 180
            float physxJoint:maxJointVelocity = 3002.2988
        }

        def PhysicsRevoluteJoint "leg_1_hip_joint" (
            apiSchemas = ["PhysxJointAPI", "PhysicsJointStateAPI:angular", "PhysicsDriveAPI:angular"]
        )
        {
            float drive:angular:physics:damping = 0
            float drive:angular:physics:maxForce = 60
            float drive:angular:physics:stiffness = 0
            uniform token drive:angular:physics:type = "force"
            uniform token physics:axis = "X"
            rel physics:body0 = </quadruped_robot/trunk>
            rel physics:body1 = </quadruped_robot/leg_1_hip>
            float physics:breakForce = 3.4028235e38
            float physics:breakTorque = 3.4028235e38
            point3f physics:localPos0 = (0.50827146, 0.3293201, -0.1084391)
            point3f physics:localPos1 = (0, 0, 0)
            quatf physics:localRot0 = (1, 0, 0, 0)
            quatf physics:localRot1 = (1, 0, 0, 0)
            float physics:lowerLimit = -180
            float physics:upperLimit = 180
            float physxJoint:maxJointVelocity = 3002.2988
        }

        def PhysicsRevoluteJoint "leg_2_hip_joint" (
            apiSchemas = ["PhysxJointAPI", "PhysicsJointStateAPI:angular", "PhysicsDriveAPI:angular"]
        )
        {
            float drive:angular:physics:damping = 0
            float drive:angular:physics:maxForce = 60
            float drive:angular:physics:stiffness = 0
            uniform token drive:angular:physics:type = "force"
            uniform token physics:axis = "X"
            rel physics:body0 = </quadruped_robot/trunk>
            rel physics:body1 = </quadruped_robot/leg_2_hip>
            float physics:breakForce = 3.4028235e38
            float physics:breakTorque = 3.4028235e38
            point3f physics:localPos0 = (0, -0.3293201, -0.1084391)
            point3f physics:localPos1 = (0, 0, 0)
            quatf physics:localRot0 = (1, 0, 0, 0)
            quatf physics:localRot1 = (1, 0, 0, 0)
            float physics:lowerLimit = -180
            float physics:upperLimit = 180
            float physxJoint:maxJointVelocity = 3002.2988
        }

        def PhysicsRevoluteJoint "leg_3_hip_joint" (
            apiSchemas = ["PhysxJointAPI", "PhysicsJointStateAPI:angular", "PhysicsDriveAPI:angular"]
        )
        {
            float drive:angular:physics:damping = 0
            float drive:angular:physics:maxForce = 60
            float drive:angular:physics:stiffness = 0
            uniform token drive:angular:physics:type = "force"
            uniform token physics:axis = "X"
            rel physics:body0 = </quadruped_robot/trunk>
            rel physics:body1 = </quadruped_robot/leg_3_hip>
            float physics:breakForce = 3.4028235e38
            float physics:breakTorque = 3.4028235e38
            point3f physics:localPos0 = (0, 0.3293201, -0.1084391)
            point3f physics:localPos1 = (0, 0, 0)
            quatf physics:localRot0 = (1, 0, 0, 0)
            quatf physics:localRot1 = (1, 0, 0, 0)
            float physics:lowerLimit = -180
            float physics:upperLimit = 180
            float physxJoint:maxJointVelocity = 3002.2988
        }

        def PhysicsRevoluteJoint "leg_4_hip_joint" (
            apiSchemas = ["PhysxJointAPI", "PhysicsJointStateAPI:angular", "PhysicsDriveAPI:angular"]
        )
        {
            float drive:angular:physics:damping = 0
            float drive:angular:physics:maxForce = 60
            float drive:angular:physics:stiffness = 0
            uniform token drive:angular:physics:type = "force"
            uniform token physics:axis = "X"
            rel physics:body0 = </quadruped_robot/trunk>
            rel physics:body1 = </quadruped_robot/leg_4_hip>
            float physics:breakForce = 3.4028235e38
            float physics:breakTorque = 3.4028235e38
            point3f physics:localPos0 = (-0.50827146, -0.3293201, -0.1084391)
            point3f physics:localPos1 = (0, 0, 0)
            quatf physics:localRot0 = (1, 0, 0, 0)
            quatf physics:localRot1 = (1, 0, 0, 0)
            float physics:lowerLimit = -180
            float physics:upperLimit = 180
            float physxJoint:maxJointVelocity = 3002.2988
        }

        def PhysicsRevoluteJoint "leg_5_hip_joint" (
            apiSchemas = ["PhysxJointAPI", "PhysicsJointStateAPI:angular", "PhysicsDriveAPI:angular"]
        )
        {
            float drive:angular:physics:damping = 0
            float drive:angular:physics:maxForce = 60
            float drive:angular:physics:stiffness = 0
            uniform token drive:angular:physics:type = "force"
            uniform token physics:axis = "X"
            rel physics:body0 = </quadruped_robot/trunk>
            rel physics:body1 = </quadruped_robot/leg_5_hip>
            float physics:breakForce = 3.4028235e38
            float physics:breakTorque = 3.4028235e38
            point3f physics:localPos0 = (-0.50827146, 0.3293201, -0.1084391)
            point3f physics:localPos1 = (0, 0, 0)
            quatf physics:localRot0 = (1, 0, 0, 0)
            quatf physics:localRot1 = (1, 0, 0, 0)
            float physics:lowerLimit = -180
            float physics:upperLimit = 180
            float physxJoint:maxJointVelocity = 3002.2988
        }
    }

    def Xform "leg_0_hip" (
        apiSchemas = ["PhysicsRigidBodyAPI", "PhysicsMassAPI"]
    )
    {
        point3f physics:centerOfMass = (0, 0, 0.08061823)
        float physics:mass = 1.1792831
        quatd xformOp:orient = (1, 0, 0, 0)
        double3 xformOp:scale = (1, 1, 1)
        double3 xformOp:translate = (0.5082714557647705, -0.32932010293006897, -0.10843910276889801)
        uniform token[] xformOpOrder = ["xformOp:translate", "xformOp:orient", "xformOp:scale"]

        def Sphere "visuals"
        {
            float3[] extent = [(-0.08061823, -0.08061823, -0.08061823), (0.08061823, 0.08061823, 0.08061823)]
            double radius = 0.0806182324886322
            quatd xformOp:orient = (1, 0, 0, 0)
            double3 xformOp:scale = (1, 1, 1)
            double3 xformOp:translate = (0, 0, 0)
            uniform token[] xformOpOrder = ["xformOp:translate", "xformOp:orient", "xformOp:scale"]
        }

        def Sphere "collisions" (
            apiSchemas = ["PhysicsCollisionAPI"]
        )
        {
            float3[] extent = [(-0.08061823, -0.08061823, -0.08061823), (0.08061823, 0.08061823, 0.08061823)]
            uniform token purpose = "guide"
            double radius = 0.0806182324886322
            quatd xformOp:orient = (1, 0, 0, 0)
            double3 xformOp:scale = (1, 1, 1)
            double3 xformOp:translate = (0, 0, 0)
            uniform token[] xformOpOrder = ["xformOp:translate", "xformOp:orient", "xformOp:scale"]
        }

        def PhysicsRevoluteJoint "leg_0_thigh_joint" (
            apiSchemas = ["PhysxJointAPI", "PhysicsJointStateAPI:angular", "PhysicsDriveAPI:angular"]
        )
        {
            float drive:angular:physics:damping = 0
            float drive:angular:physics:maxForce = 60
            float drive:angular:physics:stiffness = 0
            uniform token drive:angular:physics:type = "force"
            uniform token physics:axis = "Y"
            rel physics:body0 = </quadruped_robot/leg_0_hip>
            rel physics:body1 = </quadruped_robot/leg_0_thigh>
            float physics:breakForce = 3.4028235e38
            float physics:breakTorque = 3.4028235e38
            point3f physics:localPos0 = (0, 0, 0)
            point3f physics:localPos1 = (0, 0, 0)
            quatf physics:localRot0 = (1, 0, 0, 0)
            quatf physics:localRot1 = (1, 0, 0, 0)
            float physics:lowerLimit = -180
            float physics:upperLimit = 180
            float physxJoint:maxJointVelocity = 3002.2988
        }
    }

    def Xform "leg_0_thigh" (
        apiSchemas = ["PhysicsRigidBodyAPI", "PhysicsMassAPI"]
    )
    {
        point3f physics:centerOfMass = (0, 0, -0.19482899)
        float physics:mass = 1.2128737
        quatd xformOp:orient = (1, 0, 0, 0)
        double3 xformOp:scale = (1, 1, 1)
        double3 xformOp:translate = (0.5082714557647705, -0.32932010293006897, -0.10843910276889801)
        uniform token[] xformOpOrder = ["xformOp:translate", "xformOp:orient", "xformOp:scale"]

        def Cylinder "visuals"
        {
            uniform token axis = "Z"
            float3[] extent = [(-0.08061823, -0.08061823, -0.35134733), (0.08061823, 0.08061823, 0.35134733)]
            double height = 0.7026946544647217
            double radius = 0.0806182324886322
            quatd xformOp:orient = (1, 0, 0, 0)
            double3 xformOp:scale = (1, 1, 1)
            double3 xformOp:translate = (0, 0, -0.35134732723236084)
            uniform token[] xformOpOrder = ["xformOp:translate", "xformOp:orient", "xformOp:scale"]
        }

        def Cylinder "collisions" (
            apiSchemas = ["PhysicsCollisionAPI"]
        )
        {
            uniform token axis = "Z"
            float3[] extent = [(-0.08061823, -0.08061823, -0.35134733), (0.08061823, 0.08061823, 0.35134733)]
            double height = 0.7026946544647217
            uniform token purpose = "guide"
            double radius = 0.0806182324886322
            quatd xformOp:orient = (1, 0, 0, 0)
            double3 xformOp:scale = (1, 1, 1)
            double3 xformOp:translate = (0, 0, -0.35134732723236084)
            uniform token[] xformOpOrder = ["xformOp:translate", "xformOp:orient", "xformOp:scale"]
        }

        def PhysicsFixedJoint "leg_0_knee_joint"
        {
            rel physics:body0 = </quadruped_robot/leg_0_thigh>
            rel physics:body1 = </quadruped_robot/leg_0_knee>
            float physics:breakForce = 3.4028235e38
            float physics:breakTorque = 3.4028235e38
            point3f physics:localPos0 = (0, 0, -0.70269465)
            point3f physics:localPos1 = (0, 0, 0)
            quatf physics:localRot0 = (1, 0, 0, 0)
            quatf physics:localRot1 = (1, 0, 0, 0)
        }
    }

    def Xform "leg_0_knee" (
        apiSchemas = ["PhysicsRigidBodyAPI", "PhysicsMassAPI"]
    )
    {
        point3f physics:centerOfMass = (0, 0, 0.087385155)
        float physics:mass = 1.3555416
        quatd xformOp:orient = (1, 0, 0, 0)
        double3 xformOp:scale = (1, 1, 1)
        double3 xformOp:translate = (0.5082714557647705, -0.32932010293006897, -0.8111337423324585)
        uniform token[] xformOpOrder = ["xformOp:translate", "xformOp:orient", "xformOp:scale"]

        def Sphere "visuals"
        {
            float3[] extent = [(-0.087385155, -0.087385155, -0.087385155), (0.087385155, 0.087385155, 0.087385155)]
            double radius = 0.0873851552605629
            quatd xformOp:orient = (1, 0, 0, 0)
            double3 xformOp:scale = (1, 1, 1)
            double3 xformOp:translate = (0, 0, 0)
            uniform token[] xformOpOrder = ["xformOp:translate", "xformOp:orient", "xformOp:scale"]
        }

        def Sphere "collisions" (
            apiSchemas = ["PhysicsCollisionAPI"]
        )
        {
            float3[] extent = [(-0.087385155, -0.087385155, -0.087385155), (0.087385155, 0.087385155, 0.087385155)]
            uniform token purpose = "guide"
            double radius = 0.0873851552605629
            quatd xformOp:orient = (1, 0, 0, 0)
            double3 xformOp:scale = (1, 1, 1)
            double3 xformOp:translate = (0, 0, 0)
            uniform token[] xformOpOrder = ["xformOp:translate", "xformOp:orient", "xformOp:scale"]
        }

        def PhysicsRevoluteJoint "leg_0_calf_joint" (
            apiSchemas = ["PhysxJointAPI", "PhysicsJointStateAPI:angular", "PhysicsDriveAPI:angular"]
        )
        {
            float drive:angular:physics:damping = 0
            float drive:angular:physics:maxForce = 60
            float drive:angular:physics:stiffness = 0
            uniform token drive:angular:physics:type = "force"
            uniform token physics:axis = "Y"
            rel physics:body0 = </quadruped_robot/leg_0_knee>
            rel physics:body1 = </quadruped_robot/leg_0_calf>
            float physics:breakForce = 3.4028235e38
            float physics:breakTorque = 3.4028235e38
            point3f physics:localPos0 = (0, 0, 0)
            point3f physics:localPos1 = (0, 0, 0)
            quatf physics:localRot0 = (1, 0, 0, 0)
            quatf physics:localRot1 = (1, 0, 0, 0)
            float physics:lowerLimit = -180
            float physics:upperLimit = 180
            float physxJoint:maxJointVelocity = 3002.2988
        }
    }

    def Xform "leg_0_calf" (
        apiSchemas = ["PhysicsRigidBodyAPI", "PhysicsMassAPI"]
    )
    {
        point3f physics:centerOfMass = (0, 0, -0.5721407)
        float physics:mass = 1.2232217
        quatd xformOp:orient = (1, 0, 0, 0)
        double3 xformOp:scale = (1, 1, 1)
        double3 xformOp:translate = (0.5082714557647705, -0.32932010293006897, -0.8111337423324585)
        uniform token[] xformOpOrder = ["xformOp:translate", "xformOp:orient", "xformOp:scale"]

        def Cylinder "visuals"
        {
            uniform token axis = "Z"
            float3[] extent = [(-0.087385155, -0.087385155, -0.4394342), (0.087385155, 0.087385155, 0.4394342)]
            double height = 0.8788684010505676
            double radius = 0.0873851552605629
            quatd xformOp:orient = (1, 0, 0, 0)
            double3 xformOp:scale = (1, 1, 1)
            double3 xformOp:translate = (0, 0, -0.4394342005252838)
            uniform token[] xformOpOrder = ["xformOp:translate", "xformOp:orient", "xformOp:scale"]
        }

        def Cylinder "collisions" (
            apiSchemas = ["PhysicsCollisionAPI"]
        )
        {
            uniform token axis = "Z"
            float3[] extent = [(-0.087385155, -0.087385155, -0.4394342), (0.087385155, 0.087385155, 0.4394342)]
            double height = 0.8788684010505676
            uniform token purpose = "guide"
            double radius = 0.0873851552605629
            quatd xformOp:orient = (1, 0, 0, 0)
            double3 xformOp:scale = (1, 1, 1)
            double3 xformOp:translate = (0, 0, -0.4394342005252838)
            uniform token[] xformOpOrder = ["xformOp:translate", "xformOp:orient", "xformOp:scale"]
        }

        def PhysicsFixedJoint "leg_0_foot_joint"
        {
            rel physics:body0 = </quadruped_robot/leg_0_calf>
            rel physics:body1 = </quadruped_robot/leg_0_foot>
            float physics:breakForce = 3.4028235e38
            float physics:breakTorque = 3.4028235e38
            point3f physics:localPos0 = (0, 0, -0.8788684)
            point3f physics:localPos1 = (0, 0, 0)
            quatf physics:localRot0 = (1, 0, 0, 0)
            quatf physics:localRot1 = (1, 0, 0, 0)
        }
    }

    def Xform "leg_0_foot" (
        apiSchemas = ["PhysicsRigidBodyAPI", "PhysicsMassAPI"]
    )
    {
        point3f physics:centerOfMass = (0, 0, 0.05643276)
        float physics:mass = 1.5003107
        quatd xformOp:orient = (1, 0, 0, 0)
        double3 xformOp:scale = (1, 1, 1)
        double3 xformOp:translate = (0.5082714557647705, -0.32932010293006897, -1.690002202987671)
        uniform token[] xformOpOrder = ["xformOp:translate", "xformOp:orient", "xformOp:scale"]

        def Sphere "visuals"
        {
            float3[] extent = [(-0.05643276, -0.05643276, -0.05643276), (0.05643276, 0.05643276, 0.05643276)]
            double radius = 0.05643276125192642
            quatd xformOp:orient = (1, 0, 0, 0)
            double3 xformOp:scale = (1, 1, 1)
            double3 xformOp:translate = (0, 0, 0)
            uniform token[] xformOpOrder = ["xformOp:translate", "xformOp:orient", "xformOp:scale"]
        }

        def Sphere "collisions" (
            apiSchemas = ["PhysicsCollisionAPI"]
        )
        {
            float3[] extent = [(-0.05643276, -0.05643276, -0.05643276), (0.05643276, 0.05643276, 0.05643276)]
            uniform token purpose = "guide"
            double radius = 0.05643276125192642
            quatd xformOp:orient = (1, 0, 0, 0)
            double3 xformOp:scale = (1, 1, 1)
            double3 xformOp:translate = (0, 0, 0)
            uniform token[] xformOpOrder = ["xformOp:translate", "xformOp:orient", "xformOp:scale"]
        }
    }

    def Xform "leg_1_hip" (
        apiSchemas = ["PhysicsRigidBodyAPI", "PhysicsMassAPI"]
    )
    {
        point3f physics:centerOfMass = (0, 0, 0.09829757)
        float physics:mass = 1.3055426
        quatd xformOp:orient = (1, 0, 0, 0)
        double3 xformOp:scale = (1, 1, 1)
        double3 xformOp:translate = (0.5082714557647705, 0.32932010293006897, -0.10843910276889801)
        uniform token[] xformOpOrder = ["xformOp:translate", "xformOp:orient", "xformOp:scale"]

        def Sphere "visuals"
        {
            float3[] extent = [(-0.09829757, -0.09829757, -0.09829757), (0.09829757, 0.09829757, 0.09829757)]
            double radius = 0.09829757362604141
            quatd xformOp:orient = (1, 0, 0, 0)
            double3 xformOp:scale = (1, 1, 1)
            double3 xformOp:translate = (0, 0, 0)
            uniform token[] xformOpOrder = ["xformOp:translate", "xformOp:orient", "xformOp:scale"]
        }

        def Sphere "collisions" (
            apiSchemas = ["PhysicsCollisionAPI"]
        )
        {
            float3[] extent = [(-0.09829757, -0.09829757, -0.09829757), (0.09829757, 0.09829757, 0.09829757)]
            uniform token purpose = "guide"
            double radius = 0.09829757362604141
            quatd xformOp:orient = (1, 0, 0, 0)
            double3 xformOp:scale = (1, 1, 1)
            double3 xformOp:translate = (0, 0, 0)
            uniform token[] xformOpOrder = ["xformOp:translate", "xformOp:orient", "xformOp:scale"]
        }

        def PhysicsRevoluteJoint "leg_1_thigh_joint" (
            apiSchemas = ["PhysxJointAPI", "PhysicsJointStateAPI:angular", "PhysicsDriveAPI:angular"]
        )
        {
            float drive:angular:physics:damping = 0
            float drive:angular:physics:maxForce = 60
            float drive:angular:physics:stiffness = 0
            uniform token drive:angular:physics:type = "force"
            uniform token physics:axis = "Y"
            rel physics:body0 = </quadruped_robot/leg_1_hip>
            rel physics:body1 = </quadruped_robot/leg_1_thigh>
            float physics:breakForce = 3.4028235e38
            float physics:breakTorque = 3.4028235e38
            point3f physics:localPos0 = (0, 0, 0)
            point3f physics:localPos1 = (0, 0, 0)
            quatf physics:localRot0 = (1, 0, 0, 0)
            quatf physics:localRot1 = (1, 0, 0, 0)
            float physics:lowerLimit = -180
            float physics:upperLimit = 180
            float physxJoint:maxJointVelocity = 3002.2988
        }
    }

    def Xform "leg_1_thigh" (
        apiSchemas = ["PhysicsRigidBodyAPI", "PhysicsMassAPI"]
    )
    {
        point3f physics:centerOfMass = (0, 0, -0.47242203)
        float physics:mass = 1.393673
        quatd xformOp:orient = (1, 0, 0, 0)
        double3 xformOp:scale = (1, 1, 1)
        double3 xformOp:translate = (0.5082714557647705, 0.32932010293006897, -0.10843910276889801)
        uniform token[] xformOpOrder = ["xformOp:translate", "xformOp:orient", "xformOp:scale"]

        def Cylinder "visuals"
        {
            uniform token axis = "Z"
            float3[] extent = [(-0.09829757, -0.09829757, -0.2652358), (0.09829757, 0.09829757, 0.2652358)]
            double height = 0.5304716229438782
            double radius = 0.09829757362604141
            quatd xformOp:orient = (1, 0, 0, 0)
            double3 xformOp:scale = (1, 1, 1)
            double3 xformOp:translate = (0, 0, -0.2652358114719391)
            uniform token[] xformOpOrder = ["xformOp:translate", "xformOp:orient", "xformOp:scale"]
        }

        def Cylinder "collisions" (
            apiSchemas = ["PhysicsCollisionAPI"]
        )
        {
            uniform token axis = "Z"
            float3[] extent = [(-0.09829757, -0.09829757, -0.2652358), (0.09829757, 0.09829757, 0.2652358)]
            double height = 0.5304716229438782
            uniform token purpose = "guide"
            double radius = 0.09829757362604141
            quatd xformOp:orient = (1, 0, 0, 0)
            double3 xformOp:scale = (1, 1, 1)
            double3 xformOp:translate = (0, 0, -0.2652358114719391)
            uniform token[] xformOpOrder = ["xformOp:translate", "xformOp:orient", "xformOp:scale"]
        }

        def PhysicsFixedJoint "leg_1_knee_joint"
        {
            rel physics:body0 = </quadruped_robot/leg_1_thigh>
            rel physics:body1 = </quadruped_robot/leg_1_knee>
            float physics:breakForce = 3.4028235e38
            float physics:breakTorque = 3.4028235e38
            point3f physics:localPos0 = (0, 0, -0.5304716)
            point3f physics:localPos1 = (0, 0, 0)
            quatf physics:localRot0 = (1, 0, 0, 0)
            quatf physics:localRot1 = (1, 0, 0, 0)
        }
    }

    def Xform "leg_1_knee" (
        apiSchemas = ["PhysicsRigidBodyAPI", "PhysicsMassAPI"]
    )
    {
        point3f physics:centerOfMass = (0, 0, 0.10686046)
        float physics:mass = 1.059022
        quatd xformOp:orient = (1, 0, 0, 0)
        double3 xformOp:scale = (1, 1, 1)
        double3 xformOp:translate = (0.5082714557647705, 0.32932010293006897, -0.638910710811615)
        uniform token[] xformOpOrder = ["xformOp:translate", "xformOp:orient", "xformOp:scale"]

        def Sphere "visuals"
        {
            float3[] extent = [(-0.10686046, -0.10686046, -0.10686046), (0.10686046, 0.10686046, 0.10686046)]
            double radius = 0.1068604588508606
            quatd xformOp:orient = (1, 0, 0, 0)
            double3 xformOp:scale = (1, 1, 1)
            double3 xformOp:translate = (0, 0, 0)
            uniform token[] xformOpOrder = ["xformOp:translate", "xformOp:orient", "xformOp:scale"]
        }

        def Sphere "collisions" (
            apiSchemas = ["PhysicsCollisionAPI"]
        )
        {
            float3[] extent = [(-0.10686046, -0.10686046, -0.10686046), (0.10686046, 0.10686046, 0.10686046)]
            uniform token purpose = "guide"
            double radius = 0.1068604588508606
            quatd xformOp:orient = (1, 0, 0, 0)
            double3 xformOp:scale = (1, 1, 1)
            double3 xformOp:translate = (0, 0, 0)
            uniform token[] xformOpOrder = ["xformOp:translate", "xformOp:orient", "xformOp:scale"]
        }

        def PhysicsRevoluteJoint "leg_1_calf_joint" (
            apiSchemas = ["PhysxJointAPI", "PhysicsJointStateAPI:angular", "PhysicsDriveAPI:angular"]
        )
        {
            float drive:angular:physics:damping = 0
            float drive:angular:physics:maxForce = 60
            float drive:angular:physics:stiffness = 0
            uniform token drive:angular:physics:type = "force"
            uniform token physics:axis = "Y"
            rel physics:body0 = </quadruped_robot/leg_1_knee>
            rel physics:body1 = </quadruped_robot/leg_1_calf>
            float physics:breakForce = 3.4028235e38
            float physics:breakTorque = 3.4028235e38
            point3f physics:localPos0 = (0, 0, 0)
            point3f physics:localPos1 = (0, 0, 0)
            quatf physics:localRot0 = (1, 0, 0, 0)
            quatf physics:localRot1 = (1, 0, 0, 0)
            float physics:lowerLimit = -180
            float physics:upperLimit = 180
            float physxJoint:maxJointVelocity = 3002.2988
        }
    }

    def Xform "leg_1_calf" (
        apiSchemas = ["PhysicsRigidBodyAPI", "PhysicsMassAPI"]
    )
    {
        point3f physics:centerOfMass = (0, 0, -0.2135085)
        float physics:mass = 0.8802204
        quatd xformOp:orient = (1, 0, 0, 0)
        double3 xformOp:scale = (1, 1, 1)
        double3 xformOp:translate = (0.5082714557647705, 0.32932010293006897, -0.638910710811615)
        uniform token[] xformOpOrder = ["xformOp:translate", "xformOp:orient", "xformOp:scale"]

        def Cylinder "visuals"
        {
            uniform token axis = "Z"
            float3[] extent = [(-0.10686046, -0.10686046, -0.3464251), (0.10686046, 0.10686046, 0.3464251)]
            double height = 0.6928501725196838
            double radius = 0.1068604588508606
            quatd xformOp:orient = (1, 0, 0, 0)
            double3 xformOp:scale = (1, 1, 1)
            double3 xformOp:translate = (0, 0, -0.3464250862598419)
            uniform token[] xformOpOrder = ["xformOp:translate", "xformOp:orient", "xformOp:scale"]
        }

        def Cylinder "collisions" (
            apiSchemas = ["PhysicsCollisionAPI"]
        )
        {
            uniform token axis = "Z"
            float3[] extent = [(-0.10686046, -0.10686046, -0.3464251), (0.10686046, 0.10686046, 0.3464251)]
            double height = 0.6928501725196838
            uniform token purpose = "guide"
            double radius = 0.1068604588508606
            quatd xformOp:orient = (1, 0, 0, 0)
            double3 xformOp:scale = (1, 1, 1)
            double3 xformOp:translate = (0, 0, -0.3464250862598419)
            uniform token[] xformOpOrder = ["xformOp:translate", "xformOp:orient", "xformOp:scale"]
        }

        def PhysicsFixedJoint "leg_1_foot_joint"
        {
            rel physics:body0 = </quadruped_robot/leg_1_calf>
            rel physics:body1 = </quadruped_robot/leg_1_foot>
            float physics:breakForce = 3.4028235e38
            float physics:breakTorque = 3.4028235e38
            point3f physics:localPos0 = (0, 0, -0.6928502)
            point3f physics:localPos1 = (0, 0, 0)
            quatf physics:localRot0 = (1, 0, 0, 0)
            quatf physics:localRot1 = (1, 0, 0, 0)
        }
    }

    def Xform "leg_1_foot" (
        apiSchemas = ["PhysicsRigidBodyAPI", "PhysicsMassAPI"]
    )
    {
        point3f physics:centerOfMass = (0, 0, 0.0688083)
        float physics:mass = 1.8245223
        quatd xformOp:orient = (1, 0, 0, 0)
        double3 xformOp:scale = (1, 1, 1)
        double3 xformOp:translate = (0.5082714557647705, 0.32932010293006897, -1.3317608833312988)
        uniform token[] xformOpOrder = ["xformOp:translate", "xformOp:orient", "xformOp:scale"]

        def Sphere "visuals"
        {
            float3[] extent = [(-0.0688083, -0.0688083, -0.0688083), (0.0688083, 0.0688083, 0.0688083)]
            double radius = 0.06880830228328705
            quatd xformOp:orient = (1, 0, 0, 0)
            double3 xformOp:scale = (1, 1, 1)
            double3 xformOp:translate = (0, 0, 0)
            uniform token[] xformOpOrder = ["xformOp:translate", "xformOp:orient", "xformOp:scale"]
        }

        def Sphere "collisions" (
            apiSchemas = ["PhysicsCollisionAPI"]
        )
        {
            float3[] extent = [(-0.0688083, -0.0688083, -0.0688083), (0.0688083, 0.0688083, 0.0688083)]
            uniform token purpose = "guide"
            double radius = 0.06880830228328705
            quatd xformOp:orient = (1, 0, 0, 0)
            double3 xformOp:scale = (1, 1, 1)
            double3 xformOp:translate = (0, 0, 0)
            uniform token[] xformOpOrder = ["xformOp:translate", "xformOp:orient", "xformOp:scale"]
        }
    }

    def Xform "leg_2_hip" (
        apiSchemas = ["PhysicsRigidBodyAPI", "PhysicsMassAPI"]
    )
    {
        point3f physics:centerOfMass = (0, 0, 0.10998273)
        float physics:mass = 1.4401609
        quatd xformOp:orient = (1, 0, 0, 0)
        double3 xformOp:scale = (1, 1, 1)
        double3 xformOp:translate = (0, -0.32932010293006897, -0.10843910276889801)
        uniform token[] xformOpOrder = ["xformOp:translate", "xformOp:orient", "xformOp:scale"]

        def Sphere "visuals"
        {
            float3[] extent = [(-0.10998273, -0.10998273, -0.10998273), (0.10998273, 0.10998273, 0.10998273)]
            double radius = 0.10998272895812988
            quatd xformOp:orient = (1, 0, 0, 0)
            double3 xformOp:scale = (1, 1, 1)
            double3 xformOp:translate = (0, 0, 0)
            uniform token[] xformOpOrder = ["xformOp:translate", "xformOp:orient", "xformOp:scale"]
        }

        def Sphere "collisions" (
            apiSchemas = ["PhysicsCollisionAPI"]
        )
        {
            float3[] extent = [(-0.10998273, -0.10998273, -0.10998273), (0.10998273, 0.10998273, 0.10998273)]
            uniform token purpose = "guide"
            double radius = 0.10998272895812988
            quatd xformOp:orient = (1, 0, 0, 0)
            double3 xformOp:scale = (1, 1, 1)
            double3 xformOp:translate = (0, 0, 0)
            uniform token[] xformOpOrder = ["xformOp:translate", "xformOp:orient", "xformOp:scale"]
        }

        def PhysicsRevoluteJoint "leg_2_thigh_joint" (
            apiSchemas = ["PhysxJointAPI", "PhysicsJointStateAPI:angular", "PhysicsDriveAPI:angular"]
        )
        {
            float drive:angular:physics:damping = 0
            float drive:angular:physics:maxForce = 60
            float drive:angular:physics:stiffness = 0
            uniform token drive:angular:physics:type = "force"
            uniform token physics:axis = "Y"
            rel physics:body0 = </quadruped_robot/leg_2_hip>
            rel physics:body1 = </quadruped_robot/leg_2_thigh>
            float physics:breakForce = 3.4028235e38
            float physics:breakTorque = 3.4028235e38
            point3f physics:localPos0 = (0, 0, 0)
            point3f physics:localPos1 = (0, 0, 0)
            quatf physics:localRot0 = (1, 0, 0, 0)
            quatf physics:localRot1 = (1, 0, 0, 0)
            float physics:lowerLimit = -180
            float physics:upperLimit = 180
            float physxJoint:maxJointVelocity = 3002.2988
        }
    }

    def Xform "leg_2_thigh" (
        apiSchemas = ["PhysicsRigidBodyAPI", "PhysicsMassAPI"]
    )
    {
        point3f physics:centerOfMass = (0, 0, -0.45003942)
        float physics:mass = 1.9594641
        quatd xformOp:orient = (1, 0, 0, 0)
        double3 xformOp:scale = (1, 1, 1)
        double3 xformOp:translate = (0, -0.32932010293006897, -0.10843910276889801)
        uniform token[] xformOpOrder = ["xformOp:translate", "xformOp:orient", "xformOp:scale"]

        def Cylinder "visuals"
        {
            uniform token axis = "Z"
            float3[] extent = [(-0.10998273, -0.10998273, -0.41527125), (0.10998273, 0.10998273, 0.41527125)]
            double height = 0.8305425047874451
            double radius = 0.10998272895812988
            quatd xformOp:orient = (1, 0, 0, 0)
            double3 xformOp:scale = (1, 1, 1)
            double3 xformOp:translate = (0, 0, -0.41527125239372253)
            uniform token[] xformOpOrder = ["xformOp:translate", "xformOp:orient", "xformOp:scale"]
        }

        def Cylinder "collisions" (
            apiSchemas = ["PhysicsCollisionAPI"]
        )
        {
            uniform token axis = "Z"
            float3[] extent = [(-0.10998273, -0.10998273, -0.41527125), (0.10998273, 0.10998273, 0.41527125)]
            double height = 0.8305425047874451
            uniform token purpose = "guide"
            double radius = 0.10998272895812988
            quatd xformOp:orient = (1, 0, 0, 0)
            double3 xformOp:scale = (1, 1, 1)
            double3 xformOp:translate = (0, 0, -0.41527125239372253)
            uniform token[] xformOpOrder = ["xformOp:translate", "xformOp:orient", "xformOp:scale"]
        }

        def PhysicsFixedJoint "leg_2_knee_joint"
        {
            rel physics:body0 = </quadruped_robot/leg_2_thigh>
            rel physics:body1 = </quadruped_robot/leg_2_knee>
            float physics:breakForce = 3.4028235e38
            float physics:breakTorque = 3.4028235e38
            point3f physics:localPos0 = (0, 0, -0.8305425)
            point3f physics:localPos1 = (0, 0, 0)
            quatf physics:localRot0 = (1, 0, 0, 0)
            quatf physics:localRot1 = (1, 0, 0, 0)
        }
    }

    def Xform "leg_2_knee" (
        apiSchemas = ["PhysicsRigidBodyAPI", "PhysicsMassAPI"]
    )
    {
        point3f physics:centerOfMass = (0, 0, 0.10998273)
        float physics:mass = 1.1778922
        quatd xformOp:orient = (1, 0, 0, 0)
        double3 xformOp:scale = (1, 1, 1)
        double3 xformOp:translate = (0, -0.32932010293006897, -0.9389815926551819)
        uniform token[] xformOpOrder = ["xformOp:translate", "xformOp:orient", "xformOp:scale"]

        def Sphere "visuals"
        {
            float3[] extent = [(-0.10998273, -0.10998273, -0.10998273), (0.10998273, 0.10998273, 0.10998273)]
            double radius = 0.10998272895812988
            quatd xformOp:orient = (1, 0, 0, 0)
            double3 xformOp:scale = (1, 1, 1)
            double3 xformOp:translate = (0, 0, 0)
            uniform token[] xformOpOrder = ["xformOp:translate", "xformOp:orient", "xformOp:scale"]
        }

        def Sphere "collisions" (
            apiSchemas = ["PhysicsCollisionAPI"]
        )
        {
            float3[] extent = [(-0.10998273, -0.10998273, -0.10998273), (0.10998273, 0.10998273, 0.10998273)]
            uniform token purpose = "guide"
            double radius = 0.10998272895812988
            quatd xformOp:orient = (1, 0, 0, 0)
            double3 xformOp:scale = (1, 1, 1)
            double3 xformOp:translate = (0, 0, 0)
            uniform token[] xformOpOrder = ["xformOp:translate", "xformOp:orient", "xformOp:scale"]
        }

        def PhysicsRevoluteJoint "leg_2_calf_joint" (
            apiSchemas = ["PhysxJointAPI", "PhysicsJointStateAPI:angular", "PhysicsDriveAPI:angular"]
        )
        {
            float drive:angular:physics:damping = 0
            float drive:angular:physics:maxForce = 60
            float drive:angular:physics:stiffness = 0
            uniform token drive:angular:physics:type = "force"
            uniform token physics:axis = "Y"
            rel physics:body0 = </quadruped_robot/leg_2_knee>
            rel physics:body1 = </quadruped_robot/leg_2_calf>
            float physics:breakForce = 3.4028235e38
            float physics:breakTorque = 3.4028235e38
            point3f physics:localPos0 = (0, 0, 0)
            point3f physics:localPos1 = (0, 0, 0)
            quatf physics:localRot0 = (1, 0, 0, 0)
            quatf physics:localRot1 = (1, 0, 0, 0)
            float physics:lowerLimit = -180
            float physics:upperLimit = 180
            float physxJoint:maxJointVelocity = 3002.2988
        }
    }

    def Xform "leg_2_calf" (
        apiSchemas = ["PhysicsRigidBodyAPI", "PhysicsMassAPI"]
    )
    {
        point3f physics:centerOfMass = (0, 0, -0.69552726)
        float physics:mass = 1.9653857
        quatd xformOp:orient = (1, 0, 0, 0)
        double3 xformOp:scale = (1, 1, 1)
        double3 xformOp:translate = (0, -0.32932010293006897, -0.9389815926551819)
        uniform token[] xformOpOrder = ["xformOp:translate", "xformOp:orient", "xformOp:scale"]

        def Cylinder "visuals"
        {
            uniform token axis = "Z"
            float3[] extent = [(-0.09012222, -0.09012222, -0.38229784), (0.09012222, 0.09012222, 0.38229784)]
            double height = 0.7645956873893738
            double radius = 0.09012222290039062
            quatd xformOp:orient = (1, 0, 0, 0)
            double3 xformOp:scale = (1, 1, 1)
            double3 xformOp:translate = (0, 0, -0.3822978436946869)
            uniform token[] xformOpOrder = ["xformOp:translate", "xformOp:orient", "xformOp:scale"]
        }

        def Cylinder "collisions" (
            apiSchemas = ["PhysicsCollisionAPI"]
        )
        {
            uniform token axis = "Z"
            float3[] extent = [(-0.09012222, -0.09012222, -0.38229784), (0.09012222, 0.09012222, 0.38229784)]
            double height = 0.7645956873893738
            uniform token purpose = "guide"
            double radius = 0.09012222290039062
            quatd xformOp:orient = (1, 0, 0, 0)
            double3 xformOp:scale = (1, 1, 1)
            double3 xformOp:translate = (0, 0, -0.3822978436946869)
            uniform token[] xformOpOrder = ["xformOp:translate", "xformOp:orient", "xformOp:scale"]
        }

        def PhysicsFixedJoint "leg_2_foot_joint"
        {
            rel physics:body0 = </quadruped_robot/leg_2_calf>
            rel physics:body1 = </quadruped_robot/leg_2_foot>
            float physics:breakForce = 3.4028235e38
            float physics:breakTorque = 3.4028235e38
            point3f physics:localPos0 = (0, 0, -0.7645957)
            point3f physics:localPos1 = (0, 0, 0)
            quatf physics:localRot0 = (1, 0, 0, 0)
            quatf physics:localRot1 = (1, 0, 0, 0)
        }
    }

    def Xform "leg_2_foot" (
        apiSchemas = ["PhysicsRigidBodyAPI", "PhysicsMassAPI"]
    )
    {
        point3f physics:centerOfMass = (0, 0, 0.063085556)
        float physics:mass = 0.82847995
        quatd xformOp:orient = (1, 0, 0, 0)
        double3 xformOp:scale = (1, 1, 1)
        double3 xformOp:translate = (0, -0.32932010293006897, -1.7035772800445557)
        uniform token[] xformOpOrder = ["xformOp:translate", "xformOp:orient", "xformOp:scale"]

        def Sphere "visuals"
        {
            float3[] extent = [(-0.063085556, -0.063085556, -0.063085556), (0.063085556, 0.063085556, 0.063085556)]
            double radius = 0.06308555603027344
            quatd xformOp:orient = (1, 0, 0, 0)
            double3 xformOp:scale = (1, 1, 1)
            double3 xformOp:translate = (0, 0, 0)
            uniform token[] xformOpOrder = ["xformOp:translate", "xformOp:orient", "xformOp:scale"]
        }

        def Sphere "collisions" (
            apiSchemas = ["PhysicsCollisionAPI"]
        )
        {
            float3[] extent = [(-0.063085556, -0.063085556, -0.063085556), (0.063085556, 0.063085556, 0.063085556)]
            uniform token purpose = "guide"
            double radius = 0.06308555603027344
            quatd xformOp:orient = (1, 0, 0, 0)
            double3 xformOp:scale = (1, 1, 1)
            double3 xformOp:translate = (0, 0, 0)
            uniform token[] xformOpOrder = ["xformOp:translate", "xformOp:orient", "xformOp:scale"]
        }
    }

    def Xform "leg_3_hip" (
        apiSchemas = ["PhysicsRigidBodyAPI", "PhysicsMassAPI"]
    )
    {
        point3f physics:centerOfMass = (0, 0, 0.10053602)
        float physics:mass = 1.5061638
        quatd xformOp:orient = (1, 0, 0, 0)
        double3 xformOp:scale = (1, 1, 1)
        double3 xformOp:translate = (0, 0.32932010293006897, -0.10843910276889801)
        uniform token[] xformOpOrder = ["xformOp:translate", "xformOp:orient", "xformOp:scale"]

        def Sphere "visuals"
        {
            float3[] extent = [(-0.10053602, -0.10053602, -0.10053602), (0.10053602, 0.10053602, 0.10053602)]
            double radius = 0.10053601861000061
            quatd xformOp:orient = (1, 0, 0, 0)
            double3 xformOp:scale = (1, 1, 1)
            double3 xformOp:translate = (0, 0, 0)
            uniform token[] xformOpOrder = ["xformOp:translate", "xformOp:orient", "xformOp:scale"]
        }

        def Sphere "collisions" (
            apiSchemas = ["PhysicsCollisionAPI"]
        )
        {
            float3[] extent = [(-0.10053602, -0.10053602, -0.10053602), (0.10053602, 0.10053602, 0.10053602)]
            uniform token purpose = "guide"
            double radius = 0.10053601861000061
            quatd xformOp:orient = (1, 0, 0, 0)
            double3 xformOp:scale = (1, 1, 1)
            double3 xformOp:translate = (0, 0, 0)
            uniform token[] xformOpOrder = ["xformOp:translate", "xformOp:orient", "xformOp:scale"]
        }

        def PhysicsRevoluteJoint "leg_3_thigh_joint" (
            apiSchemas = ["PhysxJointAPI", "PhysicsJointStateAPI:angular", "PhysicsDriveAPI:angular"]
        )
        {
            float drive:angular:physics:damping = 0
            float drive:angular:physics:maxForce = 60
            float drive:angular:physics:stiffness = 0
            uniform token drive:angular:physics:type = "force"
            uniform token physics:axis = "Y"
            rel physics:body0 = </quadruped_robot/leg_3_hip>
            rel physics:body1 = </quadruped_robot/leg_3_thigh>
            float physics:breakForce = 3.4028235e38
            float physics:breakTorque = 3.4028235e38
            point3f physics:localPos0 = (0, 0, 0)
            point3f physics:localPos1 = (0, 0, 0)
            quatf physics:localRot0 = (1, 0, 0, 0)
            quatf physics:localRot1 = (1, 0, 0, 0)
            float physics:lowerLimit = -180
            float physics:upperLimit = 180
            float physxJoint:maxJointVelocity = 3002.2988
        }
    }

    def Xform "leg_3_thigh" (
        apiSchemas = ["PhysicsRigidBodyAPI", "PhysicsMassAPI"]
    )
    {
        point3f physics:centerOfMass = (0, 0, -0.14802869)
        float physics:mass = 1.3069001
        quatd xformOp:orient = (1, 0, 0, 0)
        double3 xformOp:scale = (1, 1, 1)
        double3 xformOp:translate = (0, 0.32932010293006897, -0.10843910276889801)
        uniform token[] xformOpOrder = ["xformOp:translate", "xformOp:orient", "xformOp:scale"]

        def Cylinder "visuals"
        {
            uniform token axis = "Z"
            float3[] extent = [(-0.10053602, -0.10053602, -0.1309519), (0.10053602, 0.10053602, 0.1309519)]
            double height = 0.2619037926197052
            double radius = 0.10053601861000061
            quatd xformOp:orient = (1, 0, 0, 0)
            double3 xformOp:scale = (1, 1, 1)
            double3 xformOp:translate = (0, 0, -0.1309518963098526)
            uniform token[] xformOpOrder = ["xformOp:translate", "xformOp:orient", "xformOp:scale"]
        }

        def Cylinder "collisions" (
            apiSchemas = ["PhysicsCollisionAPI"]
        )
        {
            uniform token axis = "Z"
            float3[] extent = [(-0.10053602, -0.10053602, -0.1309519), (0.10053602, 0.10053602, 0.1309519)]
            double height = 0.2619037926197052
            uniform token purpose = "guide"
            double radius = 0.10053601861000061
            quatd xformOp:orient = (1, 0, 0, 0)
            double3 xformOp:scale = (1, 1, 1)
            double3 xformOp:translate = (0, 0, -0.1309518963098526)
            uniform token[] xformOpOrder = ["xformOp:translate", "xformOp:orient", "xformOp:scale"]
        }

        def PhysicsFixedJoint "leg_3_knee_joint"
        {
            rel physics:body0 = </quadruped_robot/leg_3_thigh>
            rel physics:body1 = </quadruped_robot/leg_3_knee>
            float physics:breakForce = 3.4028235e38
            float physics:breakTorque = 3.4028235e38
            point3f physics:localPos0 = (0, 0, -0.2619038)
            point3f physics:localPos1 = (0, 0, 0)
            quatf physics:localRot0 = (1, 0, 0, 0)
            quatf physics:localRot1 = (1, 0, 0, 0)
        }
    }

    def Xform "leg_3_knee" (
        apiSchemas = ["PhysicsRigidBodyAPI", "PhysicsMassAPI"]
    )
    {
        point3f physics:centerOfMass = (0, 0, 0.10053602)
        float physics:mass = 0.70546466
        quatd xformOp:orient = (1, 0, 0, 0)
        double3 xformOp:scale = (1, 1, 1)
        double3 xformOp:translate = (0, 0.32932010293006897, -0.3703429102897644)
        uniform token[] xformOpOrder = ["xformOp:translate", "xformOp:orient", "xformOp:scale"]

        def Sphere "visuals"
        {
            float3[] extent = [(-0.10053602, -0.10053602, -0.10053602), (0.10053602, 0.10053602, 0.10053602)]
            double radius = 0.10053601861000061
            quatd xformOp:orient = (1, 0, 0, 0)
            double3 xformOp:scale = (1, 1, 1)
            double3 xformOp:translate = (0, 0, 0)
            uniform token[] xformOpOrder = ["xformOp:translate", "xformOp:orient", "xformOp:scale"]
        }

        def Sphere "collisions" (
            apiSchemas = ["PhysicsCollisionAPI"]
        )
        {
            float3[] extent = [(-0.10053602, -0.10053602, -0.10053602), (0.10053602, 0.10053602, 0.10053602)]
            uniform token purpose = "guide"
            double radius = 0.10053601861000061
            quatd xformOp:orient = (1, 0, 0, 0)
            double3 xformOp:scale = (1, 1, 1)
            double3 xformOp:translate = (0, 0, 0)
            uniform token[] xformOpOrder = ["xformOp:translate", "xformOp:orient", "xformOp:scale"]
        }

        def PhysicsRevoluteJoint "leg_3_calf_joint" (
            apiSchemas = ["PhysxJointAPI", "PhysicsJointStateAPI:angular", "PhysicsDriveAPI:angular"]
        )
        {
            float drive:angular:physics:damping = 0
            float drive:angular:physics:maxForce = 60
            float drive:angular:physics:stiffness = 0
            uniform token drive:angular:physics:type = "force"
            uniform token physics:axis = "Y"
            rel physics:body0 = </quadruped_robot/leg_3_knee>
            rel physics:body1 = </quadruped_robot/leg_3_calf>
            float physics:breakForce = 3.4028235e38
            float physics:breakTorque = 3.4028235e38
            point3f physics:localPos0 = (0, 0, 0)
            point3f physics:localPos1 = (0, 0, 0)
            quatf physics:localRot0 = (1, 0, 0, 0)
            quatf physics:localRot1 = (1, 0, 0, 0)
            float physics:lowerLimit = -180
            float physics:upperLimit = 180
            float physxJoint:maxJointVelocity = 3002.2988
        }
    }

    def Xform "leg_3_calf" (
        apiSchemas = ["PhysicsRigidBodyAPI", "PhysicsMassAPI"]
    )
    {
        point3f physics:centerOfMass = (0, 0, -0.15112317)
        float physics:mass = 0.8605006
        quatd xformOp:orient = (1, 0, 0, 0)
        double3 xformOp:scale = (1, 1, 1)
        double3 xformOp:translate = (0, 0.32932010293006897, -0.3703429102897644)
        uniform token[] xformOpOrder = ["xformOp:translate", "xformOp:orient", "xformOp:scale"]

        def Cylinder "visuals"
        {
            uniform token axis = "Z"
            float3[] extent = [(-0.09030173, -0.09030173, -0.18071324), (0.09030173, 0.09030173, 0.18071324)]
            double height = 0.3614264726638794
            double radius = 0.09030172973871231
            quatd xformOp:orient = (1, 0, 0, 0)
            double3 xformOp:scale = (1, 1, 1)
            double3 xformOp:translate = (0, 0, -0.1807132363319397)
            uniform token[] xformOpOrder = ["xformOp:translate", "xformOp:orient", "xformOp:scale"]
        }

        def Cylinder "collisions" (
            apiSchemas = ["PhysicsCollisionAPI"]
        )
        {
            uniform token axis = "Z"
            float3[] extent = [(-0.09030173, -0.09030173, -0.18071324), (0.09030173, 0.09030173, 0.18071324)]
            double height = 0.3614264726638794
            uniform token purpose = "guide"
            double radius = 0.09030172973871231
            quatd xformOp:orient = (1, 0, 0, 0)
            double3 xformOp:scale = (1, 1, 1)
            double3 xformOp:translate = (0, 0, -0.1807132363319397)
            uniform token[] xformOpOrder = ["xformOp:translate", "xformOp:orient", "xformOp:scale"]
        }

        def PhysicsFixedJoint "leg_3_foot_joint"
        {
            rel physics:body0 = </quadruped_robot/leg_3_calf>
            rel physics:body1 = </quadruped_robot/leg_3_foot>
            float physics:breakForce = 3.4028235e38
            float physics:breakTorque = 3.4028235e38
            point3f physics:localPos0 = (0, 0, -0.36142647)
            point3f physics:localPos1 = (0, 0, 0)
            quatf physics:localRot0 = (1, 0, 0, 0)
            quatf physics:localRot1 = (1, 0, 0, 0)
        }
    }

    def Xform "leg_3_foot" (
        apiSchemas = ["PhysicsRigidBodyAPI", "PhysicsMassAPI"]
    )
    {
        point3f physics:centerOfMass = (0, 0, 0.06321121)
        float physics:mass = 1.3822963
        quatd xformOp:orient = (1, 0, 0, 0)
        double3 xformOp:scale = (1, 1, 1)
        double3 xformOp:translate = (0, 0.32932010293006897, -0.7317693829536438)
        uniform token[] xformOpOrder = ["xformOp:translate", "xformOp:orient", "xformOp:scale"]

        def Sphere "visuals"
        {
            float3[] extent = [(-0.06321121, -0.06321121, -0.06321121), (0.06321121, 0.06321121, 0.06321121)]
            double radius = 0.06321121007204056
            quatd xformOp:orient = (1, 0, 0, 0)
            double3 xformOp:scale = (1, 1, 1)
            double3 xformOp:translate = (0, 0, 0)
            uniform token[] xformOpOrder = ["xformOp:translate", "xformOp:orient", "xformOp:scale"]
        }

        def Sphere "collisions" (
            apiSchemas = ["PhysicsCollisionAPI"]
        )
        {
            float3[] extent = [(-0.06321121, -0.06321121, -0.06321121), (0.06321121, 0.06321121, 0.06321121)]
            uniform token purpose = "guide"
            double radius = 0.06321121007204056
            quatd xformOp:orient = (1, 0, 0, 0)
            double3 xformOp:scale = (1, 1, 1)
            double3 xformOp:translate = (0, 0, 0)
            uniform token[] xformOpOrder = ["xformOp:translate", "xformOp:orient", "xformOp:scale"]
        }
    }

    def Xform "leg_4_hip" (
        apiSchemas = ["PhysicsRigidBodyAPI", "PhysicsMassAPI"]
    )
    {
        point3f physics:centerOfMass = (0, 0, 0.103531465)
        float physics:mass = 1.7734499
        quatd xformOp:orient = (1, 0, 0, 0)
        double3 xformOp:scale = (1, 1, 1)
        double3 xformOp:translate = (-0.5082714557647705, -0.32932010293006897, -0.10843910276889801)
        uniform token[] xformOpOrder = ["xformOp:translate", "xformOp:orient", "xformOp:scale"]

        def Sphere "visuals"
        {
            float3[] extent = [(-0.103531465, -0.103531465, -0.103531465), (0.103531465, 0.103531465, 0.103531465)]
            double radius = 0.10353146493434906
            quatd xformOp:orient = (1, 0, 0, 0)
            double3 xformOp:scale = (1, 1, 1)
            double3 xformOp:translate = (0, 0, 0)
            uniform token[] xformOpOrder = ["xformOp:translate", "xformOp:orient", "xformOp:scale"]
        }

        def Sphere "collisions" (
            apiSchemas = ["PhysicsCollisionAPI"]
        )
        {
            float3[] extent = [(-0.103531465, -0.103531465, -0.103531465), (0.103531465, 0.103531465, 0.103531465)]
            uniform token purpose = "guide"
            double radius = 0.10353146493434906
            quatd xformOp:orient = (1, 0, 0, 0)
            double3 xformOp:scale = (1, 1, 1)
            double3 xformOp:translate = (0, 0, 0)
            uniform token[] xformOpOrder = ["xformOp:translate", "xformOp:orient", "xformOp:scale"]
        }

        def PhysicsRevoluteJoint "leg_4_thigh_joint" (
            apiSchemas = ["PhysxJointAPI", "PhysicsJointStateAPI:angular", "PhysicsDriveAPI:angular"]
        )
        {
            float drive:angular:physics:damping = 0
            float drive:angular:physics:maxForce = 60
            float drive:angular:physics:stiffness = 0
            uniform token drive:angular:physics:type = "force"
            uniform token physics:axis = "Y"
            rel physics:body0 = </quadruped_robot/leg_4_hip>
            rel physics:body1 = </quadruped_robot/leg_4_thigh>
            float physics:breakForce = 3.4028235e38
            float physics:breakTorque = 3.4028235e38
            point3f physics:localPos0 = (0, 0, 0)
            point3f physics:localPos1 = (0, 0, 0)
            quatf physics:localRot0 = (1, 0, 0, 0)
            quatf physics:localRot1 = (1, 0, 0, 0)
            float physics:lowerLimit = -180
            float physics:upperLimit = 180
            float physxJoint:maxJointVelocity = 3002.2988
        }
    }

    def Xform "leg_4_thigh" (
        apiSchemas = ["PhysicsRigidBodyAPI", "PhysicsMassAPI"]
    )
    {
        point3f physics:centerOfMass = (0, 0, -0.37682036)
        float physics:mass = 1.2419889
        quatd xformOp:orient = (1, 0, 0, 0)
        double3 xformOp:scale = (1, 1, 1)
        double3 xformOp:translate = (-0.5082714557647705, -0.32932010293006897, -0.10843910276889801)
        uniform token[] xformOpOrder = ["xformOp:translate", "xformOp:orient", "xformOp:scale"]

        def Cylinder "visuals"
        {
            uniform token axis = "Z"
            float3[] extent = [(-0.103531465, -0.103531465, -0.4219749), (0.103531465, 0.103531465, 0.4219749)]
            double height = 0.8439497947692871
            double radius = 0.10353146493434906
            quatd xformOp:orient = (1, 0, 0, 0)
            double3 xformOp:scale = (1, 1, 1)
            double3 xformOp:translate = (0, 0, -0.42197489738464355)
            uniform token[] xformOpOrder = ["xformOp:translate", "xformOp:orient", "xformOp:scale"]
        }

        def Cylinder "collisions" (
            apiSchemas = ["PhysicsCollisionAPI"]
        )
        {
            uniform token axis = "Z"
            float3[] extent = [(-0.103531465, -0.103531465, -0.4219749), (0.103531465, 0.103531465, 0.4219749)]
            double height = 0.8439497947692871
            uniform token purpose = "guide"
            double radius = 0.10353146493434906
            quatd xformOp:orient = (1, 0, 0, 0)
            double3 xformOp:scale = (1, 1, 1)
            double3 xformOp:translate = (0, 0, -0.42197489738464355)
            uniform token[] xformOpOrder = ["xformOp:translate", "xformOp:orient", "xformOp:scale"]
        }

        def PhysicsFixedJoint "leg_4_knee_joint"
        {
            rel physics:body0 = </quadruped_robot/leg_4_thigh>
            rel physics:body1 = </quadruped_robot/leg_4_knee>
            float physics:breakForce = 3.4028235e38
            float physics:breakTorque = 3.4028235e38
            point3f physics:localPos0 = (0, 0, -0.8439498)
            point3f physics:localPos1 = (0, 0, 0)
            quatf physics:localRot0 = (1, 0, 0, 0)
            quatf physics:localRot1 = (1, 0, 0, 0)
        }
    }

    def Xform "leg_4_knee" (
        apiSchemas = ["PhysicsRigidBodyAPI", "PhysicsMassAPI"]
    )
    {
        point3f physics:centerOfMass = (0, 0, 0.109165356)
        float physics:mass = 1.5402402
        quatd xformOp:orient = (1, 0, 0, 0)
        double3 xformOp:scale = (1, 1, 1)
        double3 xformOp:translate = (-0.5082714557647705, -0.32932010293006897, -0.9523888826370239)
        uniform token[] xformOpOrder = ["xformOp:translate", "xformOp:orient", "xformOp:scale"]

        def Sphere "visuals"
        {
            float3[] extent = [(-0.109165356, -0.109165356, -0.109165356), (0.109165356, 0.109165356, 0.109165356)]
            double radius = 0.10916535556316376
            quatd xformOp:orient = (1, 0, 0, 0)
            double3 xformOp:scale = (1, 1, 1)
            double3 xformOp:translate = (0, 0, 0)
            uniform token[] xformOpOrder = ["xformOp:translate", "xformOp:orient", "xformOp:scale"]
        }

        def Sphere "collisions" (
            apiSchemas = ["PhysicsCollisionAPI"]
        )
        {
            float3[] extent = [(-0.109165356, -0.109165356, -0.109165356), (0.109165356, 0.109165356, 0.109165356)]
            uniform token purpose = "guide"
            double radius = 0.10916535556316376
            quatd xformOp:orient = (1, 0, 0, 0)
            double3 xformOp:scale = (1, 1, 1)
            double3 xformOp:translate = (0, 0, 0)
            uniform token[] xformOpOrder = ["xformOp:translate", "xformOp:orient", "xformOp:scale"]
        }

        def PhysicsRevoluteJoint "leg_4_calf_joint" (
            apiSchemas = ["PhysxJointAPI", "PhysicsJointStateAPI:angular", "PhysicsDriveAPI:angular"]
        )
        {
            float drive:angular:physics:damping = 0
            float drive:angular:physics:maxForce = 60
            float drive:angular:physics:stiffness = 0
            uniform token drive:angular:physics:type = "force"
            uniform token physics:axis = "Y"
            rel physics:body0 = </quadruped_robot/leg_4_knee>
            rel physics:body1 = </quadruped_robot/leg_4_calf>
            float physics:breakForce = 3.4028235e38
            float physics:breakTorque = 3.4028235e38
            point3f physics:localPos0 = (0, 0, 0)
            point3f physics:localPos1 = (0, 0, 0)
            quatf physics:localRot0 = (1, 0, 0, 0)
            quatf physics:localRot1 = (1, 0, 0, 0)
            float physics:lowerLimit = -180
            float physics:upperLimit = 180
            float physxJoint:maxJointVelocity = 3002.2988
        }
    }

    def Xform "leg_4_calf" (
        apiSchemas = ["PhysicsRigidBodyAPI", "PhysicsMassAPI"]
    )
    {
        point3f physics:centerOfMass = (0, 0, -0.11120687)
        float physics:mass = 1.4061176
        quatd xformOp:orient = (1, 0, 0, 0)
        double3 xformOp:scale = (1, 1, 1)
        double3 xformOp:translate = (-0.5082714557647705, -0.32932010293006897, -0.9523888826370239)
        uniform token[] xformOpOrder = ["xformOp:translate", "xformOp:orient", "xformOp:scale"]

        def Cylinder "visuals"
        {
            uniform token axis = "Z"
            float3[] extent = [(-0.109165356, -0.109165356, -0.27160615), (0.109165356, 0.109165356, 0.27160615)]
            double height = 0.5432122945785522
            double radius = 0.10916535556316376
            quatd xformOp:orient = (1, 0, 0, 0)
            double3 xformOp:scale = (1, 1, 1)
            double3 xformOp:translate = (0, 0, -0.2716061472892761)
            uniform token[] xformOpOrder = ["xformOp:translate", "xformOp:orient", "xformOp:scale"]
        }

        def Cylinder "collisions" (
            apiSchemas = ["PhysicsCollisionAPI"]
        )
        {
            uniform token axis = "Z"
            float3[] extent = [(-0.109165356, -0.109165356, -0.27160615), (0.109165356, 0.109165356, 0.27160615)]
            double height = 0.5432122945785522
            uniform token purpose = "guide"
            double radius = 0.10916535556316376
            quatd xformOp:orient = (1, 0, 0, 0)
            double3 xformOp:scale = (1, 1, 1)
            double3 xformOp:translate = (0, 0, -0.2716061472892761)
            uniform token[] xformOpOrder = ["xformOp:translate", "xformOp:orient", "xformOp:scale"]
        }

        def PhysicsFixedJoint "leg_4_foot_joint"
        {
            rel physics:body0 = </quadruped_robot/leg_4_calf>
            rel physics:body1 = </quadruped_robot/leg_4_foot>
            float physics:breakForce = 3.4028235e38
            float physics:breakTorque = 3.4028235e38
            point3f physics:localPos0 = (0, 0, -0.5432123)
            point3f physics:localPos1 = (0, 0, 0)
            quatf physics:localRot0 = (1, 0, 0, 0)
            quatf physics:localRot1 = (1, 0, 0, 0)
        }
    }

    def Xform "leg_4_foot" (
        apiSchemas = ["PhysicsRigidBodyAPI", "PhysicsMassAPI"]
    )
    {
        point3f physics:centerOfMass = (0, 0, 0.07247202)
        float physics:mass = 1.6782268
        quatd xformOp:orient = (1, 0, 0, 0)
        double3 xformOp:scale = (1, 1, 1)
        double3 xformOp:translate = (-0.5082714557647705, -0.32932010293006897, -1.4956011772155762)
        uniform token[] xformOpOrder = ["xformOp:translate", "xformOp:orient", "xformOp:scale"]

        def Sphere "visuals"
        {
            float3[] extent = [(-0.07247202, -0.07247202, -0.07247202), (0.07247202, 0.07247202, 0.07247202)]
            double radius = 0.07247202098369598
            quatd xformOp:orient = (1, 0, 0, 0)
            double3 xformOp:scale = (1, 1, 1)
            double3 xformOp:translate = (0, 0, 0)
            uniform token[] xformOpOrder = ["xformOp:translate", "xformOp:orient", "xformOp:scale"]
        }

        def Sphere "collisions" (
            apiSchemas = ["PhysicsCollisionAPI"]
        )
        {
            float3[] extent = [(-0.07247202, -0.07247202, -0.07247202), (0.07247202, 0.07247202, 0.07247202)]
            uniform token purpose = "guide"
            double radius = 0.07247202098369598
            quatd xformOp:orient = (1, 0, 0, 0)
            double3 xformOp:scale = (1, 1, 1)
            double3 xformOp:translate = (0, 0, 0)
            uniform token[] xformOpOrder = ["xformOp:translate", "xformOp:orient", "xformOp:scale"]
        }
    }

    def Xform "leg_5_hip" (
        apiSchemas = ["PhysicsRigidBodyAPI", "PhysicsMassAPI"]
    )
    {
        point3f physics:centerOfMass = (0, 0, 0.096338294)
        float physics:mass = 0.7739677
        quatd xformOp:orient = (1, 0, 0, 0)
        double3 xformOp:scale = (1, 1, 1)
        double3 xformOp:translate = (-0.5082714557647705, 0.32932010293006897, -0.10843910276889801)
        uniform token[] xformOpOrder = ["xformOp:translate", "xformOp:orient", "xformOp:scale"]

        def Sphere "visuals"
        {
            float3[] extent = [(-0.096338294, -0.096338294, -0.096338294), (0.096338294, 0.096338294, 0.096338294)]
            double radius = 0.09633829444646835
            quatd xformOp:orient = (1, 0, 0, 0)
            double3 xformOp:scale = (1, 1, 1)
            double3 xformOp:translate = (0, 0, 0)
            uniform token[] xformOpOrder = ["xformOp:translate", "xformOp:orient", "xformOp:scale"]
        }

        def Sphere "collisions" (
            apiSchemas = ["PhysicsCollisionAPI"]
        )
        {
            float3[] extent = [(-0.096338294, -0.096338294, -0.096338294), (0.096338294, 0.096338294, 0.096338294)]
            uniform token purpose = "guide"
            double radius = 0.09633829444646835
            quatd xformOp:orient = (1, 0, 0, 0)
            double3 xformOp:scale = (1, 1, 1)
            double3 xformOp:translate = (0, 0, 0)
            uniform token[] xformOpOrder = ["xformOp:translate", "xformOp:orient", "xformOp:scale"]
        }

        def PhysicsRevoluteJoint "leg_5_thigh_joint" (
            apiSchemas = ["PhysxJointAPI", "PhysicsJointStateAPI:angular", "PhysicsDriveAPI:angular"]
        )
        {
            float drive:angular:physics:damping = 0
            float drive:angular:physics:maxForce = 60
            float drive:angular:physics:stiffness = 0
            uniform token drive:angular:physics:type = "force"
            uniform token physics:axis = "Y"
            rel physics:body0 = </quadruped_robot/leg_5_hip>
            rel physics:body1 = </quadruped_robot/leg_5_thigh>
            float physics:breakForce = 3.4028235e38
            float physics:breakTorque = 3.4028235e38
            point3f physics:localPos0 = (0, 0, 0)
            point3f physics:localPos1 = (0, 0, 0)
            quatf physics:localRot0 = (1, 0, 0, 0)
            quatf physics:localRot1 = (1, 0, 0, 0)
            float physics:lowerLimit = -180
            float physics:upperLimit = 180
            float physxJoint:maxJointVelocity = 3002.2988
        }
    }

    def Xform "leg_5_thigh" (
        apiSchemas = ["PhysicsRigidBodyAPI", "PhysicsMassAPI"]
    )
    {
        point3f physics:centerOfMass = (0, 0, -0.2537077)
        float physics:mass = 1.9956
        quatd xformOp:orient = (1, 0, 0, 0)
        double3 xformOp:scale = (1, 1, 1)
        double3 xformOp:translate = (-0.5082714557647705, 0.32932010293006897, -0.10843910276889801)
        uniform token[] xformOpOrder = ["xformOp:translate", "xformOp:orient", "xformOp:scale"]

        def Cylinder "visuals"
        {
            uniform token axis = "Z"
            float3[] extent = [(-0.096338294, -0.096338294, -0.14318003), (0.096338294, 0.096338294, 0.14318003)]
            double height = 0.2863600552082062
            double radius = 0.09633829444646835
            quatd xformOp:orient = (1, 0, 0, 0)
            double3 xformOp:scale = (1, 1, 1)
            double3 xformOp:translate = (0, 0, -0.1431800276041031)
            uniform token[] xformOpOrder = ["xformOp:translate", "xformOp:orient", "xformOp:scale"]
        }

        def Cylinder "collisions" (
            apiSchemas = ["PhysicsCollisionAPI"]
        )
        {
            uniform token axis = "Z"
            float3[] extent = [(-0.096338294, -0.096338294, -0.14318003), (0.096338294, 0.096338294, 0.14318003)]
            double height = 0.2863600552082062
            uniform token purpose = "guide"
            double radius = 0.09633829444646835
            quatd xformOp:orient = (1, 0, 0, 0)
            double3 xformOp:scale = (1, 1, 1)
            double3 xformOp:translate = (0, 0, -0.1431800276041031)
            uniform token[] xformOpOrder = ["xformOp:translate", "xformOp:orient", "xformOp:scale"]
        }

        def PhysicsFixedJoint "leg_5_knee_joint"
        {
            rel physics:body0 = </quadruped_robot/leg_5_thigh>
            rel physics:body1 = </quadruped_robot/leg_5_knee>
            float physics:breakForce = 3.4028235e38
            float physics:breakTorque = 3.4028235e38
            point3f physics:localPos0 = (0, 0, -0.28636006)
            point3f physics:localPos1 = (0, 0, 0)
            quatf physics:localRot0 = (1, 0, 0, 0)
            quatf physics:localRot1 = (1, 0, 0, 0)
        }
    }

    def Xform "leg_5_knee" (
        apiSchemas = ["PhysicsRigidBodyAPI", "PhysicsMassAPI"]
    )
    {
        point3f physics:centerOfMass = (0, 0, 0.096338294)
        float physics:mass = 0.5646913
        quatd xformOp:orient = (1, 0, 0, 0)
        double3 xformOp:scale = (1, 1, 1)
        double3 xformOp:translate = (-0.5082714557647705, 0.32932010293006897, -0.3947991728782654)
        uniform token[] xformOpOrder = ["xformOp:translate", "xformOp:orient", "xformOp:scale"]

        def Sphere "visuals"
        {
            float3[] extent = [(-0.096338294, -0.096338294, -0.096338294), (0.096338294, 0.096338294, 0.096338294)]
            double radius = 0.09633829444646835
            quatd xformOp:orient = (1, 0, 0, 0)
            double3 xformOp:scale = (1, 1, 1)
            double3 xformOp:translate = (0, 0, 0)
            uniform token[] xformOpOrder = ["xformOp:translate", "xformOp:orient", "xformOp:scale"]
        }

        def Sphere "collisions" (
            apiSchemas = ["PhysicsCollisionAPI"]
        )
        {
            float3[] extent = [(-0.096338294, -0.096338294, -0.096338294), (0.096338294, 0.096338294, 0.096338294)]
            uniform token purpose = "guide"
            double radius = 0.09633829444646835
            quatd xformOp:orient = (1, 0, 0, 0)
            double3 xformOp:scale = (1, 1, 1)
            double3 xformOp:translate = (0, 0, 0)
            uniform token[] xformOpOrder = ["xformOp:translate", "xformOp:orient", "xformOp:scale"]
        }

        def PhysicsRevoluteJoint "leg_5_calf_joint" (
            apiSchemas = ["PhysxJointAPI", "PhysicsJointStateAPI:angular", "PhysicsDriveAPI:angular"]
        )
        {
            float drive:angular:physics:damping = 0
            float drive:angular:physics:maxForce = 60
            float drive:angular:physics:stiffness = 0
            uniform token drive:angular:physics:type = "force"
            uniform token physics:axis = "Y"
            rel physics:body0 = </quadruped_robot/leg_5_knee>
            rel physics:body1 = </quadruped_robot/leg_5_calf>
            float physics:breakForce = 3.4028235e38
            float physics:breakTorque = 3.4028235e38
            point3f physics:localPos0 = (0, 0, 0)
            point3f physics:localPos1 = (0, 0, 0)
            quatf physics:localRot0 = (1, 0, 0, 0)
            quatf physics:localRot1 = (1, 0, 0, 0)
            float physics:lowerLimit = -180
            float physics:upperLimit = 180
            float physxJoint:maxJointVelocity = 3002.2988
        }
    }

    def Xform "leg_5_calf" (
        apiSchemas = ["PhysicsRigidBodyAPI", "PhysicsMassAPI"]
    )
    {
        point3f physics:centerOfMass = (0, 0, -0.057415493)
        float physics:mass = 0.50625026
        quatd xformOp:orient = (1, 0, 0, 0)
        double3 xformOp:scale = (1, 1, 1)
        double3 xformOp:translate = (-0.5082714557647705, 0.32932010293006897, -0.3947991728782654)
        uniform token[] xformOpOrder = ["xformOp:translate", "xformOp:orient", "xformOp:scale"]

        def Cylinder "visuals"
        {
            uniform token axis = "Z"
            float3[] extent = [(-0.08720613, -0.08720613, -0.20827115), (0.08720613, 0.08720613, 0.20827115)]
            double height = 0.41654229164123535
            double radius = 0.08720613270998001
            quatd xformOp:orient = (1, 0, 0, 0)
            double3 xformOp:scale = (1, 1, 1)
            double3 xformOp:translate = (0, 0, -0.20827114582061768)
            uniform token[] xformOpOrder = ["xformOp:translate", "xformOp:orient", "xformOp:scale"]
        }

        def Cylinder "collisions" (
            apiSchemas = ["PhysicsCollisionAPI"]
        )
        {
            uniform token axis = "Z"
            float3[] extent = [(-0.08720613, -0.08720613, -0.20827115), (0.08720613, 0.08720613, 0.20827115)]
            double height = 0.41654229164123535
            uniform token purpose = "guide"
            double radius = 0.08720613270998001
            quatd xformOp:orient = (1, 0, 0, 0)
            double3 xformOp:scale = (1, 1, 1)
            double3 xformOp:translate = (0, 0, -0.20827114582061768)
            uniform token[] xformOpOrder = ["xformOp:translate", "xformOp:orient", "xformOp:scale"]
        }

        def PhysicsFixedJoint "leg_5_foot_joint"
        {
            rel physics:body0 = </quadruped_robot/leg_5_calf>
            rel physics:body1 = </quadruped_robot/leg_5_foot>
            float physics:breakForce = 3.4028235e38
            float physics:breakTorque = 3.4028235e38
            point3f physics:localPos0 = (0, 0, -0.4165423)
            point3f physics:localPos1 = (0, 0, 0)
            quatf physics:localRot0 = (1, 0, 0, 0)
            quatf physics:localRot1 = (1, 0, 0, 0)
        }
    }

    def Xform "leg_5_foot" (
        apiSchemas = ["PhysicsRigidBodyAPI", "PhysicsMassAPI"]
    )
    {
        point3f physics:centerOfMass = (0, 0, 0.06104429)
        float physics:mass = 1.9135827
        quatd xformOp:orient = (1, 0, 0, 0)
        double3 xformOp:scale = (1, 1, 1)
        double3 xformOp:translate = (-0.5082714557647705, 0.32932010293006897, -0.8113414645195007)
        uniform token[] xformOpOrder = ["xformOp:translate", "xformOp:orient", "xformOp:scale"]

        def Sphere "visuals"
        {
            float3[] extent = [(-0.06104429, -0.06104429, -0.06104429), (0.06104429, 0.06104429, 0.06104429)]
            double radius = 0.06104429066181183
            quatd xformOp:orient = (1, 0, 0, 0)
            double3 xformOp:scale = (1, 1, 1)
            double3 xformOp:translate = (0, 0, 0)
            uniform token[] xformOpOrder = ["xformOp:translate", "xformOp:orient", "xformOp:scale"]
        }

        def Sphere "collisions" (
            apiSchemas = ["PhysicsCollisionAPI"]
        )
        {
            float3[] extent = [(-0.06104429, -0.06104429, -0.06104429), (0.06104429, 0.06104429, 0.06104429)]
            uniform token purpose = "guide"
            double radius = 0.06104429066181183
            quatd xformOp:orient = (1, 0, 0, 0)
            double3 xformOp:scale = (1, 1, 1)
            double3 xformOp:translate = (0, 0, 0)
            uniform token[] xformOpOrder = ["xformOp:translate", "xformOp:orient", "xformOp:scale"]
        }
    }
}

