#usda 1.0
(
    customLayerData = {
        dictionary omni_layer = {
            dictionary locked = {
            }
            dictionary muteness = {
            }
        }
    }
    defaultPrim = "quadruped_robot"
    doc = """Generated from Composed Stage of root layer /home/gpuuser/GitHub/Intelligent-robot-design/generations/generation_0/robot_28.usda
"""
    metersPerUnit = 1
    upAxis = "Z"
)

def Xform "quadruped_robot"
{
    quatd xformOp:orient = (1, 0, 0, 0)
    double3 xformOp:scale = (1, 1, 1)
    double3 xformOp:translate = (0, 0, 0)
    uniform token[] xformOpOrder = ["xformOp:translate", "xformOp:orient", "xformOp:scale"]

    def Scope "Looks"
    {
    }

    def Xform "base" (
        apiSchemas = ["PhysicsRigidBodyAPI", "PhysicsMassAPI", "PhysicsArticulationRootAPI", "PhysxArticulationAPI"]
    )
    {
        point3f physics:centerOfMass = (0, 0, -0.007472649)
        float3 physics:diagonalInertia = (0.000026679763, 0.000026679763, 0.000012299893)
        float physics:mass = 0.73799354
        quatf physics:principalAxes = (1, 0, 0, 0)
        bool physxArticulation:enabledSelfCollisions = 1
        int physxArticulation:solverPositionIterationCount = 32
        int physxArticulation:solverVelocityIterationCount = 1
        quatd xformOp:orient = (1, 0, 0, 0)
        double3 xformOp:scale = (1, 1, 1)
        double3 xformOp:translate = (0, 0, 0)
        uniform token[] xformOpOrder = ["xformOp:translate", "xformOp:orient", "xformOp:scale"]

        def Cube "visuals"
        {
            float3[] extent = [(-0.005, -0.005, -0.005), (0.005, 0.005, 0.005)]
            double size = 1
            quatd xformOp:orient = (1, 0, 0, 0)
            double3 xformOp:scale = (0.009999999776482582, 0.009999999776482582, 0.009999999776482582)
            double3 xformOp:translate = (0, 0, 0)
            uniform token[] xformOpOrder = ["xformOp:translate", "xformOp:orient", "xformOp:scale"]
        }

        def Cube "collisions" (
            apiSchemas = ["PhysicsCollisionAPI"]
        )
        {
            float3[] extent = [(-0.005, -0.005, -0.005), (0.005, 0.005, 0.005)]
            uniform token purpose = "guide"
            double size = 1
            quatd xformOp:orient = (1, 0, 0, 0)
            double3 xformOp:scale = (0.009999999776482582, 0.009999999776482582, 0.009999999776482582)
            double3 xformOp:translate = (0, 0, 0)
            uniform token[] xformOpOrder = ["xformOp:translate", "xformOp:orient", "xformOp:scale"]
        }

        def PhysicsFixedJoint "floating_base"
        {
            rel physics:body0 = </quadruped_robot/base>
            rel physics:body1 = </quadruped_robot/trunk>
            float physics:breakForce = 3.4028235e38
            float physics:breakTorque = 3.4028235e38
            point3f physics:localPos0 = (0, 0, 0)
            point3f physics:localPos1 = (0, 0, 0)
            quatf physics:localRot0 = (1, 0, 0, 0)
            quatf physics:localRot1 = (1, 0, 0, 0)
        }
    }

    def Xform "trunk" (
        apiSchemas = ["PhysicsRigidBodyAPI", "PhysicsMassAPI"]
    )
    {
        point3f physics:centerOfMass = (0, 0, -0.037445057)
        float3 physics:diagonalInertia = (0.014714865, 0.014714865, 0.07152143)
        float physics:mass = 0.61009467
        quatf physics:principalAxes = (1, 0, 0, 0)
        quatd xformOp:orient = (1, 0, 0, 0)
        double3 xformOp:scale = (1, 1, 1)
        double3 xformOp:translate = (0, 0, 0)
        uniform token[] xformOpOrder = ["xformOp:translate", "xformOp:orient", "xformOp:scale"]

        def Cube "visuals"
        {
            float3[] extent = [(-0.52893686, -0.26817146, -0.11904495), (0.52893686, 0.26817146, 0.11904495)]
            double size = 1
            quatd xformOp:orient = (1, 0, 0, 0)
            double3 xformOp:scale = (1.0578737258911133, 0.5363429188728333, 0.2380899041891098)
            double3 xformOp:translate = (0, 0, 0)
            uniform token[] xformOpOrder = ["xformOp:translate", "xformOp:orient", "xformOp:scale"]
        }

        def Cube "collisions" (
            apiSchemas = ["PhysicsCollisionAPI"]
        )
        {
            float3[] extent = [(-0.52893686, -0.26817146, -0.11904495), (0.52893686, 0.26817146, 0.11904495)]
            uniform token purpose = "guide"
            double size = 1
            quatd xformOp:orient = (1, 0, 0, 0)
            double3 xformOp:scale = (1.0578737258911133, 0.5363429188728333, 0.2380899041891098)
            double3 xformOp:translate = (0, 0, 0)
            uniform token[] xformOpOrder = ["xformOp:translate", "xformOp:orient", "xformOp:scale"]
        }

        def PhysicsRevoluteJoint "FL_hip_joint" (
            apiSchemas = ["PhysxJointAPI", "PhysicsJointStateAPI:angular", "PhysicsDriveAPI:angular"]
        )
        {
            float drive:angular:physics:damping = 0
            float drive:angular:physics:maxForce = 60
            float drive:angular:physics:stiffness = 0
            uniform token drive:angular:physics:type = "force"
            uniform token physics:axis = "X"
            rel physics:body0 = </quadruped_robot/trunk>
            rel physics:body1 = </quadruped_robot/FL_hip>
            float physics:breakForce = 3.4028235e38
            float physics:breakTorque = 3.4028235e38
            point3f physics:localPos0 = (0.52893686, 0.26817146, -0.095235966)
            point3f physics:localPos1 = (0, 0, 0)
            quatf physics:localRot0 = (1, 0, 0, 0)
            quatf physics:localRot1 = (1, 0, 0, 0)
            float physics:lowerLimit = -180
            float physics:upperLimit = 180
            float physxJoint:maxJointVelocity = 3002.2988
        }

        def PhysicsRevoluteJoint "FR_hip_joint" (
            apiSchemas = ["PhysxJointAPI", "PhysicsJointStateAPI:angular", "PhysicsDriveAPI:angular"]
        )
        {
            float drive:angular:physics:damping = 0
            float drive:angular:physics:maxForce = 60
            float drive:angular:physics:stiffness = 0
            uniform token drive:angular:physics:type = "force"
            uniform token physics:axis = "X"
            rel physics:body0 = </quadruped_robot/trunk>
            rel physics:body1 = </quadruped_robot/FR_hip>
            float physics:breakForce = 3.4028235e38
            float physics:breakTorque = 3.4028235e38
            point3f physics:localPos0 = (0.52893686, -0.26817146, -0.095235966)
            point3f physics:localPos1 = (0, 0, 0)
            quatf physics:localRot0 = (1, 0, 0, 0)
            quatf physics:localRot1 = (1, 0, 0, 0)
            float physics:lowerLimit = -180
            float physics:upperLimit = 180
            float physxJoint:maxJointVelocity = 3002.2988
        }

        def PhysicsRevoluteJoint "RL_hip_joint" (
            apiSchemas = ["PhysxJointAPI", "PhysicsJointStateAPI:angular", "PhysicsDriveAPI:angular"]
        )
        {
            float drive:angular:physics:damping = 0
            float drive:angular:physics:maxForce = 60
            float drive:angular:physics:stiffness = 0
            uniform token drive:angular:physics:type = "force"
            uniform token physics:axis = "X"
            rel physics:body0 = </quadruped_robot/trunk>
            rel physics:body1 = </quadruped_robot/RL_hip>
            float physics:breakForce = 3.4028235e38
            float physics:breakTorque = 3.4028235e38
            point3f physics:localPos0 = (-0.52893686, 0.26817146, -0.095235966)
            point3f physics:localPos1 = (0, 0, 0)
            quatf physics:localRot0 = (1, 0, 0, 0)
            quatf physics:localRot1 = (1, 0, 0, 0)
            float physics:lowerLimit = -180
            float physics:upperLimit = 180
            float physxJoint:maxJointVelocity = 3002.2988
        }

        def PhysicsRevoluteJoint "RR_hip_joint" (
            apiSchemas = ["PhysxJointAPI", "PhysicsJointStateAPI:angular", "PhysicsDriveAPI:angular"]
        )
        {
            float drive:angular:physics:damping = 0
            float drive:angular:physics:maxForce = 60
            float drive:angular:physics:stiffness = 0
            uniform token drive:angular:physics:type = "force"
            uniform token physics:axis = "X"
            rel physics:body0 = </quadruped_robot/trunk>
            rel physics:body1 = </quadruped_robot/RR_hip>
            float physics:breakForce = 3.4028235e38
            float physics:breakTorque = 3.4028235e38
            point3f physics:localPos0 = (-0.52893686, -0.26817146, -0.095235966)
            point3f physics:localPos1 = (0, 0, 0)
            quatf physics:localRot0 = (1, 0, 0, 0)
            quatf physics:localRot1 = (1, 0, 0, 0)
            float physics:lowerLimit = -180
            float physics:upperLimit = 180
            float physxJoint:maxJointVelocity = 3002.2988
        }
    }

    def Xform "FL_hip" (
        apiSchemas = ["PhysicsRigidBodyAPI", "PhysicsMassAPI"]
    )
    {
        point3f physics:centerOfMass = (0, 0, 0.08566506)
        float3 physics:diagonalInertia = (0.005608656, 0.005608656, 0.005608656)
        float physics:mass = 1.9106951
        quatf physics:principalAxes = (1, 0, 0, 0)
        quatd xformOp:orient = (1, 0, 0, 0)
        double3 xformOp:scale = (1, 1, 1)
        double3 xformOp:translate = (0.5289368629455566, 0.2681714594364166, -0.09523596614599228)
        uniform token[] xformOpOrder = ["xformOp:translate", "xformOp:orient", "xformOp:scale"]

        def Sphere "visuals"
        {
            float3[] extent = [(-0.08566506, -0.08566506, -0.08566506), (0.08566506, 0.08566506, 0.08566506)]
            double radius = 0.08566506206989288
            quatd xformOp:orient = (1, 0, 0, 0)
            double3 xformOp:scale = (1, 1, 1)
            double3 xformOp:translate = (0, 0, 0)
            uniform token[] xformOpOrder = ["xformOp:translate", "xformOp:orient", "xformOp:scale"]
        }

        def Sphere "collisions" (
            apiSchemas = ["PhysicsCollisionAPI"]
        )
        {
            float3[] extent = [(-0.08566506, -0.08566506, -0.08566506), (0.08566506, 0.08566506, 0.08566506)]
            uniform token purpose = "guide"
            double radius = 0.08566506206989288
            quatd xformOp:orient = (1, 0, 0, 0)
            double3 xformOp:scale = (1, 1, 1)
            double3 xformOp:translate = (0, 0, 0)
            uniform token[] xformOpOrder = ["xformOp:translate", "xformOp:orient", "xformOp:scale"]
        }

        def PhysicsRevoluteJoint "FL_thigh_joint" (
            apiSchemas = ["PhysxJointAPI", "PhysicsJointStateAPI:angular", "PhysicsDriveAPI:angular"]
        )
        {
            float drive:angular:physics:damping = 0
            float drive:angular:physics:maxForce = 60
            float drive:angular:physics:stiffness = 0
            uniform token drive:angular:physics:type = "force"
            uniform token physics:axis = "Y"
            rel physics:body0 = </quadruped_robot/FL_hip>
            rel physics:body1 = </quadruped_robot/FL_thigh>
            float physics:breakForce = 3.4028235e38
            float physics:breakTorque = 3.4028235e38
            point3f physics:localPos0 = (0, 0, 0)
            point3f physics:localPos1 = (0, 0, 0)
            quatf physics:localRot0 = (1, 0, 0, 0)
            quatf physics:localRot1 = (1, 0, 0, 0)
            float physics:lowerLimit = -180
            float physics:upperLimit = 180
            float physxJoint:maxJointVelocity = 3002.2988
        }
    }

    def Xform "FL_thigh" (
        apiSchemas = ["PhysicsRigidBodyAPI", "PhysicsMassAPI"]
    )
    {
        point3f physics:centerOfMass = (0, 0, -0.1698252)
        float3 physics:diagonalInertia = (0.013746599, 0.013746599, 0.00398584)
        float physics:mass = 1.0862815
        quatf physics:principalAxes = (1, 0, 0, 0)
        quatd xformOp:orient = (1, 0, 0, 0)
        double3 xformOp:scale = (1, 1, 1)
        double3 xformOp:translate = (0.5289368629455566, 0.2681714594364166, -0.09523596614599228)
        uniform token[] xformOpOrder = ["xformOp:translate", "xformOp:orient", "xformOp:scale"]

        def Cylinder "visuals"
        {
            uniform token axis = "Z"
            float3[] extent = [(-0.08566506, -0.08566506, -0.18048236), (0.08566506, 0.08566506, 0.18048236)]
            double height = 0.36096471548080444
            double radius = 0.08566506206989288
            quatd xformOp:orient = (1, 0, 0, 0)
            double3 xformOp:scale = (1, 1, 1)
            double3 xformOp:translate = (0, 0, -0.18048235774040222)
            uniform token[] xformOpOrder = ["xformOp:translate", "xformOp:orient", "xformOp:scale"]
        }

        def Cylinder "collisions" (
            apiSchemas = ["PhysicsCollisionAPI"]
        )
        {
            uniform token axis = "Z"
            float3[] extent = [(-0.08566506, -0.08566506, -0.18048236), (0.08566506, 0.08566506, 0.18048236)]
            double height = 0.36096471548080444
            uniform token purpose = "guide"
            double radius = 0.08566506206989288
            quatd xformOp:orient = (1, 0, 0, 0)
            double3 xformOp:scale = (1, 1, 1)
            double3 xformOp:translate = (0, 0, -0.18048235774040222)
            uniform token[] xformOpOrder = ["xformOp:translate", "xformOp:orient", "xformOp:scale"]
        }

        def PhysicsFixedJoint "FL_knee_joint"
        {
            rel physics:body0 = </quadruped_robot/FL_thigh>
            rel physics:body1 = </quadruped_robot/FL_knee>
            float physics:breakForce = 3.4028235e38
            float physics:breakTorque = 3.4028235e38
            point3f physics:localPos0 = (0, 0, -0.36096472)
            point3f physics:localPos1 = (0, 0, 0)
            quatf physics:localRot0 = (1, 0, 0, 0)
            quatf physics:localRot1 = (1, 0, 0, 0)
        }
    }

    def Xform "FL_knee" (
        apiSchemas = ["PhysicsRigidBodyAPI", "PhysicsMassAPI"]
    )
    {
        point3f physics:centerOfMass = (0, 0, 0.08566506)
        float3 physics:diagonalInertia = (0.0029986035, 0.0029986035, 0.0029986035)
        float physics:mass = 1.0215312
        quatf physics:principalAxes = (1, 0, 0, 0)
        quatd xformOp:orient = (1, 0, 0, 0)
        double3 xformOp:scale = (1, 1, 1)
        double3 xformOp:translate = (0.5289368629455566, 0.2681714594364166, -0.4562006890773773)
        uniform token[] xformOpOrder = ["xformOp:translate", "xformOp:orient", "xformOp:scale"]

        def Sphere "visuals"
        {
            float3[] extent = [(-0.08566506, -0.08566506, -0.08566506), (0.08566506, 0.08566506, 0.08566506)]
            double radius = 0.08566506206989288
            quatd xformOp:orient = (1, 0, 0, 0)
            double3 xformOp:scale = (1, 1, 1)
            double3 xformOp:translate = (0, 0, 0)
            uniform token[] xformOpOrder = ["xformOp:translate", "xformOp:orient", "xformOp:scale"]
        }

        def Sphere "collisions" (
            apiSchemas = ["PhysicsCollisionAPI"]
        )
        {
            float3[] extent = [(-0.08566506, -0.08566506, -0.08566506), (0.08566506, 0.08566506, 0.08566506)]
            uniform token purpose = "guide"
            double radius = 0.08566506206989288
            quatd xformOp:orient = (1, 0, 0, 0)
            double3 xformOp:scale = (1, 1, 1)
            double3 xformOp:translate = (0, 0, 0)
            uniform token[] xformOpOrder = ["xformOp:translate", "xformOp:orient", "xformOp:scale"]
        }

        def PhysicsRevoluteJoint "FL_calf_joint" (
            apiSchemas = ["PhysxJointAPI", "PhysicsJointStateAPI:angular", "PhysicsDriveAPI:angular"]
        )
        {
            float drive:angular:physics:damping = 0
            float drive:angular:physics:maxForce = 60
            float drive:angular:physics:stiffness = 0
            uniform token drive:angular:physics:type = "force"
            uniform token physics:axis = "Y"
            rel physics:body0 = </quadruped_robot/FL_knee>
            rel physics:body1 = </quadruped_robot/FL_calf>
            float physics:breakForce = 3.4028235e38
            float physics:breakTorque = 3.4028235e38
            point3f physics:localPos0 = (0, 0, 0)
            point3f physics:localPos1 = (0, 0, 0)
            quatf physics:localRot0 = (1, 0, 0, 0)
            quatf physics:localRot1 = (1, 0, 0, 0)
            float physics:lowerLimit = -180
            float physics:upperLimit = 180
            float physxJoint:maxJointVelocity = 3002.2988
        }
    }

    def Xform "FL_calf" (
        apiSchemas = ["PhysicsRigidBodyAPI", "PhysicsMassAPI"]
    )
    {
        point3f physics:centerOfMass = (0, 0, -0.13854443)
        float3 physics:diagonalInertia = (0.019298477, 0.019298477, 0.006523957)
        float physics:mass = 1.974089
        quatf physics:principalAxes = (1, 0, 0, 0)
        quatd xformOp:orient = (1, 0, 0, 0)
        double3 xformOp:scale = (1, 1, 1)
        double3 xformOp:translate = (0.5289368629455566, 0.2681714594364166, -0.4562006890773773)
        uniform token[] xformOpOrder = ["xformOp:translate", "xformOp:orient", "xformOp:scale"]

        def Cylinder "visuals"
        {
            uniform token axis = "Z"
            float3[] extent = [(-0.081299365, -0.081299365, -0.15722407), (0.081299365, 0.081299365, 0.15722407)]
            double height = 0.31444814801216125
            double radius = 0.08129936456680298
            quatd xformOp:orient = (1, 0, 0, 0)
            double3 xformOp:scale = (1, 1, 1)
            double3 xformOp:translate = (0, 0, -0.15722407400608063)
            uniform token[] xformOpOrder = ["xformOp:translate", "xformOp:orient", "xformOp:scale"]
        }

        def Cylinder "collisions" (
            apiSchemas = ["PhysicsCollisionAPI"]
        )
        {
            uniform token axis = "Z"
            float3[] extent = [(-0.081299365, -0.081299365, -0.15722407), (0.081299365, 0.081299365, 0.15722407)]
            double height = 0.31444814801216125
            uniform token purpose = "guide"
            double radius = 0.08129936456680298
            quatd xformOp:orient = (1, 0, 0, 0)
            double3 xformOp:scale = (1, 1, 1)
            double3 xformOp:translate = (0, 0, -0.15722407400608063)
            uniform token[] xformOpOrder = ["xformOp:translate", "xformOp:orient", "xformOp:scale"]
        }

        def PhysicsFixedJoint "FL_foot_joint"
        {
            rel physics:body0 = </quadruped_robot/FL_calf>
            rel physics:body1 = </quadruped_robot/FL_foot>
            float physics:breakForce = 3.4028235e38
            float physics:breakTorque = 3.4028235e38
            point3f physics:localPos0 = (0, 0, -0.31444815)
            point3f physics:localPos1 = (0, 0, 0)
            quatf physics:localRot0 = (1, 0, 0, 0)
            quatf physics:localRot1 = (1, 0, 0, 0)
        }
    }

    def Xform "FL_foot" (
        apiSchemas = ["PhysicsRigidBodyAPI", "PhysicsMassAPI"]
    )
    {
        point3f physics:centerOfMass = (0, 0, 0.056909557)
        float3 physics:diagonalInertia = (0.0019365915, 0.0019365915, 0.0019365915)
        float physics:mass = 1.4948844
        quatf physics:principalAxes = (1, 0, 0, 0)
        quatd xformOp:orient = (1, 0, 0, 0)
        double3 xformOp:scale = (1, 1, 1)
        double3 xformOp:translate = (0.5289368629455566, 0.2681714594364166, -0.7706488370895386)
        uniform token[] xformOpOrder = ["xformOp:translate", "xformOp:orient", "xformOp:scale"]

        def Sphere "visuals"
        {
            float3[] extent = [(-0.056909557, -0.056909557, -0.056909557), (0.056909557, 0.056909557, 0.056909557)]
            double radius = 0.056909557431936264
            quatd xformOp:orient = (1, 0, 0, 0)
            double3 xformOp:scale = (1, 1, 1)
            double3 xformOp:translate = (0, 0, 0)
            uniform token[] xformOpOrder = ["xformOp:translate", "xformOp:orient", "xformOp:scale"]
        }

        def Sphere "collisions" (
            apiSchemas = ["PhysicsCollisionAPI"]
        )
        {
            float3[] extent = [(-0.056909557, -0.056909557, -0.056909557), (0.056909557, 0.056909557, 0.056909557)]
            uniform token purpose = "guide"
            double radius = 0.056909557431936264
            quatd xformOp:orient = (1, 0, 0, 0)
            double3 xformOp:scale = (1, 1, 1)
            double3 xformOp:translate = (0, 0, 0)
            uniform token[] xformOpOrder = ["xformOp:translate", "xformOp:orient", "xformOp:scale"]
        }
    }

    def Xform "FR_hip" (
        apiSchemas = ["PhysicsRigidBodyAPI", "PhysicsMassAPI"]
    )
    {
        point3f physics:centerOfMass = (0, 0, 0.08566506)
        float3 physics:diagonalInertia = (0.00532404, 0.00532404, 0.00532404)
        float physics:mass = 1.8137352
        quatf physics:principalAxes = (1, 0, 0, 0)
        quatd xformOp:orient = (1, 0, 0, 0)
        double3 xformOp:scale = (1, 1, 1)
        double3 xformOp:translate = (0.5289368629455566, -0.2681714594364166, -0.09523596614599228)
        uniform token[] xformOpOrder = ["xformOp:translate", "xformOp:orient", "xformOp:scale"]

        def Sphere "visuals"
        {
            float3[] extent = [(-0.08566506, -0.08566506, -0.08566506), (0.08566506, 0.08566506, 0.08566506)]
            double radius = 0.08566506206989288
            quatd xformOp:orient = (1, 0, 0, 0)
            double3 xformOp:scale = (1, 1, 1)
            double3 xformOp:translate = (0, 0, 0)
            uniform token[] xformOpOrder = ["xformOp:translate", "xformOp:orient", "xformOp:scale"]
        }

        def Sphere "collisions" (
            apiSchemas = ["PhysicsCollisionAPI"]
        )
        {
            float3[] extent = [(-0.08566506, -0.08566506, -0.08566506), (0.08566506, 0.08566506, 0.08566506)]
            uniform token purpose = "guide"
            double radius = 0.08566506206989288
            quatd xformOp:orient = (1, 0, 0, 0)
            double3 xformOp:scale = (1, 1, 1)
            double3 xformOp:translate = (0, 0, 0)
            uniform token[] xformOpOrder = ["xformOp:translate", "xformOp:orient", "xformOp:scale"]
        }

        def PhysicsRevoluteJoint "FR_thigh_joint" (
            apiSchemas = ["PhysxJointAPI", "PhysicsJointStateAPI:angular", "PhysicsDriveAPI:angular"]
        )
        {
            float drive:angular:physics:damping = 0
            float drive:angular:physics:maxForce = 60
            float drive:angular:physics:stiffness = 0
            uniform token drive:angular:physics:type = "force"
            uniform token physics:axis = "Y"
            rel physics:body0 = </quadruped_robot/FR_hip>
            rel physics:body1 = </quadruped_robot/FR_thigh>
            float physics:breakForce = 3.4028235e38
            float physics:breakTorque = 3.4028235e38
            point3f physics:localPos0 = (0, 0, 0)
            point3f physics:localPos1 = (0, 0, 0)
            quatf physics:localRot0 = (1, 0, 0, 0)
            quatf physics:localRot1 = (1, 0, 0, 0)
            float physics:lowerLimit = -180
            float physics:upperLimit = 180
            float physxJoint:maxJointVelocity = 3002.2988
        }
    }

    def Xform "FR_thigh" (
        apiSchemas = ["PhysicsRigidBodyAPI", "PhysicsMassAPI"]
    )
    {
        point3f physics:centerOfMass = (0, 0, -0.23016083)
        float3 physics:diagonalInertia = (0.016445579, 0.016445579, 0.00508368)
        float physics:mass = 1.3854816
        quatf physics:principalAxes = (1, 0, 0, 0)
        quatd xformOp:orient = (1, 0, 0, 0)
        double3 xformOp:scale = (1, 1, 1)
        double3 xformOp:translate = (0.5289368629455566, -0.2681714594364166, -0.09523596614599228)
        uniform token[] xformOpOrder = ["xformOp:translate", "xformOp:orient", "xformOp:scale"]

        def Cylinder "visuals"
        {
            uniform token axis = "Z"
            float3[] extent = [(-0.08566506, -0.08566506, -0.18048236), (0.08566506, 0.08566506, 0.18048236)]
            double height = 0.36096471548080444
            double radius = 0.08566506206989288
            quatd xformOp:orient = (1, 0, 0, 0)
            double3 xformOp:scale = (1, 1, 1)
            double3 xformOp:translate = (0, 0, -0.18048235774040222)
            uniform token[] xformOpOrder = ["xformOp:translate", "xformOp:orient", "xformOp:scale"]
        }

        def Cylinder "collisions" (
            apiSchemas = ["PhysicsCollisionAPI"]
        )
        {
            uniform token axis = "Z"
            float3[] extent = [(-0.08566506, -0.08566506, -0.18048236), (0.08566506, 0.08566506, 0.18048236)]
            double height = 0.36096471548080444
            uniform token purpose = "guide"
            double radius = 0.08566506206989288
            quatd xformOp:orient = (1, 0, 0, 0)
            double3 xformOp:scale = (1, 1, 1)
            double3 xformOp:translate = (0, 0, -0.18048235774040222)
            uniform token[] xformOpOrder = ["xformOp:translate", "xformOp:orient", "xformOp:scale"]
        }

        def PhysicsFixedJoint "FR_knee_joint"
        {
            rel physics:body0 = </quadruped_robot/FR_thigh>
            rel physics:body1 = </quadruped_robot/FR_knee>
            float physics:breakForce = 3.4028235e38
            float physics:breakTorque = 3.4028235e38
            point3f physics:localPos0 = (0, 0, -0.36096472)
            point3f physics:localPos1 = (0, 0, 0)
            quatf physics:localRot0 = (1, 0, 0, 0)
            quatf physics:localRot1 = (1, 0, 0, 0)
        }
    }

    def Xform "FR_knee" (
        apiSchemas = ["PhysicsRigidBodyAPI", "PhysicsMassAPI"]
    )
    {
        point3f physics:centerOfMass = (0, 0, 0.08566506)
        float3 physics:diagonalInertia = (0.0046963, 0.0046963, 0.0046963)
        float physics:mass = 1.5998837
        quatf physics:principalAxes = (1, 0, 0, 0)
        quatd xformOp:orient = (1, 0, 0, 0)
        double3 xformOp:scale = (1, 1, 1)
        double3 xformOp:translate = (0.5289368629455566, -0.2681714594364166, -0.4562006890773773)
        uniform token[] xformOpOrder = ["xformOp:translate", "xformOp:orient", "xformOp:scale"]

        def Sphere "visuals"
        {
            float3[] extent = [(-0.08566506, -0.08566506, -0.08566506), (0.08566506, 0.08566506, 0.08566506)]
            double radius = 0.08566506206989288
            quatd xformOp:orient = (1, 0, 0, 0)
            double3 xformOp:scale = (1, 1, 1)
            double3 xformOp:translate = (0, 0, 0)
            uniform token[] xformOpOrder = ["xformOp:translate", "xformOp:orient", "xformOp:scale"]
        }

        def Sphere "collisions" (
            apiSchemas = ["PhysicsCollisionAPI"]
        )
        {
            float3[] extent = [(-0.08566506, -0.08566506, -0.08566506), (0.08566506, 0.08566506, 0.08566506)]
            uniform token purpose = "guide"
            double radius = 0.08566506206989288
            quatd xformOp:orient = (1, 0, 0, 0)
            double3 xformOp:scale = (1, 1, 1)
            double3 xformOp:translate = (0, 0, 0)
            uniform token[] xformOpOrder = ["xformOp:translate", "xformOp:orient", "xformOp:scale"]
        }

        def PhysicsRevoluteJoint "FR_calf_joint" (
            apiSchemas = ["PhysxJointAPI", "PhysicsJointStateAPI:angular", "PhysicsDriveAPI:angular"]
        )
        {
            float drive:angular:physics:damping = 0
            float drive:angular:physics:maxForce = 60
            float drive:angular:physics:stiffness = 0
            uniform token drive:angular:physics:type = "force"
            uniform token physics:axis = "Y"
            rel physics:body0 = </quadruped_robot/FR_knee>
            rel physics:body1 = </quadruped_robot/FR_calf>
            float physics:breakForce = 3.4028235e38
            float physics:breakTorque = 3.4028235e38
            point3f physics:localPos0 = (0, 0, 0)
            point3f physics:localPos1 = (0, 0, 0)
            quatf physics:localRot0 = (1, 0, 0, 0)
            quatf physics:localRot1 = (1, 0, 0, 0)
            float physics:lowerLimit = -180
            float physics:upperLimit = 180
            float physxJoint:maxJointVelocity = 3002.2988
        }
    }

    def Xform "FR_calf" (
        apiSchemas = ["PhysicsRigidBodyAPI", "PhysicsMassAPI"]
    )
    {
        point3f physics:centerOfMass = (0, 0, -0.094433606)
        float3 physics:diagonalInertia = (0.014993035, 0.014993035, 0.005776285)
        float physics:mass = 1.7478504
        quatf physics:principalAxes = (1, 0, 0, 0)
        quatd xformOp:orient = (1, 0, 0, 0)
        double3 xformOp:scale = (1, 1, 1)
        double3 xformOp:translate = (0.5289368629455566, -0.2681714594364166, -0.4562006890773773)
        uniform token[] xformOpOrder = ["xformOp:translate", "xformOp:orient", "xformOp:scale"]

        def Cylinder "visuals"
        {
            uniform token axis = "Z"
            float3[] extent = [(-0.081299365, -0.081299365, -0.15722407), (0.081299365, 0.081299365, 0.15722407)]
            double height = 0.31444814801216125
            double radius = 0.08129936456680298
            quatd xformOp:orient = (1, 0, 0, 0)
            double3 xformOp:scale = (1, 1, 1)
            double3 xformOp:translate = (0, 0, -0.15722407400608063)
            uniform token[] xformOpOrder = ["xformOp:translate", "xformOp:orient", "xformOp:scale"]
        }

        def Cylinder "collisions" (
            apiSchemas = ["PhysicsCollisionAPI"]
        )
        {
            uniform token axis = "Z"
            float3[] extent = [(-0.081299365, -0.081299365, -0.15722407), (0.081299365, 0.081299365, 0.15722407)]
            double height = 0.31444814801216125
            uniform token purpose = "guide"
            double radius = 0.08129936456680298
            quatd xformOp:orient = (1, 0, 0, 0)
            double3 xformOp:scale = (1, 1, 1)
            double3 xformOp:translate = (0, 0, -0.15722407400608063)
            uniform token[] xformOpOrder = ["xformOp:translate", "xformOp:orient", "xformOp:scale"]
        }

        def PhysicsFixedJoint "FR_foot_joint"
        {
            rel physics:body0 = </quadruped_robot/FR_calf>
            rel physics:body1 = </quadruped_robot/FR_foot>
            float physics:breakForce = 3.4028235e38
            float physics:breakTorque = 3.4028235e38
            point3f physics:localPos0 = (0, 0, -0.31444815)
            point3f physics:localPos1 = (0, 0, 0)
            quatf physics:localRot0 = (1, 0, 0, 0)
            quatf physics:localRot1 = (1, 0, 0, 0)
        }
    }

    def Xform "FR_foot" (
        apiSchemas = ["PhysicsRigidBodyAPI", "PhysicsMassAPI"]
    )
    {
        point3f physics:centerOfMass = (0, 0, 0.056909557)
        float3 physics:diagonalInertia = (0.0015279944, 0.0015279944, 0.0015279944)
        float physics:mass = 1.1794821
        quatf physics:principalAxes = (1, 0, 0, 0)
        quatd xformOp:orient = (1, 0, 0, 0)
        double3 xformOp:scale = (1, 1, 1)
        double3 xformOp:translate = (0.5289368629455566, -0.2681714594364166, -0.7706488370895386)
        uniform token[] xformOpOrder = ["xformOp:translate", "xformOp:orient", "xformOp:scale"]

        def Sphere "visuals"
        {
            float3[] extent = [(-0.056909557, -0.056909557, -0.056909557), (0.056909557, 0.056909557, 0.056909557)]
            double radius = 0.056909557431936264
            quatd xformOp:orient = (1, 0, 0, 0)
            double3 xformOp:scale = (1, 1, 1)
            double3 xformOp:translate = (0, 0, 0)
            uniform token[] xformOpOrder = ["xformOp:translate", "xformOp:orient", "xformOp:scale"]
        }

        def Sphere "collisions" (
            apiSchemas = ["PhysicsCollisionAPI"]
        )
        {
            float3[] extent = [(-0.056909557, -0.056909557, -0.056909557), (0.056909557, 0.056909557, 0.056909557)]
            uniform token purpose = "guide"
            double radius = 0.056909557431936264
            quatd xformOp:orient = (1, 0, 0, 0)
            double3 xformOp:scale = (1, 1, 1)
            double3 xformOp:translate = (0, 0, 0)
            uniform token[] xformOpOrder = ["xformOp:translate", "xformOp:orient", "xformOp:scale"]
        }
    }

    def Xform "RL_hip" (
        apiSchemas = ["PhysicsRigidBodyAPI", "PhysicsMassAPI"]
    )
    {
        point3f physics:centerOfMass = (0, 0, 0.08713908)
        float3 physics:diagonalInertia = (0.0033998014, 0.0033998014, 0.0033998014)
        float physics:mass = 1.1193545
        quatf physics:principalAxes = (1, 0, 0, 0)
        quatd xformOp:orient = (1, 0, 0, 0)
        double3 xformOp:scale = (1, 1, 1)
        double3 xformOp:translate = (-0.5289368629455566, 0.2681714594364166, -0.09523596614599228)
        uniform token[] xformOpOrder = ["xformOp:translate", "xformOp:orient", "xformOp:scale"]

        def Sphere "visuals"
        {
            float3[] extent = [(-0.08713908, -0.08713908, -0.08713908), (0.08713908, 0.08713908, 0.08713908)]
            double radius = 0.0871390774846077
            quatd xformOp:orient = (1, 0, 0, 0)
            double3 xformOp:scale = (1, 1, 1)
            double3 xformOp:translate = (0, 0, 0)
            uniform token[] xformOpOrder = ["xformOp:translate", "xformOp:orient", "xformOp:scale"]
        }

        def Sphere "collisions" (
            apiSchemas = ["PhysicsCollisionAPI"]
        )
        {
            float3[] extent = [(-0.08713908, -0.08713908, -0.08713908), (0.08713908, 0.08713908, 0.08713908)]
            uniform token purpose = "guide"
            double radius = 0.0871390774846077
            quatd xformOp:orient = (1, 0, 0, 0)
            double3 xformOp:scale = (1, 1, 1)
            double3 xformOp:translate = (0, 0, 0)
            uniform token[] xformOpOrder = ["xformOp:translate", "xformOp:orient", "xformOp:scale"]
        }

        def PhysicsRevoluteJoint "RL_thigh_joint" (
            apiSchemas = ["PhysxJointAPI", "PhysicsJointStateAPI:angular", "PhysicsDriveAPI:angular"]
        )
        {
            float drive:angular:physics:damping = 0
            float drive:angular:physics:maxForce = 60
            float drive:angular:physics:stiffness = 0
            uniform token drive:angular:physics:type = "force"
            uniform token physics:axis = "Y"
            rel physics:body0 = </quadruped_robot/RL_hip>
            rel physics:body1 = </quadruped_robot/RL_thigh>
            float physics:breakForce = 3.4028235e38
            float physics:breakTorque = 3.4028235e38
            point3f physics:localPos0 = (0, 0, 0)
            point3f physics:localPos1 = (0, 0, 0)
            quatf physics:localRot0 = (1, 0, 0, 0)
            quatf physics:localRot1 = (1, 0, 0, 0)
            float physics:lowerLimit = -180
            float physics:upperLimit = 180
            float physxJoint:maxJointVelocity = 3002.2988
        }
    }

    def Xform "RL_thigh" (
        apiSchemas = ["PhysicsRigidBodyAPI", "PhysicsMassAPI"]
    )
    {
        point3f physics:centerOfMass = (0, 0, -0.33984515)
        float3 physics:diagonalInertia = (0.02114557, 0.02114557, 0.0027493539)
        float physics:mass = 0.7241603
        quatf physics:principalAxes = (1, 0, 0, 0)
        quatd xformOp:orient = (1, 0, 0, 0)
        double3 xformOp:scale = (1, 1, 1)
        double3 xformOp:translate = (-0.5289368629455566, 0.2681714594364166, -0.09523596614599228)
        uniform token[] xformOpOrder = ["xformOp:translate", "xformOp:orient", "xformOp:scale"]

        def Cylinder "visuals"
        {
            uniform token axis = "Z"
            float3[] extent = [(-0.08713908, -0.08713908, -0.29042664), (0.08713908, 0.08713908, 0.29042664)]
            double height = 0.580853283405304
            double radius = 0.0871390774846077
            quatd xformOp:orient = (1, 0, 0, 0)
            double3 xformOp:scale = (1, 1, 1)
            double3 xformOp:translate = (0, 0, -0.290426641702652)
            uniform token[] xformOpOrder = ["xformOp:translate", "xformOp:orient", "xformOp:scale"]
        }

        def Cylinder "collisions" (
            apiSchemas = ["PhysicsCollisionAPI"]
        )
        {
            uniform token axis = "Z"
            float3[] extent = [(-0.08713908, -0.08713908, -0.29042664), (0.08713908, 0.08713908, 0.29042664)]
            double height = 0.580853283405304
            uniform token purpose = "guide"
            double radius = 0.0871390774846077
            quatd xformOp:orient = (1, 0, 0, 0)
            double3 xformOp:scale = (1, 1, 1)
            double3 xformOp:translate = (0, 0, -0.290426641702652)
            uniform token[] xformOpOrder = ["xformOp:translate", "xformOp:orient", "xformOp:scale"]
        }

        def PhysicsFixedJoint "RL_knee_joint"
        {
            rel physics:body0 = </quadruped_robot/RL_thigh>
            rel physics:body1 = </quadruped_robot/RL_knee>
            float physics:breakForce = 3.4028235e38
            float physics:breakTorque = 3.4028235e38
            point3f physics:localPos0 = (0, 0, -0.5808533)
            point3f physics:localPos1 = (0, 0, 0)
            quatf physics:localRot0 = (1, 0, 0, 0)
            quatf physics:localRot1 = (1, 0, 0, 0)
        }
    }

    def Xform "RL_knee" (
        apiSchemas = ["PhysicsRigidBodyAPI", "PhysicsMassAPI"]
    )
    {
        point3f physics:centerOfMass = (0, 0, 0.08713908)
        float3 physics:diagonalInertia = (0.0044868602, 0.0044868602, 0.0044868602)
        float physics:mass = 1.477259
        quatf physics:principalAxes = (1, 0, 0, 0)
        quatd xformOp:orient = (1, 0, 0, 0)
        double3 xformOp:scale = (1, 1, 1)
        double3 xformOp:translate = (-0.5289368629455566, 0.2681714594364166, -0.6760892271995544)
        uniform token[] xformOpOrder = ["xformOp:translate", "xformOp:orient", "xformOp:scale"]

        def Sphere "visuals"
        {
            float3[] extent = [(-0.08713908, -0.08713908, -0.08713908), (0.08713908, 0.08713908, 0.08713908)]
            double radius = 0.0871390774846077
            quatd xformOp:orient = (1, 0, 0, 0)
            double3 xformOp:scale = (1, 1, 1)
            double3 xformOp:translate = (0, 0, 0)
            uniform token[] xformOpOrder = ["xformOp:translate", "xformOp:orient", "xformOp:scale"]
        }

        def Sphere "collisions" (
            apiSchemas = ["PhysicsCollisionAPI"]
        )
        {
            float3[] extent = [(-0.08713908, -0.08713908, -0.08713908), (0.08713908, 0.08713908, 0.08713908)]
            uniform token purpose = "guide"
            double radius = 0.0871390774846077
            quatd xformOp:orient = (1, 0, 0, 0)
            double3 xformOp:scale = (1, 1, 1)
            double3 xformOp:translate = (0, 0, 0)
            uniform token[] xformOpOrder = ["xformOp:translate", "xformOp:orient", "xformOp:scale"]
        }

        def PhysicsRevoluteJoint "RL_calf_joint" (
            apiSchemas = ["PhysxJointAPI", "PhysicsJointStateAPI:angular", "PhysicsDriveAPI:angular"]
        )
        {
            float drive:angular:physics:damping = 0
            float drive:angular:physics:maxForce = 60
            float drive:angular:physics:stiffness = 0
            uniform token drive:angular:physics:type = "force"
            uniform token physics:axis = "Y"
            rel physics:body0 = </quadruped_robot/RL_knee>
            rel physics:body1 = </quadruped_robot/RL_calf>
            float physics:breakForce = 3.4028235e38
            float physics:breakTorque = 3.4028235e38
            point3f physics:localPos0 = (0, 0, 0)
            point3f physics:localPos1 = (0, 0, 0)
            quatf physics:localRot0 = (1, 0, 0, 0)
            quatf physics:localRot1 = (1, 0, 0, 0)
            float physics:lowerLimit = -180
            float physics:upperLimit = 180
            float physxJoint:maxJointVelocity = 3002.2988
        }
    }

    def Xform "RL_calf" (
        apiSchemas = ["PhysicsRigidBodyAPI", "PhysicsMassAPI"]
    )
    {
        point3f physics:centerOfMass = (0, 0, -0.098548114)
        float3 physics:diagonalInertia = (0.021258773, 0.021258773, 0.005580486)
        float physics:mass = 1.6308337
        quatf physics:principalAxes = (1, 0, 0, 0)
        quatd xformOp:orient = (1, 0, 0, 0)
        double3 xformOp:scale = (1, 1, 1)
        double3 xformOp:translate = (-0.5289368629455566, 0.2681714594364166, -0.6760892271995544)
        uniform token[] xformOpOrder = ["xformOp:translate", "xformOp:orient", "xformOp:scale"]

        def Cylinder "visuals"
        {
            uniform token axis = "Z"
            float3[] extent = [(-0.082726784, -0.082726784, -0.22164561), (0.082726784, 0.082726784, 0.22164561)]
            double height = 0.44329121708869934
            double radius = 0.08272678405046463
            quatd xformOp:orient = (1, 0, 0, 0)
            double3 xformOp:scale = (1, 1, 1)
            double3 xformOp:translate = (0, 0, -0.22164560854434967)
            uniform token[] xformOpOrder = ["xformOp:translate", "xformOp:orient", "xformOp:scale"]
        }

        def Cylinder "collisions" (
            apiSchemas = ["PhysicsCollisionAPI"]
        )
        {
            uniform token axis = "Z"
            float3[] extent = [(-0.082726784, -0.082726784, -0.22164561), (0.082726784, 0.082726784, 0.22164561)]
            double height = 0.44329121708869934
            uniform token purpose = "guide"
            double radius = 0.08272678405046463
            quatd xformOp:orient = (1, 0, 0, 0)
            double3 xformOp:scale = (1, 1, 1)
            double3 xformOp:translate = (0, 0, -0.22164560854434967)
            uniform token[] xformOpOrder = ["xformOp:translate", "xformOp:orient", "xformOp:scale"]
        }

        def PhysicsFixedJoint "RL_foot_joint"
        {
            rel physics:body0 = </quadruped_robot/RL_calf>
            rel physics:body1 = </quadruped_robot/RL_foot>
            float physics:breakForce = 3.4028235e38
            float physics:breakTorque = 3.4028235e38
            point3f physics:localPos0 = (0, 0, -0.44329122)
            point3f physics:localPos1 = (0, 0, 0)
            quatf physics:localRot0 = (1, 0, 0, 0)
            quatf physics:localRot1 = (1, 0, 0, 0)
        }
    }

    def Xform "RL_foot" (
        apiSchemas = ["PhysicsRigidBodyAPI", "PhysicsMassAPI"]
    )
    {
        point3f physics:centerOfMass = (0, 0, 0.056909557)
        float3 physics:diagonalInertia = (0.002536128, 0.002536128, 0.002536128)
        float physics:mass = 1.9576757
        quatf physics:principalAxes = (1, 0, 0, 0)
        quatd xformOp:orient = (1, 0, 0, 0)
        double3 xformOp:scale = (1, 1, 1)
        double3 xformOp:translate = (-0.5289368629455566, 0.2681714594364166, -1.1193804740905762)
        uniform token[] xformOpOrder = ["xformOp:translate", "xformOp:orient", "xformOp:scale"]

        def Sphere "visuals"
        {
            float3[] extent = [(-0.056909557, -0.056909557, -0.056909557), (0.056909557, 0.056909557, 0.056909557)]
            double radius = 0.056909557431936264
            quatd xformOp:orient = (1, 0, 0, 0)
            double3 xformOp:scale = (1, 1, 1)
            double3 xformOp:translate = (0, 0, 0)
            uniform token[] xformOpOrder = ["xformOp:translate", "xformOp:orient", "xformOp:scale"]
        }

        def Sphere "collisions" (
            apiSchemas = ["PhysicsCollisionAPI"]
        )
        {
            float3[] extent = [(-0.056909557, -0.056909557, -0.056909557), (0.056909557, 0.056909557, 0.056909557)]
            uniform token purpose = "guide"
            double radius = 0.056909557431936264
            quatd xformOp:orient = (1, 0, 0, 0)
            double3 xformOp:scale = (1, 1, 1)
            double3 xformOp:translate = (0, 0, 0)
            uniform token[] xformOpOrder = ["xformOp:translate", "xformOp:orient", "xformOp:scale"]
        }
    }

    def Xform "RR_hip" (
        apiSchemas = ["PhysicsRigidBodyAPI", "PhysicsMassAPI"]
    )
    {
        point3f physics:centerOfMass = (0, 0, 0.08713908)
        float3 physics:diagonalInertia = (0.0042124726, 0.0042124726, 0.0042124726)
        float physics:mass = 1.3869194
        quatf physics:principalAxes = (1, 0, 0, 0)
        quatd xformOp:orient = (1, 0, 0, 0)
        double3 xformOp:scale = (1, 1, 1)
        double3 xformOp:translate = (-0.5289368629455566, -0.2681714594364166, -0.09523596614599228)
        uniform token[] xformOpOrder = ["xformOp:translate", "xformOp:orient", "xformOp:scale"]

        def Sphere "visuals"
        {
            float3[] extent = [(-0.08713908, -0.08713908, -0.08713908), (0.08713908, 0.08713908, 0.08713908)]
            double radius = 0.0871390774846077
            quatd xformOp:orient = (1, 0, 0, 0)
            double3 xformOp:scale = (1, 1, 1)
            double3 xformOp:translate = (0, 0, 0)
            uniform token[] xformOpOrder = ["xformOp:translate", "xformOp:orient", "xformOp:scale"]
        }

        def Sphere "collisions" (
            apiSchemas = ["PhysicsCollisionAPI"]
        )
        {
            float3[] extent = [(-0.08713908, -0.08713908, -0.08713908), (0.08713908, 0.08713908, 0.08713908)]
            uniform token purpose = "guide"
            double radius = 0.0871390774846077
            quatd xformOp:orient = (1, 0, 0, 0)
            double3 xformOp:scale = (1, 1, 1)
            double3 xformOp:translate = (0, 0, 0)
            uniform token[] xformOpOrder = ["xformOp:translate", "xformOp:orient", "xformOp:scale"]
        }

        def PhysicsRevoluteJoint "RR_thigh_joint" (
            apiSchemas = ["PhysxJointAPI", "PhysicsJointStateAPI:angular", "PhysicsDriveAPI:angular"]
        )
        {
            float drive:angular:physics:damping = 0
            float drive:angular:physics:maxForce = 60
            float drive:angular:physics:stiffness = 0
            uniform token drive:angular:physics:type = "force"
            uniform token physics:axis = "Y"
            rel physics:body0 = </quadruped_robot/RR_hip>
            rel physics:body1 = </quadruped_robot/RR_thigh>
            float physics:breakForce = 3.4028235e38
            float physics:breakTorque = 3.4028235e38
            point3f physics:localPos0 = (0, 0, 0)
            point3f physics:localPos1 = (0, 0, 0)
            quatf physics:localRot0 = (1, 0, 0, 0)
            quatf physics:localRot1 = (1, 0, 0, 0)
            float physics:lowerLimit = -180
            float physics:upperLimit = 180
            float physxJoint:maxJointVelocity = 3002.2988
        }
    }

    def Xform "RR_thigh" (
        apiSchemas = ["PhysicsRigidBodyAPI", "PhysicsMassAPI"]
    )
    {
        point3f physics:centerOfMass = (0, 0, -0.1673336)
        float3 physics:diagonalInertia = (0.017259121, 0.017259121, 0.0026248726)
        float physics:mass = 0.6913728
        quatf physics:principalAxes = (1, 0, 0, 0)
        quatd xformOp:orient = (1, 0, 0, 0)
        double3 xformOp:scale = (1, 1, 1)
        double3 xformOp:translate = (-0.5289368629455566, -0.2681714594364166, -0.09523596614599228)
        uniform token[] xformOpOrder = ["xformOp:translate", "xformOp:orient", "xformOp:scale"]

        def Cylinder "visuals"
        {
            uniform token axis = "Z"
            float3[] extent = [(-0.08713908, -0.08713908, -0.29042664), (0.08713908, 0.08713908, 0.29042664)]
            double height = 0.580853283405304
            double radius = 0.0871390774846077
            quatd xformOp:orient = (1, 0, 0, 0)
            double3 xformOp:scale = (1, 1, 1)
            double3 xformOp:translate = (0, 0, -0.290426641702652)
            uniform token[] xformOpOrder = ["xformOp:translate", "xformOp:orient", "xformOp:scale"]
        }

        def Cylinder "collisions" (
            apiSchemas = ["PhysicsCollisionAPI"]
        )
        {
            uniform token axis = "Z"
            float3[] extent = [(-0.08713908, -0.08713908, -0.29042664), (0.08713908, 0.08713908, 0.29042664)]
            double height = 0.580853283405304
            uniform token purpose = "guide"
            double radius = 0.0871390774846077
            quatd xformOp:orient = (1, 0, 0, 0)
            double3 xformOp:scale = (1, 1, 1)
            double3 xformOp:translate = (0, 0, -0.290426641702652)
            uniform token[] xformOpOrder = ["xformOp:translate", "xformOp:orient", "xformOp:scale"]
        }

        def PhysicsFixedJoint "RR_knee_joint"
        {
            rel physics:body0 = </quadruped_robot/RR_thigh>
            rel physics:body1 = </quadruped_robot/RR_knee>
            float physics:breakForce = 3.4028235e38
            float physics:breakTorque = 3.4028235e38
            point3f physics:localPos0 = (0, 0, -0.5808533)
            point3f physics:localPos1 = (0, 0, 0)
            quatf physics:localRot0 = (1, 0, 0, 0)
            quatf physics:localRot1 = (1, 0, 0, 0)
        }
    }

    def Xform "RR_knee" (
        apiSchemas = ["PhysicsRigidBodyAPI", "PhysicsMassAPI"]
    )
    {
        point3f physics:centerOfMass = (0, 0, 0.08713908)
        float3 physics:diagonalInertia = (0.004588183, 0.004588183, 0.004588183)
        float physics:mass = 1.5106187
        quatf physics:principalAxes = (1, 0, 0, 0)
        quatd xformOp:orient = (1, 0, 0, 0)
        double3 xformOp:scale = (1, 1, 1)
        double3 xformOp:translate = (-0.5289368629455566, -0.2681714594364166, -0.6760892271995544)
        uniform token[] xformOpOrder = ["xformOp:translate", "xformOp:orient", "xformOp:scale"]

        def Sphere "visuals"
        {
            float3[] extent = [(-0.08713908, -0.08713908, -0.08713908), (0.08713908, 0.08713908, 0.08713908)]
            double radius = 0.0871390774846077
            quatd xformOp:orient = (1, 0, 0, 0)
            double3 xformOp:scale = (1, 1, 1)
            double3 xformOp:translate = (0, 0, 0)
            uniform token[] xformOpOrder = ["xformOp:translate", "xformOp:orient", "xformOp:scale"]
        }

        def Sphere "collisions" (
            apiSchemas = ["PhysicsCollisionAPI"]
        )
        {
            float3[] extent = [(-0.08713908, -0.08713908, -0.08713908), (0.08713908, 0.08713908, 0.08713908)]
            uniform token purpose = "guide"
            double radius = 0.0871390774846077
            quatd xformOp:orient = (1, 0, 0, 0)
            double3 xformOp:scale = (1, 1, 1)
            double3 xformOp:translate = (0, 0, 0)
            uniform token[] xformOpOrder = ["xformOp:translate", "xformOp:orient", "xformOp:scale"]
        }

        def PhysicsRevoluteJoint "RR_calf_joint" (
            apiSchemas = ["PhysxJointAPI", "PhysicsJointStateAPI:angular", "PhysicsDriveAPI:angular"]
        )
        {
            float drive:angular:physics:damping = 0
            float drive:angular:physics:maxForce = 60
            float drive:angular:physics:stiffness = 0
            uniform token drive:angular:physics:type = "force"
            uniform token physics:axis = "Y"
            rel physics:body0 = </quadruped_robot/RR_knee>
            rel physics:body1 = </quadruped_robot/RR_calf>
            float physics:breakForce = 3.4028235e38
            float physics:breakTorque = 3.4028235e38
            point3f physics:localPos0 = (0, 0, 0)
            point3f physics:localPos1 = (0, 0, 0)
            quatf physics:localRot0 = (1, 0, 0, 0)
            quatf physics:localRot1 = (1, 0, 0, 0)
            float physics:lowerLimit = -180
            float physics:upperLimit = 180
            float physxJoint:maxJointVelocity = 3002.2988
        }
    }

    def Xform "RR_calf" (
        apiSchemas = ["PhysicsRigidBodyAPI", "PhysicsMassAPI"]
    )
    {
        point3f physics:centerOfMass = (0, 0, -0.33327374)
        float3 physics:diagonalInertia = (0.020327155, 0.020327155, 0.004992259)
        float physics:mass = 1.4589311
        quatf physics:principalAxes = (1, 0, 0, 0)
        quatd xformOp:orient = (1, 0, 0, 0)
        double3 xformOp:scale = (1, 1, 1)
        double3 xformOp:translate = (-0.5289368629455566, -0.2681714594364166, -0.6760892271995544)
        uniform token[] xformOpOrder = ["xformOp:translate", "xformOp:orient", "xformOp:scale"]

        def Cylinder "visuals"
        {
            uniform token axis = "Z"
            float3[] extent = [(-0.082726784, -0.082726784, -0.22164561), (0.082726784, 0.082726784, 0.22164561)]
            double height = 0.44329121708869934
            double radius = 0.08272678405046463
            quatd xformOp:orient = (1, 0, 0, 0)
            double3 xformOp:scale = (1, 1, 1)
            double3 xformOp:translate = (0, 0, -0.22164560854434967)
            uniform token[] xformOpOrder = ["xformOp:translate", "xformOp:orient", "xformOp:scale"]
        }

        def Cylinder "collisions" (
            apiSchemas = ["PhysicsCollisionAPI"]
        )
        {
            uniform token axis = "Z"
            float3[] extent = [(-0.082726784, -0.082726784, -0.22164561), (0.082726784, 0.082726784, 0.22164561)]
            double height = 0.44329121708869934
            uniform token purpose = "guide"
            double radius = 0.08272678405046463
            quatd xformOp:orient = (1, 0, 0, 0)
            double3 xformOp:scale = (1, 1, 1)
            double3 xformOp:translate = (0, 0, -0.22164560854434967)
            uniform token[] xformOpOrder = ["xformOp:translate", "xformOp:orient", "xformOp:scale"]
        }

        def PhysicsFixedJoint "RR_foot_joint"
        {
            rel physics:body0 = </quadruped_robot/RR_calf>
            rel physics:body1 = </quadruped_robot/RR_foot>
            float physics:breakForce = 3.4028235e38
            float physics:breakTorque = 3.4028235e38
            point3f physics:localPos0 = (0, 0, -0.44329122)
            point3f physics:localPos1 = (0, 0, 0)
            quatf physics:localRot0 = (1, 0, 0, 0)
            quatf physics:localRot1 = (1, 0, 0, 0)
        }
    }

    def Xform "RR_foot" (
        apiSchemas = ["PhysicsRigidBodyAPI", "PhysicsMassAPI"]
    )
    {
        point3f physics:centerOfMass = (0, 0, 0.056909557)
        float3 physics:diagonalInertia = (0.00091661874, 0.00091661874, 0.00091661874)
        float physics:mass = 0.70755196
        quatf physics:principalAxes = (1, 0, 0, 0)
        quatd xformOp:orient = (1, 0, 0, 0)
        double3 xformOp:scale = (1, 1, 1)
        double3 xformOp:translate = (-0.5289368629455566, -0.2681714594364166, -1.1193804740905762)
        uniform token[] xformOpOrder = ["xformOp:translate", "xformOp:orient", "xformOp:scale"]

        def Sphere "visuals"
        {
            float3[] extent = [(-0.056909557, -0.056909557, -0.056909557), (0.056909557, 0.056909557, 0.056909557)]
            double radius = 0.056909557431936264
            quatd xformOp:orient = (1, 0, 0, 0)
            double3 xformOp:scale = (1, 1, 1)
            double3 xformOp:translate = (0, 0, 0)
            uniform token[] xformOpOrder = ["xformOp:translate", "xformOp:orient", "xformOp:scale"]
        }

        def Sphere "collisions" (
            apiSchemas = ["PhysicsCollisionAPI"]
        )
        {
            float3[] extent = [(-0.056909557, -0.056909557, -0.056909557), (0.056909557, 0.056909557, 0.056909557)]
            uniform token purpose = "guide"
            double radius = 0.056909557431936264
            quatd xformOp:orient = (1, 0, 0, 0)
            double3 xformOp:scale = (1, 1, 1)
            double3 xformOp:translate = (0, 0, 0)
            uniform token[] xformOpOrder = ["xformOp:translate", "xformOp:orient", "xformOp:scale"]
        }
    }
}

