#usda 1.0
(
    customLayerData = {
        dictionary omni_layer = {
            dictionary locked = {
            }
            dictionary muteness = {
            }
        }
    }
    defaultPrim = "quadruped_robot"
    doc = """Generated from Composed Stage of root layer /home/gpuuser/GitHub/Intelligent-robot-design/generations/generation_1/robot_34.usda
"""
    metersPerUnit = 1
    upAxis = "Z"
)

def Xform "quadruped_robot"
{
    quatd xformOp:orient = (1, 0, 0, 0)
    double3 xformOp:scale = (1, 1, 1)
    double3 xformOp:translate = (0, 0, 0)
    uniform token[] xformOpOrder = ["xformOp:translate", "xformOp:orient", "xformOp:scale"]

    def Scope "Looks"
    {
    }

    def Xform "base" (
        apiSchemas = ["PhysicsRigidBodyAPI", "PhysicsMassAPI", "PhysicsArticulationRootAPI", "PhysxArticulationAPI"]
    )
    {
        point3f physics:centerOfMass = (0, 0, -0.005)
        float3 physics:diagonalInertia = (0.000025149182, 0.000025149182, 0.000025149182)
        float physics:mass = 1.508951
        quatf physics:principalAxes = (1, 0, 0, 0)
        bool physxArticulation:enabledSelfCollisions = 1
        int physxArticulation:solverPositionIterationCount = 32
        int physxArticulation:solverVelocityIterationCount = 1
        quatd xformOp:orient = (1, 0, 0, 0)
        double3 xformOp:scale = (1, 1, 1)
        double3 xformOp:translate = (0, 0, 0)
        uniform token[] xformOpOrder = ["xformOp:translate", "xformOp:orient", "xformOp:scale"]

        def Cube "visuals"
        {
            float3[] extent = [(-0.005, -0.005, -0.005), (0.005, 0.005, 0.005)]
            double size = 1
            quatd xformOp:orient = (1, 0, 0, 0)
            double3 xformOp:scale = (0.009999999776482582, 0.009999999776482582, 0.009999999776482582)
            double3 xformOp:translate = (0, 0, 0)
            uniform token[] xformOpOrder = ["xformOp:translate", "xformOp:orient", "xformOp:scale"]
        }

        def Cube "collisions" (
            apiSchemas = ["PhysicsCollisionAPI"]
        )
        {
            float3[] extent = [(-0.005, -0.005, -0.005), (0.005, 0.005, 0.005)]
            uniform token purpose = "guide"
            double size = 1
            quatd xformOp:orient = (1, 0, 0, 0)
            double3 xformOp:scale = (0.009999999776482582, 0.009999999776482582, 0.009999999776482582)
            double3 xformOp:translate = (0, 0, 0)
            uniform token[] xformOpOrder = ["xformOp:translate", "xformOp:orient", "xformOp:scale"]
        }

        def PhysicsFixedJoint "floating_base"
        {
            rel physics:body0 = </quadruped_robot/base>
            rel physics:body1 = </quadruped_robot/trunk>
            float physics:breakForce = 3.4028235e38
            float physics:breakTorque = 3.4028235e38
            point3f physics:localPos0 = (0, 0, 0)
            point3f physics:localPos1 = (0, 0, 0)
            quatf physics:localRot0 = (1, 0, 0, 0)
            quatf physics:localRot1 = (1, 0, 0, 0)
        }
    }

    def Xform "trunk" (
        apiSchemas = ["PhysicsRigidBodyAPI", "PhysicsMassAPI"]
    )
    {
        point3f physics:centerOfMass = (0, 0, -0.08836427)
        float3 physics:diagonalInertia = (0.06262807, 0.06262807, 0.2585767)
        float physics:mass = 1.9779148
        quatf physics:principalAxes = (1, 0, 0, 0)
        quatd xformOp:orient = (1, 0, 0, 0)
        double3 xformOp:scale = (1, 1, 1)
        double3 xformOp:translate = (0, 0, 0)
        uniform token[] xformOpOrder = ["xformOp:translate", "xformOp:orient", "xformOp:scale"]

        def Cube "visuals"
        {
            float3[] extent = [(-0.5522799, -0.29526734, -0.08836427), (0.5522799, 0.29526734, 0.08836427)]
            double size = 1
            quatd xformOp:orient = (1, 0, 0, 0)
            double3 xformOp:scale = (1.1045597791671753, 0.5905346870422363, 0.17672854661941528)
            double3 xformOp:translate = (0, 0, 0)
            uniform token[] xformOpOrder = ["xformOp:translate", "xformOp:orient", "xformOp:scale"]
        }

        def Cube "collisions" (
            apiSchemas = ["PhysicsCollisionAPI"]
        )
        {
            float3[] extent = [(-0.5522799, -0.29526734, -0.08836427), (0.5522799, 0.29526734, 0.08836427)]
            uniform token purpose = "guide"
            double size = 1
            quatd xformOp:orient = (1, 0, 0, 0)
            double3 xformOp:scale = (1.1045597791671753, 0.5905346870422363, 0.17672854661941528)
            double3 xformOp:translate = (0, 0, 0)
            uniform token[] xformOpOrder = ["xformOp:translate", "xformOp:orient", "xformOp:scale"]
        }

        def PhysicsRevoluteJoint "FL_hip_joint" (
            apiSchemas = ["PhysxJointAPI", "PhysicsJointStateAPI:angular", "PhysicsDriveAPI:angular"]
        )
        {
            float drive:angular:physics:damping = 0
            float drive:angular:physics:maxForce = 60
            float drive:angular:physics:stiffness = 0
            uniform token drive:angular:physics:type = "force"
            uniform token physics:axis = "X"
            rel physics:body0 = </quadruped_robot/trunk>
            rel physics:body1 = </quadruped_robot/FL_hip>
            float physics:breakForce = 3.4028235e38
            float physics:breakTorque = 3.4028235e38
            point3f physics:localPos0 = (0.5522799, 0.29526734, -0.070691414)
            point3f physics:localPos1 = (0, 0, 0)
            quatf physics:localRot0 = (1, 0, 0, 0)
            quatf physics:localRot1 = (1, 0, 0, 0)
            float physics:lowerLimit = -180
            float physics:upperLimit = 180
            float physxJoint:maxJointVelocity = 3002.2988
        }

        def PhysicsRevoluteJoint "FR_hip_joint" (
            apiSchemas = ["PhysxJointAPI", "PhysicsJointStateAPI:angular", "PhysicsDriveAPI:angular"]
        )
        {
            float drive:angular:physics:damping = 0
            float drive:angular:physics:maxForce = 60
            float drive:angular:physics:stiffness = 0
            uniform token drive:angular:physics:type = "force"
            uniform token physics:axis = "X"
            rel physics:body0 = </quadruped_robot/trunk>
            rel physics:body1 = </quadruped_robot/FR_hip>
            float physics:breakForce = 3.4028235e38
            float physics:breakTorque = 3.4028235e38
            point3f physics:localPos0 = (0.5522799, -0.29526734, -0.070691414)
            point3f physics:localPos1 = (0, 0, 0)
            quatf physics:localRot0 = (1, 0, 0, 0)
            quatf physics:localRot1 = (1, 0, 0, 0)
            float physics:lowerLimit = -180
            float physics:upperLimit = 180
            float physxJoint:maxJointVelocity = 3002.2988
        }

        def PhysicsRevoluteJoint "RL_hip_joint" (
            apiSchemas = ["PhysxJointAPI", "PhysicsJointStateAPI:angular", "PhysicsDriveAPI:angular"]
        )
        {
            float drive:angular:physics:damping = 0
            float drive:angular:physics:maxForce = 60
            float drive:angular:physics:stiffness = 0
            uniform token drive:angular:physics:type = "force"
            uniform token physics:axis = "X"
            rel physics:body0 = </quadruped_robot/trunk>
            rel physics:body1 = </quadruped_robot/RL_hip>
            float physics:breakForce = 3.4028235e38
            float physics:breakTorque = 3.4028235e38
            point3f physics:localPos0 = (-0.5522799, 0.29526734, -0.070691414)
            point3f physics:localPos1 = (0, 0, 0)
            quatf physics:localRot0 = (1, 0, 0, 0)
            quatf physics:localRot1 = (1, 0, 0, 0)
            float physics:lowerLimit = -180
            float physics:upperLimit = 180
            float physxJoint:maxJointVelocity = 3002.2988
        }

        def PhysicsRevoluteJoint "RR_hip_joint" (
            apiSchemas = ["PhysxJointAPI", "PhysicsJointStateAPI:angular", "PhysicsDriveAPI:angular"]
        )
        {
            float drive:angular:physics:damping = 0
            float drive:angular:physics:maxForce = 60
            float drive:angular:physics:stiffness = 0
            uniform token drive:angular:physics:type = "force"
            uniform token physics:axis = "X"
            rel physics:body0 = </quadruped_robot/trunk>
            rel physics:body1 = </quadruped_robot/RR_hip>
            float physics:breakForce = 3.4028235e38
            float physics:breakTorque = 3.4028235e38
            point3f physics:localPos0 = (-0.5522799, -0.29526734, -0.070691414)
            point3f physics:localPos1 = (0, 0, 0)
            quatf physics:localRot0 = (1, 0, 0, 0)
            quatf physics:localRot1 = (1, 0, 0, 0)
            float physics:lowerLimit = -180
            float physics:upperLimit = 180
            float physxJoint:maxJointVelocity = 3002.2988
        }
    }

    def Xform "FL_hip" (
        apiSchemas = ["PhysicsRigidBodyAPI", "PhysicsMassAPI"]
    )
    {
        point3f physics:centerOfMass = (0, 0, 0.08890925)
        float3 physics:diagonalInertia = (0.0047348994, 0.0047348994, 0.0047348994)
        float physics:mass = 1.4974655
        quatf physics:principalAxes = (1, 0, 0, 0)
        quatd xformOp:orient = (1, 0, 0, 0)
        double3 xformOp:scale = (1, 1, 1)
        double3 xformOp:translate = (0.5522798895835876, 0.29526734352111816, -0.07069141417741776)
        uniform token[] xformOpOrder = ["xformOp:translate", "xformOp:orient", "xformOp:scale"]

        def Sphere "visuals"
        {
            float3[] extent = [(-0.08890925, -0.08890925, -0.08890925), (0.08890925, 0.08890925, 0.08890925)]
            double radius = 0.08890925347805023
            quatd xformOp:orient = (1, 0, 0, 0)
            double3 xformOp:scale = (1, 1, 1)
            double3 xformOp:translate = (0, 0, 0)
            uniform token[] xformOpOrder = ["xformOp:translate", "xformOp:orient", "xformOp:scale"]
        }

        def Sphere "collisions" (
            apiSchemas = ["PhysicsCollisionAPI"]
        )
        {
            float3[] extent = [(-0.08890925, -0.08890925, -0.08890925), (0.08890925, 0.08890925, 0.08890925)]
            uniform token purpose = "guide"
            double radius = 0.08890925347805023
            quatd xformOp:orient = (1, 0, 0, 0)
            double3 xformOp:scale = (1, 1, 1)
            double3 xformOp:translate = (0, 0, 0)
            uniform token[] xformOpOrder = ["xformOp:translate", "xformOp:orient", "xformOp:scale"]
        }

        def PhysicsRevoluteJoint "FL_thigh_joint" (
            apiSchemas = ["PhysxJointAPI", "PhysicsJointStateAPI:angular", "PhysicsDriveAPI:angular"]
        )
        {
            float drive:angular:physics:damping = 0
            float drive:angular:physics:maxForce = 60
            float drive:angular:physics:stiffness = 0
            uniform token drive:angular:physics:type = "force"
            uniform token physics:axis = "Y"
            rel physics:body0 = </quadruped_robot/FL_hip>
            rel physics:body1 = </quadruped_robot/FL_thigh>
            float physics:breakForce = 3.4028235e38
            float physics:breakTorque = 3.4028235e38
            point3f physics:localPos0 = (0, 0, 0)
            point3f physics:localPos1 = (0, 0, 0)
            quatf physics:localRot0 = (1, 0, 0, 0)
            quatf physics:localRot1 = (1, 0, 0, 0)
            float physics:lowerLimit = -180
            float physics:upperLimit = 180
            float physxJoint:maxJointVelocity = 3002.2988
        }
    }

    def Xform "FL_thigh" (
        apiSchemas = ["PhysicsRigidBodyAPI", "PhysicsMassAPI"]
    )
    {
        point3f physics:centerOfMass = (0, 0, -0.15253891)
        float3 physics:diagonalInertia = (0.007960401, 0.007960401, 0.003232849)
        float physics:mass = 0.81794006
        quatf physics:principalAxes = (1, 0, 0, 0)
        quatd xformOp:orient = (1, 0, 0, 0)
        double3 xformOp:scale = (1, 1, 1)
        double3 xformOp:translate = (0.5522798895835876, 0.29526734352111816, -0.07069141417741776)
        uniform token[] xformOpOrder = ["xformOp:translate", "xformOp:orient", "xformOp:scale"]

        def Cylinder "visuals"
        {
            uniform token axis = "Z"
            float3[] extent = [(-0.08890925, -0.08890925, -0.15253891), (0.08890925, 0.08890925, 0.15253891)]
            double height = 0.30507782101631165
            double radius = 0.08890925347805023
            quatd xformOp:orient = (1, 0, 0, 0)
            double3 xformOp:scale = (1, 1, 1)
            double3 xformOp:translate = (0, 0, -0.15253891050815582)
            uniform token[] xformOpOrder = ["xformOp:translate", "xformOp:orient", "xformOp:scale"]
        }

        def Cylinder "collisions" (
            apiSchemas = ["PhysicsCollisionAPI"]
        )
        {
            uniform token axis = "Z"
            float3[] extent = [(-0.08890925, -0.08890925, -0.15253891), (0.08890925, 0.08890925, 0.15253891)]
            double height = 0.30507782101631165
            uniform token purpose = "guide"
            double radius = 0.08890925347805023
            quatd xformOp:orient = (1, 0, 0, 0)
            double3 xformOp:scale = (1, 1, 1)
            double3 xformOp:translate = (0, 0, -0.15253891050815582)
            uniform token[] xformOpOrder = ["xformOp:translate", "xformOp:orient", "xformOp:scale"]
        }

        def PhysicsFixedJoint "FL_knee_joint"
        {
            rel physics:body0 = </quadruped_robot/FL_thigh>
            rel physics:body1 = </quadruped_robot/FL_knee>
            float physics:breakForce = 3.4028235e38
            float physics:breakTorque = 3.4028235e38
            point3f physics:localPos0 = (0, 0, -0.30507782)
            point3f physics:localPos1 = (0, 0, 0)
            quatf physics:localRot0 = (1, 0, 0, 0)
            quatf physics:localRot1 = (1, 0, 0, 0)
        }
    }

    def Xform "FL_knee" (
        apiSchemas = ["PhysicsRigidBodyAPI", "PhysicsMassAPI"]
    )
    {
        point3f physics:centerOfMass = (0, 0, 0.10685682)
        float3 physics:diagonalInertia = (0.0036336759, 0.0036336759, 0.0036336759)
        float physics:mass = 0.79557604
        quatf physics:principalAxes = (1, 0, 0, 0)
        quatd xformOp:orient = (1, 0, 0, 0)
        double3 xformOp:scale = (1, 1, 1)
        double3 xformOp:translate = (0.5522798895835876, 0.29526734352111816, -0.3757692277431488)
        uniform token[] xformOpOrder = ["xformOp:translate", "xformOp:orient", "xformOp:scale"]

        def Sphere "visuals"
        {
            float3[] extent = [(-0.10685682, -0.10685682, -0.10685682), (0.10685682, 0.10685682, 0.10685682)]
            double radius = 0.1068568229675293
            quatd xformOp:orient = (1, 0, 0, 0)
            double3 xformOp:scale = (1, 1, 1)
            double3 xformOp:translate = (0, 0, 0)
            uniform token[] xformOpOrder = ["xformOp:translate", "xformOp:orient", "xformOp:scale"]
        }

        def Sphere "collisions" (
            apiSchemas = ["PhysicsCollisionAPI"]
        )
        {
            float3[] extent = [(-0.10685682, -0.10685682, -0.10685682), (0.10685682, 0.10685682, 0.10685682)]
            uniform token purpose = "guide"
            double radius = 0.1068568229675293
            quatd xformOp:orient = (1, 0, 0, 0)
            double3 xformOp:scale = (1, 1, 1)
            double3 xformOp:translate = (0, 0, 0)
            uniform token[] xformOpOrder = ["xformOp:translate", "xformOp:orient", "xformOp:scale"]
        }

        def PhysicsRevoluteJoint "FL_calf_joint" (
            apiSchemas = ["PhysxJointAPI", "PhysicsJointStateAPI:angular", "PhysicsDriveAPI:angular"]
        )
        {
            float drive:angular:physics:damping = 0
            float drive:angular:physics:maxForce = 60
            float drive:angular:physics:stiffness = 0
            uniform token drive:angular:physics:type = "force"
            uniform token physics:axis = "Y"
            rel physics:body0 = </quadruped_robot/FL_knee>
            rel physics:body1 = </quadruped_robot/FL_calf>
            float physics:breakForce = 3.4028235e38
            float physics:breakTorque = 3.4028235e38
            point3f physics:localPos0 = (0, 0, 0)
            point3f physics:localPos1 = (0, 0, 0)
            quatf physics:localRot0 = (1, 0, 0, 0)
            quatf physics:localRot1 = (1, 0, 0, 0)
            float physics:lowerLimit = -180
            float physics:upperLimit = 180
            float physxJoint:maxJointVelocity = 3002.2988
        }
    }

    def Xform "FL_calf" (
        apiSchemas = ["PhysicsRigidBodyAPI", "PhysicsMassAPI"]
    )
    {
        point3f physics:centerOfMass = (0, 0, -0.16101232)
        float3 physics:diagonalInertia = (0.0093824295, 0.0093824295, 0.0046594385)
        float physics:mass = 0.8161295
        quatf physics:principalAxes = (1, 0, 0, 0)
        quatd xformOp:orient = (1, 0, 0, 0)
        double3 xformOp:scale = (1, 1, 1)
        double3 xformOp:translate = (0.5522798895835876, 0.29526734352111816, -0.3757692277431488)
        uniform token[] xformOpOrder = ["xformOp:translate", "xformOp:orient", "xformOp:scale"]

        def Cylinder "visuals"
        {
            uniform token axis = "Z"
            float3[] extent = [(-0.10685682, -0.10685682, -0.16101232), (0.10685682, 0.10685682, 0.16101232)]
            double height = 0.3220246434211731
            double radius = 0.1068568229675293
            quatd xformOp:orient = (1, 0, 0, 0)
            double3 xformOp:scale = (1, 1, 1)
            double3 xformOp:translate = (0, 0, -0.16101232171058655)
            uniform token[] xformOpOrder = ["xformOp:translate", "xformOp:orient", "xformOp:scale"]
        }

        def Cylinder "collisions" (
            apiSchemas = ["PhysicsCollisionAPI"]
        )
        {
            uniform token axis = "Z"
            float3[] extent = [(-0.10685682, -0.10685682, -0.16101232), (0.10685682, 0.10685682, 0.16101232)]
            double height = 0.3220246434211731
            uniform token purpose = "guide"
            double radius = 0.1068568229675293
            quatd xformOp:orient = (1, 0, 0, 0)
            double3 xformOp:scale = (1, 1, 1)
            double3 xformOp:translate = (0, 0, -0.16101232171058655)
            uniform token[] xformOpOrder = ["xformOp:translate", "xformOp:orient", "xformOp:scale"]
        }

        def PhysicsFixedJoint "FL_foot_joint"
        {
            rel physics:body0 = </quadruped_robot/FL_calf>
            rel physics:body1 = </quadruped_robot/FL_foot>
            float physics:breakForce = 3.4028235e38
            float physics:breakTorque = 3.4028235e38
            point3f physics:localPos0 = (0, 0, -0.32202464)
            point3f physics:localPos1 = (0, 0, 0)
            quatf physics:localRot0 = (1, 0, 0, 0)
            quatf physics:localRot1 = (1, 0, 0, 0)
        }
    }

    def Xform "FL_foot" (
        apiSchemas = ["PhysicsRigidBodyAPI", "PhysicsMassAPI"]
    )
    {
        point3f physics:centerOfMass = (0, 0, 0.07184092)
        float3 physics:diagonalInertia = (0.0013231311, 0.0013231311, 0.0013231311)
        float physics:mass = 0.640913
        quatf physics:principalAxes = (1, 0, 0, 0)
        quatd xformOp:orient = (1, 0, 0, 0)
        double3 xformOp:scale = (1, 1, 1)
        double3 xformOp:translate = (0.5522798895835876, 0.29526734352111816, -0.6977938413619995)
        uniform token[] xformOpOrder = ["xformOp:translate", "xformOp:orient", "xformOp:scale"]

        def Sphere "visuals"
        {
            float3[] extent = [(-0.07184092, -0.07184092, -0.07184092), (0.07184092, 0.07184092, 0.07184092)]
            double radius = 0.07184091955423355
            quatd xformOp:orient = (1, 0, 0, 0)
            double3 xformOp:scale = (1, 1, 1)
            double3 xformOp:translate = (0, 0, 0)
            uniform token[] xformOpOrder = ["xformOp:translate", "xformOp:orient", "xformOp:scale"]
        }

        def Sphere "collisions" (
            apiSchemas = ["PhysicsCollisionAPI"]
        )
        {
            float3[] extent = [(-0.07184092, -0.07184092, -0.07184092), (0.07184092, 0.07184092, 0.07184092)]
            uniform token purpose = "guide"
            double radius = 0.07184091955423355
            quatd xformOp:orient = (1, 0, 0, 0)
            double3 xformOp:scale = (1, 1, 1)
            double3 xformOp:translate = (0, 0, 0)
            uniform token[] xformOpOrder = ["xformOp:translate", "xformOp:orient", "xformOp:scale"]
        }
    }

    def Xform "FR_hip" (
        apiSchemas = ["PhysicsRigidBodyAPI", "PhysicsMassAPI"]
    )
    {
        point3f physics:centerOfMass = (0, 0, 0.08890925)
        float3 physics:diagonalInertia = (0.0033052943, 0.0033052943, 0.0033052943)
        float physics:mass = 1.0453367
        quatf physics:principalAxes = (1, 0, 0, 0)
        quatd xformOp:orient = (1, 0, 0, 0)
        double3 xformOp:scale = (1, 1, 1)
        double3 xformOp:translate = (0.5522798895835876, -0.29526734352111816, -0.07069141417741776)
        uniform token[] xformOpOrder = ["xformOp:translate", "xformOp:orient", "xformOp:scale"]

        def Sphere "visuals"
        {
            float3[] extent = [(-0.08890925, -0.08890925, -0.08890925), (0.08890925, 0.08890925, 0.08890925)]
            double radius = 0.08890925347805023
            quatd xformOp:orient = (1, 0, 0, 0)
            double3 xformOp:scale = (1, 1, 1)
            double3 xformOp:translate = (0, 0, 0)
            uniform token[] xformOpOrder = ["xformOp:translate", "xformOp:orient", "xformOp:scale"]
        }

        def Sphere "collisions" (
            apiSchemas = ["PhysicsCollisionAPI"]
        )
        {
            float3[] extent = [(-0.08890925, -0.08890925, -0.08890925), (0.08890925, 0.08890925, 0.08890925)]
            uniform token purpose = "guide"
            double radius = 0.08890925347805023
            quatd xformOp:orient = (1, 0, 0, 0)
            double3 xformOp:scale = (1, 1, 1)
            double3 xformOp:translate = (0, 0, 0)
            uniform token[] xformOpOrder = ["xformOp:translate", "xformOp:orient", "xformOp:scale"]
        }

        def PhysicsRevoluteJoint "FR_thigh_joint" (
            apiSchemas = ["PhysxJointAPI", "PhysicsJointStateAPI:angular", "PhysicsDriveAPI:angular"]
        )
        {
            float drive:angular:physics:damping = 0
            float drive:angular:physics:maxForce = 60
            float drive:angular:physics:stiffness = 0
            uniform token drive:angular:physics:type = "force"
            uniform token physics:axis = "Y"
            rel physics:body0 = </quadruped_robot/FR_hip>
            rel physics:body1 = </quadruped_robot/FR_thigh>
            float physics:breakForce = 3.4028235e38
            float physics:breakTorque = 3.4028235e38
            point3f physics:localPos0 = (0, 0, 0)
            point3f physics:localPos1 = (0, 0, 0)
            quatf physics:localRot0 = (1, 0, 0, 0)
            quatf physics:localRot1 = (1, 0, 0, 0)
            float physics:lowerLimit = -180
            float physics:upperLimit = 180
            float physxJoint:maxJointVelocity = 3002.2988
        }
    }

    def Xform "FR_thigh" (
        apiSchemas = ["PhysicsRigidBodyAPI", "PhysicsMassAPI"]
    )
    {
        point3f physics:centerOfMass = (0, 0, -0.15253891)
        float3 physics:diagonalInertia = (0.01451599, 0.01451599, 0.005895181)
        float physics:mass = 1.4915342
        quatf physics:principalAxes = (1, 0, 0, 0)
        quatd xformOp:orient = (1, 0, 0, 0)
        double3 xformOp:scale = (1, 1, 1)
        double3 xformOp:translate = (0.5522798895835876, -0.29526734352111816, -0.07069141417741776)
        uniform token[] xformOpOrder = ["xformOp:translate", "xformOp:orient", "xformOp:scale"]

        def Cylinder "visuals"
        {
            uniform token axis = "Z"
            float3[] extent = [(-0.08890925, -0.08890925, -0.15253891), (0.08890925, 0.08890925, 0.15253891)]
            double height = 0.30507782101631165
            double radius = 0.08890925347805023
            quatd xformOp:orient = (1, 0, 0, 0)
            double3 xformOp:scale = (1, 1, 1)
            double3 xformOp:translate = (0, 0, -0.15253891050815582)
            uniform token[] xformOpOrder = ["xformOp:translate", "xformOp:orient", "xformOp:scale"]
        }

        def Cylinder "collisions" (
            apiSchemas = ["PhysicsCollisionAPI"]
        )
        {
            uniform token axis = "Z"
            float3[] extent = [(-0.08890925, -0.08890925, -0.15253891), (0.08890925, 0.08890925, 0.15253891)]
            double height = 0.30507782101631165
            uniform token purpose = "guide"
            double radius = 0.08890925347805023
            quatd xformOp:orient = (1, 0, 0, 0)
            double3 xformOp:scale = (1, 1, 1)
            double3 xformOp:translate = (0, 0, -0.15253891050815582)
            uniform token[] xformOpOrder = ["xformOp:translate", "xformOp:orient", "xformOp:scale"]
        }

        def PhysicsFixedJoint "FR_knee_joint"
        {
            rel physics:body0 = </quadruped_robot/FR_thigh>
            rel physics:body1 = </quadruped_robot/FR_knee>
            float physics:breakForce = 3.4028235e38
            float physics:breakTorque = 3.4028235e38
            point3f physics:localPos0 = (0, 0, -0.30507782)
            point3f physics:localPos1 = (0, 0, 0)
            quatf physics:localRot0 = (1, 0, 0, 0)
            quatf physics:localRot1 = (1, 0, 0, 0)
        }
    }

    def Xform "FR_knee" (
        apiSchemas = ["PhysicsRigidBodyAPI", "PhysicsMassAPI"]
    )
    {
        point3f physics:centerOfMass = (0, 0, 0.10685682)
        float3 physics:diagonalInertia = (0.0030896727, 0.0030896727, 0.0030896727)
        float physics:mass = 0.67646915
        quatf physics:principalAxes = (1, 0, 0, 0)
        quatd xformOp:orient = (1, 0, 0, 0)
        double3 xformOp:scale = (1, 1, 1)
        double3 xformOp:translate = (0.5522798895835876, -0.29526734352111816, -0.3757692277431488)
        uniform token[] xformOpOrder = ["xformOp:translate", "xformOp:orient", "xformOp:scale"]

        def Sphere "visuals"
        {
            float3[] extent = [(-0.10685682, -0.10685682, -0.10685682), (0.10685682, 0.10685682, 0.10685682)]
            double radius = 0.1068568229675293
            quatd xformOp:orient = (1, 0, 0, 0)
            double3 xformOp:scale = (1, 1, 1)
            double3 xformOp:translate = (0, 0, 0)
            uniform token[] xformOpOrder = ["xformOp:translate", "xformOp:orient", "xformOp:scale"]
        }

        def Sphere "collisions" (
            apiSchemas = ["PhysicsCollisionAPI"]
        )
        {
            float3[] extent = [(-0.10685682, -0.10685682, -0.10685682), (0.10685682, 0.10685682, 0.10685682)]
            uniform token purpose = "guide"
            double radius = 0.1068568229675293
            quatd xformOp:orient = (1, 0, 0, 0)
            double3 xformOp:scale = (1, 1, 1)
            double3 xformOp:translate = (0, 0, 0)
            uniform token[] xformOpOrder = ["xformOp:translate", "xformOp:orient", "xformOp:scale"]
        }

        def PhysicsRevoluteJoint "FR_calf_joint" (
            apiSchemas = ["PhysxJointAPI", "PhysicsJointStateAPI:angular", "PhysicsDriveAPI:angular"]
        )
        {
            float drive:angular:physics:damping = 0
            float drive:angular:physics:maxForce = 60
            float drive:angular:physics:stiffness = 0
            uniform token drive:angular:physics:type = "force"
            uniform token physics:axis = "Y"
            rel physics:body0 = </quadruped_robot/FR_knee>
            rel physics:body1 = </quadruped_robot/FR_calf>
            float physics:breakForce = 3.4028235e38
            float physics:breakTorque = 3.4028235e38
            point3f physics:localPos0 = (0, 0, 0)
            point3f physics:localPos1 = (0, 0, 0)
            quatf physics:localRot0 = (1, 0, 0, 0)
            quatf physics:localRot1 = (1, 0, 0, 0)
            float physics:lowerLimit = -180
            float physics:upperLimit = 180
            float physxJoint:maxJointVelocity = 3002.2988
        }
    }

    def Xform "FR_calf" (
        apiSchemas = ["PhysicsRigidBodyAPI", "PhysicsMassAPI"]
    )
    {
        point3f physics:centerOfMass = (0, 0, -0.16101232)
        float3 physics:diagonalInertia = (0.009559389, 0.009559389, 0.004747319)
        float physics:mass = 0.83152235
        quatf physics:principalAxes = (1, 0, 0, 0)
        quatd xformOp:orient = (1, 0, 0, 0)
        double3 xformOp:scale = (1, 1, 1)
        double3 xformOp:translate = (0.5522798895835876, -0.29526734352111816, -0.3757692277431488)
        uniform token[] xformOpOrder = ["xformOp:translate", "xformOp:orient", "xformOp:scale"]

        def Cylinder "visuals"
        {
            uniform token axis = "Z"
            float3[] extent = [(-0.10685682, -0.10685682, -0.16101232), (0.10685682, 0.10685682, 0.16101232)]
            double height = 0.3220246434211731
            double radius = 0.1068568229675293
            quatd xformOp:orient = (1, 0, 0, 0)
            double3 xformOp:scale = (1, 1, 1)
            double3 xformOp:translate = (0, 0, -0.16101232171058655)
            uniform token[] xformOpOrder = ["xformOp:translate", "xformOp:orient", "xformOp:scale"]
        }

        def Cylinder "collisions" (
            apiSchemas = ["PhysicsCollisionAPI"]
        )
        {
            uniform token axis = "Z"
            float3[] extent = [(-0.10685682, -0.10685682, -0.16101232), (0.10685682, 0.10685682, 0.16101232)]
            double height = 0.3220246434211731
            uniform token purpose = "guide"
            double radius = 0.1068568229675293
            quatd xformOp:orient = (1, 0, 0, 0)
            double3 xformOp:scale = (1, 1, 1)
            double3 xformOp:translate = (0, 0, -0.16101232171058655)
            uniform token[] xformOpOrder = ["xformOp:translate", "xformOp:orient", "xformOp:scale"]
        }

        def PhysicsFixedJoint "FR_foot_joint"
        {
            rel physics:body0 = </quadruped_robot/FR_calf>
            rel physics:body1 = </quadruped_robot/FR_foot>
            float physics:breakForce = 3.4028235e38
            float physics:breakTorque = 3.4028235e38
            point3f physics:localPos0 = (0, 0, -0.32202464)
            point3f physics:localPos1 = (0, 0, 0)
            quatf physics:localRot0 = (1, 0, 0, 0)
            quatf physics:localRot1 = (1, 0, 0, 0)
        }
    }

    def Xform "FR_foot" (
        apiSchemas = ["PhysicsRigidBodyAPI", "PhysicsMassAPI"]
    )
    {
        point3f physics:centerOfMass = (0, 0, 0.07184092)
        float3 physics:diagonalInertia = (0.0022357744, 0.0022357744, 0.0022357744)
        float physics:mass = 1.0829895
        quatf physics:principalAxes = (1, 0, 0, 0)
        quatd xformOp:orient = (1, 0, 0, 0)
        double3 xformOp:scale = (1, 1, 1)
        double3 xformOp:translate = (0.5522798895835876, -0.29526734352111816, -0.6977938413619995)
        uniform token[] xformOpOrder = ["xformOp:translate", "xformOp:orient", "xformOp:scale"]

        def Sphere "visuals"
        {
            float3[] extent = [(-0.07184092, -0.07184092, -0.07184092), (0.07184092, 0.07184092, 0.07184092)]
            double radius = 0.07184091955423355
            quatd xformOp:orient = (1, 0, 0, 0)
            double3 xformOp:scale = (1, 1, 1)
            double3 xformOp:translate = (0, 0, 0)
            uniform token[] xformOpOrder = ["xformOp:translate", "xformOp:orient", "xformOp:scale"]
        }

        def Sphere "collisions" (
            apiSchemas = ["PhysicsCollisionAPI"]
        )
        {
            float3[] extent = [(-0.07184092, -0.07184092, -0.07184092), (0.07184092, 0.07184092, 0.07184092)]
            uniform token purpose = "guide"
            double radius = 0.07184091955423355
            quatd xformOp:orient = (1, 0, 0, 0)
            double3 xformOp:scale = (1, 1, 1)
            double3 xformOp:translate = (0, 0, 0)
            uniform token[] xformOpOrder = ["xformOp:translate", "xformOp:orient", "xformOp:scale"]
        }
    }

    def Xform "RL_hip" (
        apiSchemas = ["PhysicsRigidBodyAPI", "PhysicsMassAPI"]
    )
    {
        point3f physics:centerOfMass = (0, 0, 0.106035486)
        float3 physics:diagonalInertia = (0.0071520754, 0.0071520754, 0.0071520754)
        float physics:mass = 1.5902656
        quatf physics:principalAxes = (1, 0, 0, 0)
        quatd xformOp:orient = (1, 0, 0, 0)
        double3 xformOp:scale = (1, 1, 1)
        double3 xformOp:translate = (-0.5522798895835876, 0.29526734352111816, -0.07069141417741776)
        uniform token[] xformOpOrder = ["xformOp:translate", "xformOp:orient", "xformOp:scale"]

        def Sphere "visuals"
        {
            float3[] extent = [(-0.106035486, -0.106035486, -0.106035486), (0.106035486, 0.106035486, 0.106035486)]
            double radius = 0.10603548586368561
            quatd xformOp:orient = (1, 0, 0, 0)
            double3 xformOp:scale = (1, 1, 1)
            double3 xformOp:translate = (0, 0, 0)
            uniform token[] xformOpOrder = ["xformOp:translate", "xformOp:orient", "xformOp:scale"]
        }

        def Sphere "collisions" (
            apiSchemas = ["PhysicsCollisionAPI"]
        )
        {
            float3[] extent = [(-0.106035486, -0.106035486, -0.106035486), (0.106035486, 0.106035486, 0.106035486)]
            uniform token purpose = "guide"
            double radius = 0.10603548586368561
            quatd xformOp:orient = (1, 0, 0, 0)
            double3 xformOp:scale = (1, 1, 1)
            double3 xformOp:translate = (0, 0, 0)
            uniform token[] xformOpOrder = ["xformOp:translate", "xformOp:orient", "xformOp:scale"]
        }

        def PhysicsRevoluteJoint "RL_thigh_joint" (
            apiSchemas = ["PhysxJointAPI", "PhysicsJointStateAPI:angular", "PhysicsDriveAPI:angular"]
        )
        {
            float drive:angular:physics:damping = 0
            float drive:angular:physics:maxForce = 60
            float drive:angular:physics:stiffness = 0
            uniform token drive:angular:physics:type = "force"
            uniform token physics:axis = "Y"
            rel physics:body0 = </quadruped_robot/RL_hip>
            rel physics:body1 = </quadruped_robot/RL_thigh>
            float physics:breakForce = 3.4028235e38
            float physics:breakTorque = 3.4028235e38
            point3f physics:localPos0 = (0, 0, 0)
            point3f physics:localPos1 = (0, 0, 0)
            quatf physics:localRot0 = (1, 0, 0, 0)
            quatf physics:localRot1 = (1, 0, 0, 0)
            float physics:lowerLimit = -180
            float physics:upperLimit = 180
            float physxJoint:maxJointVelocity = 3002.2988
        }
    }

    def Xform "RL_thigh" (
        apiSchemas = ["PhysicsRigidBodyAPI", "PhysicsMassAPI"]
    )
    {
        point3f physics:centerOfMass = (0, 0, -0.19255297)
        float3 physics:diagonalInertia = (0.01688236, 0.01688236, 0.006256433)
        float physics:mass = 1.1128955
        quatf physics:principalAxes = (1, 0, 0, 0)
        quatd xformOp:orient = (1, 0, 0, 0)
        double3 xformOp:scale = (1, 1, 1)
        double3 xformOp:translate = (-0.5522798895835876, 0.29526734352111816, -0.07069141417741776)
        uniform token[] xformOpOrder = ["xformOp:translate", "xformOp:orient", "xformOp:scale"]

        def Cylinder "visuals"
        {
            uniform token axis = "Z"
            float3[] extent = [(-0.106035486, -0.106035486, -0.19255297), (0.106035486, 0.106035486, 0.19255297)]
            double height = 0.3851059377193451
            double radius = 0.10603548586368561
            quatd xformOp:orient = (1, 0, 0, 0)
            double3 xformOp:scale = (1, 1, 1)
            double3 xformOp:translate = (0, 0, -0.19255296885967255)
            uniform token[] xformOpOrder = ["xformOp:translate", "xformOp:orient", "xformOp:scale"]
        }

        def Cylinder "collisions" (
            apiSchemas = ["PhysicsCollisionAPI"]
        )
        {
            uniform token axis = "Z"
            float3[] extent = [(-0.106035486, -0.106035486, -0.19255297), (0.106035486, 0.106035486, 0.19255297)]
            double height = 0.3851059377193451
            uniform token purpose = "guide"
            double radius = 0.10603548586368561
            quatd xformOp:orient = (1, 0, 0, 0)
            double3 xformOp:scale = (1, 1, 1)
            double3 xformOp:translate = (0, 0, -0.19255296885967255)
            uniform token[] xformOpOrder = ["xformOp:translate", "xformOp:orient", "xformOp:scale"]
        }

        def PhysicsFixedJoint "RL_knee_joint"
        {
            rel physics:body0 = </quadruped_robot/RL_thigh>
            rel physics:body1 = </quadruped_robot/RL_knee>
            float physics:breakForce = 3.4028235e38
            float physics:breakTorque = 3.4028235e38
            point3f physics:localPos0 = (0, 0, -0.38510594)
            point3f physics:localPos1 = (0, 0, 0)
            quatf physics:localRot0 = (1, 0, 0, 0)
            quatf physics:localRot1 = (1, 0, 0, 0)
        }
    }

    def Xform "RL_knee" (
        apiSchemas = ["PhysicsRigidBodyAPI", "PhysicsMassAPI"]
    )
    {
        point3f physics:centerOfMass = (0, 0, 0.106035486)
        float3 physics:diagonalInertia = (0.008597176, 0.008597176, 0.008597176)
        float physics:mass = 1.9115839
        quatf physics:principalAxes = (1, 0, 0, 0)
        quatd xformOp:orient = (1, 0, 0, 0)
        double3 xformOp:scale = (1, 1, 1)
        double3 xformOp:translate = (-0.5522798895835876, 0.29526734352111816, -0.45579734444618225)
        uniform token[] xformOpOrder = ["xformOp:translate", "xformOp:orient", "xformOp:scale"]

        def Sphere "visuals"
        {
            float3[] extent = [(-0.106035486, -0.106035486, -0.106035486), (0.106035486, 0.106035486, 0.106035486)]
            double radius = 0.10603548586368561
            quatd xformOp:orient = (1, 0, 0, 0)
            double3 xformOp:scale = (1, 1, 1)
            double3 xformOp:translate = (0, 0, 0)
            uniform token[] xformOpOrder = ["xformOp:translate", "xformOp:orient", "xformOp:scale"]
        }

        def Sphere "collisions" (
            apiSchemas = ["PhysicsCollisionAPI"]
        )
        {
            float3[] extent = [(-0.106035486, -0.106035486, -0.106035486), (0.106035486, 0.106035486, 0.106035486)]
            uniform token purpose = "guide"
            double radius = 0.10603548586368561
            quatd xformOp:orient = (1, 0, 0, 0)
            double3 xformOp:scale = (1, 1, 1)
            double3 xformOp:translate = (0, 0, 0)
            uniform token[] xformOpOrder = ["xformOp:translate", "xformOp:orient", "xformOp:scale"]
        }

        def PhysicsRevoluteJoint "RL_calf_joint" (
            apiSchemas = ["PhysxJointAPI", "PhysicsJointStateAPI:angular", "PhysicsDriveAPI:angular"]
        )
        {
            float drive:angular:physics:damping = 0
            float drive:angular:physics:maxForce = 60
            float drive:angular:physics:stiffness = 0
            uniform token drive:angular:physics:type = "force"
            uniform token physics:axis = "Y"
            rel physics:body0 = </quadruped_robot/RL_knee>
            rel physics:body1 = </quadruped_robot/RL_calf>
            float physics:breakForce = 3.4028235e38
            float physics:breakTorque = 3.4028235e38
            point3f physics:localPos0 = (0, 0, 0)
            point3f physics:localPos1 = (0, 0, 0)
            quatf physics:localRot0 = (1, 0, 0, 0)
            quatf physics:localRot1 = (1, 0, 0, 0)
            float physics:lowerLimit = -180
            float physics:upperLimit = 180
            float physxJoint:maxJointVelocity = 3002.2988
        }
    }

    def Xform "RL_calf" (
        apiSchemas = ["PhysicsRigidBodyAPI", "PhysicsMassAPI"]
    )
    {
        point3f physics:centerOfMass = (0, 0, -0.22201742)
        float3 physics:diagonalInertia = (0.015584845, 0.015584845, 0.004305372)
        float physics:mass = 0.8175098
        quatf physics:principalAxes = (1, 0, 0, 0)
        quatd xformOp:orient = (1, 0, 0, 0)
        double3 xformOp:scale = (1, 1, 1)
        double3 xformOp:translate = (-0.5522798895835876, 0.29526734352111816, -0.45579734444618225)
        uniform token[] xformOpOrder = ["xformOp:translate", "xformOp:orient", "xformOp:scale"]

        def Cylinder "visuals"
        {
            uniform token axis = "Z"
            float3[] extent = [(-0.102629885, -0.102629885, -0.22201742), (0.102629885, 0.102629885, 0.22201742)]
            double height = 0.4440348446369171
            double radius = 0.1026298850774765
            quatd xformOp:orient = (1, 0, 0, 0)
            double3 xformOp:scale = (1, 1, 1)
            double3 xformOp:translate = (0, 0, -0.22201742231845856)
            uniform token[] xformOpOrder = ["xformOp:translate", "xformOp:orient", "xformOp:scale"]
        }

        def Cylinder "collisions" (
            apiSchemas = ["PhysicsCollisionAPI"]
        )
        {
            uniform token axis = "Z"
            float3[] extent = [(-0.102629885, -0.102629885, -0.22201742), (0.102629885, 0.102629885, 0.22201742)]
            double height = 0.4440348446369171
            uniform token purpose = "guide"
            double radius = 0.1026298850774765
            quatd xformOp:orient = (1, 0, 0, 0)
            double3 xformOp:scale = (1, 1, 1)
            double3 xformOp:translate = (0, 0, -0.22201742231845856)
            uniform token[] xformOpOrder = ["xformOp:translate", "xformOp:orient", "xformOp:scale"]
        }

        def PhysicsFixedJoint "RL_foot_joint"
        {
            rel physics:body0 = </quadruped_robot/RL_calf>
            rel physics:body1 = </quadruped_robot/RL_foot>
            float physics:breakForce = 3.4028235e38
            float physics:breakTorque = 3.4028235e38
            point3f physics:localPos0 = (0, 0, -0.44403484)
            point3f physics:localPos1 = (0, 0, 0)
            quatf physics:localRot0 = (1, 0, 0, 0)
            quatf physics:localRot1 = (1, 0, 0, 0)
        }
    }

    def Xform "RL_foot" (
        apiSchemas = ["PhysicsRigidBodyAPI", "PhysicsMassAPI"]
    )
    {
        point3f physics:centerOfMass = (0, 0, 0.07184092)
        float3 physics:diagonalInertia = (0.0041265073, 0.0041265073, 0.0041265073)
        float physics:mass = 1.9988437
        quatf physics:principalAxes = (1, 0, 0, 0)
        quatd xformOp:orient = (1, 0, 0, 0)
        double3 xformOp:scale = (1, 1, 1)
        double3 xformOp:translate = (-0.5522798895835876, 0.29526734352111816, -0.8998321890830994)
        uniform token[] xformOpOrder = ["xformOp:translate", "xformOp:orient", "xformOp:scale"]

        def Sphere "visuals"
        {
            float3[] extent = [(-0.07184092, -0.07184092, -0.07184092), (0.07184092, 0.07184092, 0.07184092)]
            double radius = 0.07184091955423355
            quatd xformOp:orient = (1, 0, 0, 0)
            double3 xformOp:scale = (1, 1, 1)
            double3 xformOp:translate = (0, 0, 0)
            uniform token[] xformOpOrder = ["xformOp:translate", "xformOp:orient", "xformOp:scale"]
        }

        def Sphere "collisions" (
            apiSchemas = ["PhysicsCollisionAPI"]
        )
        {
            float3[] extent = [(-0.07184092, -0.07184092, -0.07184092), (0.07184092, 0.07184092, 0.07184092)]
            uniform token purpose = "guide"
            double radius = 0.07184091955423355
            quatd xformOp:orient = (1, 0, 0, 0)
            double3 xformOp:scale = (1, 1, 1)
            double3 xformOp:translate = (0, 0, 0)
            uniform token[] xformOpOrder = ["xformOp:translate", "xformOp:orient", "xformOp:scale"]
        }
    }

    def Xform "RR_hip" (
        apiSchemas = ["PhysicsRigidBodyAPI", "PhysicsMassAPI"]
    )
    {
        point3f physics:centerOfMass = (0, 0, 0.106035486)
        float3 physics:diagonalInertia = (0.0048752395, 0.0048752395, 0.0048752395)
        float physics:mass = 1.0840106
        quatf physics:principalAxes = (1, 0, 0, 0)
        quatd xformOp:orient = (1, 0, 0, 0)
        double3 xformOp:scale = (1, 1, 1)
        double3 xformOp:translate = (-0.5522798895835876, -0.29526734352111816, -0.07069141417741776)
        uniform token[] xformOpOrder = ["xformOp:translate", "xformOp:orient", "xformOp:scale"]

        def Sphere "visuals"
        {
            float3[] extent = [(-0.106035486, -0.106035486, -0.106035486), (0.106035486, 0.106035486, 0.106035486)]
            double radius = 0.10603548586368561
            quatd xformOp:orient = (1, 0, 0, 0)
            double3 xformOp:scale = (1, 1, 1)
            double3 xformOp:translate = (0, 0, 0)
            uniform token[] xformOpOrder = ["xformOp:translate", "xformOp:orient", "xformOp:scale"]
        }

        def Sphere "collisions" (
            apiSchemas = ["PhysicsCollisionAPI"]
        )
        {
            float3[] extent = [(-0.106035486, -0.106035486, -0.106035486), (0.106035486, 0.106035486, 0.106035486)]
            uniform token purpose = "guide"
            double radius = 0.10603548586368561
            quatd xformOp:orient = (1, 0, 0, 0)
            double3 xformOp:scale = (1, 1, 1)
            double3 xformOp:translate = (0, 0, 0)
            uniform token[] xformOpOrder = ["xformOp:translate", "xformOp:orient", "xformOp:scale"]
        }

        def PhysicsRevoluteJoint "RR_thigh_joint" (
            apiSchemas = ["PhysxJointAPI", "PhysicsJointStateAPI:angular", "PhysicsDriveAPI:angular"]
        )
        {
            float drive:angular:physics:damping = 0
            float drive:angular:physics:maxForce = 60
            float drive:angular:physics:stiffness = 0
            uniform token drive:angular:physics:type = "force"
            uniform token physics:axis = "Y"
            rel physics:body0 = </quadruped_robot/RR_hip>
            rel physics:body1 = </quadruped_robot/RR_thigh>
            float physics:breakForce = 3.4028235e38
            float physics:breakTorque = 3.4028235e38
            point3f physics:localPos0 = (0, 0, 0)
            point3f physics:localPos1 = (0, 0, 0)
            quatf physics:localRot0 = (1, 0, 0, 0)
            quatf physics:localRot1 = (1, 0, 0, 0)
            float physics:lowerLimit = -180
            float physics:upperLimit = 180
            float physxJoint:maxJointVelocity = 3002.2988
        }
    }

    def Xform "RR_thigh" (
        apiSchemas = ["PhysicsRigidBodyAPI", "PhysicsMassAPI"]
    )
    {
        point3f physics:centerOfMass = (0, 0, -0.19255297)
        float3 physics:diagonalInertia = (0.019149665, 0.019149665, 0.007096674)
        float physics:mass = 1.2623576
        quatf physics:principalAxes = (1, 0, 0, 0)
        quatd xformOp:orient = (1, 0, 0, 0)
        double3 xformOp:scale = (1, 1, 1)
        double3 xformOp:translate = (-0.5522798895835876, -0.29526734352111816, -0.07069141417741776)
        uniform token[] xformOpOrder = ["xformOp:translate", "xformOp:orient", "xformOp:scale"]

        def Cylinder "visuals"
        {
            uniform token axis = "Z"
            float3[] extent = [(-0.106035486, -0.106035486, -0.19255297), (0.106035486, 0.106035486, 0.19255297)]
            double height = 0.3851059377193451
            double radius = 0.10603548586368561
            quatd xformOp:orient = (1, 0, 0, 0)
            double3 xformOp:scale = (1, 1, 1)
            double3 xformOp:translate = (0, 0, -0.19255296885967255)
            uniform token[] xformOpOrder = ["xformOp:translate", "xformOp:orient", "xformOp:scale"]
        }

        def Cylinder "collisions" (
            apiSchemas = ["PhysicsCollisionAPI"]
        )
        {
            uniform token axis = "Z"
            float3[] extent = [(-0.106035486, -0.106035486, -0.19255297), (0.106035486, 0.106035486, 0.19255297)]
            double height = 0.3851059377193451
            uniform token purpose = "guide"
            double radius = 0.10603548586368561
            quatd xformOp:orient = (1, 0, 0, 0)
            double3 xformOp:scale = (1, 1, 1)
            double3 xformOp:translate = (0, 0, -0.19255296885967255)
            uniform token[] xformOpOrder = ["xformOp:translate", "xformOp:orient", "xformOp:scale"]
        }

        def PhysicsFixedJoint "RR_knee_joint"
        {
            rel physics:body0 = </quadruped_robot/RR_thigh>
            rel physics:body1 = </quadruped_robot/RR_knee>
            float physics:breakForce = 3.4028235e38
            float physics:breakTorque = 3.4028235e38
            point3f physics:localPos0 = (0, 0, -0.38510594)
            point3f physics:localPos1 = (0, 0, 0)
            quatf physics:localRot0 = (1, 0, 0, 0)
            quatf physics:localRot1 = (1, 0, 0, 0)
        }
    }

    def Xform "RR_knee" (
        apiSchemas = ["PhysicsRigidBodyAPI", "PhysicsMassAPI"]
    )
    {
        point3f physics:centerOfMass = (0, 0, 0.106035486)
        float3 physics:diagonalInertia = (0.0080526825, 0.0080526825, 0.0080526825)
        float physics:mass = 1.7905157
        quatf physics:principalAxes = (1, 0, 0, 0)
        quatd xformOp:orient = (1, 0, 0, 0)
        double3 xformOp:scale = (1, 1, 1)
        double3 xformOp:translate = (-0.5522798895835876, -0.29526734352111816, -0.45579734444618225)
        uniform token[] xformOpOrder = ["xformOp:translate", "xformOp:orient", "xformOp:scale"]

        def Sphere "visuals"
        {
            float3[] extent = [(-0.106035486, -0.106035486, -0.106035486), (0.106035486, 0.106035486, 0.106035486)]
            double radius = 0.10603548586368561
            quatd xformOp:orient = (1, 0, 0, 0)
            double3 xformOp:scale = (1, 1, 1)
            double3 xformOp:translate = (0, 0, 0)
            uniform token[] xformOpOrder = ["xformOp:translate", "xformOp:orient", "xformOp:scale"]
        }

        def Sphere "collisions" (
            apiSchemas = ["PhysicsCollisionAPI"]
        )
        {
            float3[] extent = [(-0.106035486, -0.106035486, -0.106035486), (0.106035486, 0.106035486, 0.106035486)]
            uniform token purpose = "guide"
            double radius = 0.10603548586368561
            quatd xformOp:orient = (1, 0, 0, 0)
            double3 xformOp:scale = (1, 1, 1)
            double3 xformOp:translate = (0, 0, 0)
            uniform token[] xformOpOrder = ["xformOp:translate", "xformOp:orient", "xformOp:scale"]
        }

        def PhysicsRevoluteJoint "RR_calf_joint" (
            apiSchemas = ["PhysxJointAPI", "PhysicsJointStateAPI:angular", "PhysicsDriveAPI:angular"]
        )
        {
            float drive:angular:physics:damping = 0
            float drive:angular:physics:maxForce = 60
            float drive:angular:physics:stiffness = 0
            uniform token drive:angular:physics:type = "force"
            uniform token physics:axis = "Y"
            rel physics:body0 = </quadruped_robot/RR_knee>
            rel physics:body1 = </quadruped_robot/RR_calf>
            float physics:breakForce = 3.4028235e38
            float physics:breakTorque = 3.4028235e38
            point3f physics:localPos0 = (0, 0, 0)
            point3f physics:localPos1 = (0, 0, 0)
            quatf physics:localRot0 = (1, 0, 0, 0)
            quatf physics:localRot1 = (1, 0, 0, 0)
            float physics:lowerLimit = -180
            float physics:upperLimit = 180
            float physxJoint:maxJointVelocity = 3002.2988
        }
    }

    def Xform "RR_calf" (
        apiSchemas = ["PhysicsRigidBodyAPI", "PhysicsMassAPI"]
    )
    {
        point3f physics:centerOfMass = (0, 0, -0.22201742)
        float3 physics:diagonalInertia = (0.037639167, 0.037639167, 0.010397961)
        float physics:mass = 1.9743788
        quatf physics:principalAxes = (1, 0, 0, 0)
        quatd xformOp:orient = (1, 0, 0, 0)
        double3 xformOp:scale = (1, 1, 1)
        double3 xformOp:translate = (-0.5522798895835876, -0.29526734352111816, -0.45579734444618225)
        uniform token[] xformOpOrder = ["xformOp:translate", "xformOp:orient", "xformOp:scale"]

        def Cylinder "visuals"
        {
            uniform token axis = "Z"
            float3[] extent = [(-0.102629885, -0.102629885, -0.22201742), (0.102629885, 0.102629885, 0.22201742)]
            double height = 0.4440348446369171
            double radius = 0.1026298850774765
            quatd xformOp:orient = (1, 0, 0, 0)
            double3 xformOp:scale = (1, 1, 1)
            double3 xformOp:translate = (0, 0, -0.22201742231845856)
            uniform token[] xformOpOrder = ["xformOp:translate", "xformOp:orient", "xformOp:scale"]
        }

        def Cylinder "collisions" (
            apiSchemas = ["PhysicsCollisionAPI"]
        )
        {
            uniform token axis = "Z"
            float3[] extent = [(-0.102629885, -0.102629885, -0.22201742), (0.102629885, 0.102629885, 0.22201742)]
            double height = 0.4440348446369171
            uniform token purpose = "guide"
            double radius = 0.1026298850774765
            quatd xformOp:orient = (1, 0, 0, 0)
            double3 xformOp:scale = (1, 1, 1)
            double3 xformOp:translate = (0, 0, -0.22201742231845856)
            uniform token[] xformOpOrder = ["xformOp:translate", "xformOp:orient", "xformOp:scale"]
        }

        def PhysicsFixedJoint "RR_foot_joint"
        {
            rel physics:body0 = </quadruped_robot/RR_calf>
            rel physics:body1 = </quadruped_robot/RR_foot>
            float physics:breakForce = 3.4028235e38
            float physics:breakTorque = 3.4028235e38
            point3f physics:localPos0 = (0, 0, -0.44403484)
            point3f physics:localPos1 = (0, 0, 0)
            quatf physics:localRot0 = (1, 0, 0, 0)
            quatf physics:localRot1 = (1, 0, 0, 0)
        }
    }

    def Xform "RR_foot" (
        apiSchemas = ["PhysicsRigidBodyAPI", "PhysicsMassAPI"]
    )
    {
        point3f physics:centerOfMass = (0, 0, 0.07184092)
        float3 physics:diagonalInertia = (0.0026187357, 0.0026187357, 0.0026187357)
        float physics:mass = 1.2684925
        quatf physics:principalAxes = (1, 0, 0, 0)
        quatd xformOp:orient = (1, 0, 0, 0)
        double3 xformOp:scale = (1, 1, 1)
        double3 xformOp:translate = (-0.5522798895835876, -0.29526734352111816, -0.8998321890830994)
        uniform token[] xformOpOrder = ["xformOp:translate", "xformOp:orient", "xformOp:scale"]

        def Sphere "visuals"
        {
            float3[] extent = [(-0.07184092, -0.07184092, -0.07184092), (0.07184092, 0.07184092, 0.07184092)]
            double radius = 0.07184091955423355
            quatd xformOp:orient = (1, 0, 0, 0)
            double3 xformOp:scale = (1, 1, 1)
            double3 xformOp:translate = (0, 0, 0)
            uniform token[] xformOpOrder = ["xformOp:translate", "xformOp:orient", "xformOp:scale"]
        }

        def Sphere "collisions" (
            apiSchemas = ["PhysicsCollisionAPI"]
        )
        {
            float3[] extent = [(-0.07184092, -0.07184092, -0.07184092), (0.07184092, 0.07184092, 0.07184092)]
            uniform token purpose = "guide"
            double radius = 0.07184091955423355
            quatd xformOp:orient = (1, 0, 0, 0)
            double3 xformOp:scale = (1, 1, 1)
            double3 xformOp:translate = (0, 0, 0)
            uniform token[] xformOpOrder = ["xformOp:translate", "xformOp:orient", "xformOp:scale"]
        }
    }
}

