#usda 1.0
(
    customLayerData = {
        dictionary omni_layer = {
            dictionary locked = {
            }
            dictionary muteness = {
            }
        }
    }
    defaultPrim = "quadruped_robot"
    doc = """Generated from Composed Stage of root layer /home/gpuuser/GitHub/Intelligent-robot-design/generations/generation_1/robot_45.usda
"""
    metersPerUnit = 1
    upAxis = "Z"
)

def Xform "quadruped_robot"
{
    quatd xformOp:orient = (1, 0, 0, 0)
    double3 xformOp:scale = (1, 1, 1)
    double3 xformOp:translate = (0, 0, 0)
    uniform token[] xformOpOrder = ["xformOp:translate", "xformOp:orient", "xformOp:scale"]

    def Scope "Looks"
    {
    }

    def Xform "base" (
        apiSchemas = ["PhysicsRigidBodyAPI", "PhysicsMassAPI", "PhysicsArticulationRootAPI", "PhysxArticulationAPI"]
    )
    {
        point3f physics:centerOfMass = (0, 0, -0.005)
        float3 physics:diagonalInertia = (0.000028139219, 0.000028139219, 0.000028139219)
        float physics:mass = 1.6883531
        quatf physics:principalAxes = (1, 0, 0, 0)
        bool physxArticulation:enabledSelfCollisions = 1
        int physxArticulation:solverPositionIterationCount = 32
        int physxArticulation:solverVelocityIterationCount = 1
        quatd xformOp:orient = (1, 0, 0, 0)
        double3 xformOp:scale = (1, 1, 1)
        double3 xformOp:translate = (0, 0, 0)
        uniform token[] xformOpOrder = ["xformOp:translate", "xformOp:orient", "xformOp:scale"]

        def Cube "visuals"
        {
            float3[] extent = [(-0.005, -0.005, -0.005), (0.005, 0.005, 0.005)]
            double size = 1
            quatd xformOp:orient = (1, 0, 0, 0)
            double3 xformOp:scale = (0.009999999776482582, 0.009999999776482582, 0.009999999776482582)
            double3 xformOp:translate = (0, 0, 0)
            uniform token[] xformOpOrder = ["xformOp:translate", "xformOp:orient", "xformOp:scale"]
        }

        def Cube "collisions" (
            apiSchemas = ["PhysicsCollisionAPI"]
        )
        {
            float3[] extent = [(-0.005, -0.005, -0.005), (0.005, 0.005, 0.005)]
            uniform token purpose = "guide"
            double size = 1
            quatd xformOp:orient = (1, 0, 0, 0)
            double3 xformOp:scale = (0.009999999776482582, 0.009999999776482582, 0.009999999776482582)
            double3 xformOp:translate = (0, 0, 0)
            uniform token[] xformOpOrder = ["xformOp:translate", "xformOp:orient", "xformOp:scale"]
        }

        def PhysicsFixedJoint "floating_base"
        {
            rel physics:body0 = </quadruped_robot/base>
            rel physics:body1 = </quadruped_robot/trunk>
            float physics:breakForce = 3.4028235e38
            float physics:breakTorque = 3.4028235e38
            point3f physics:localPos0 = (0, 0, 0)
            point3f physics:localPos1 = (0, 0, 0)
            quatf physics:localRot0 = (1, 0, 0, 0)
            quatf physics:localRot1 = (1, 0, 0, 0)
        }
    }

    def Xform "trunk" (
        apiSchemas = ["PhysicsRigidBodyAPI", "PhysicsMassAPI"]
    )
    {
        point3f physics:centerOfMass = (0, 0, -0.14763029)
        float3 physics:diagonalInertia = (0.011179614, 0.011179614, 0.038289983)
        float physics:mass = 0.5157522
        quatf physics:principalAxes = (1, 0, 0, 0)
        quatd xformOp:orient = (1, 0, 0, 0)
        double3 xformOp:scale = (1, 1, 1)
        double3 xformOp:translate = (0, 0, 0)
        uniform token[] xformOpOrder = ["xformOp:translate", "xformOp:orient", "xformOp:scale"]

        def Cube "visuals"
        {
            float3[] extent = [(-0.42366126, -0.20792854, -0.14763029), (0.42366126, 0.20792854, 0.14763029)]
            double size = 1
            quatd xformOp:orient = (1, 0, 0, 0)
            double3 xformOp:scale = (0.8473225235939026, 0.41585707664489746, 0.29526057839393616)
            double3 xformOp:translate = (0, 0, 0)
            uniform token[] xformOpOrder = ["xformOp:translate", "xformOp:orient", "xformOp:scale"]
        }

        def Cube "collisions" (
            apiSchemas = ["PhysicsCollisionAPI"]
        )
        {
            float3[] extent = [(-0.42366126, -0.20792854, -0.14763029), (0.42366126, 0.20792854, 0.14763029)]
            uniform token purpose = "guide"
            double size = 1
            quatd xformOp:orient = (1, 0, 0, 0)
            double3 xformOp:scale = (0.8473225235939026, 0.41585707664489746, 0.29526057839393616)
            double3 xformOp:translate = (0, 0, 0)
            uniform token[] xformOpOrder = ["xformOp:translate", "xformOp:orient", "xformOp:scale"]
        }

        def PhysicsRevoluteJoint "FL_hip_joint" (
            apiSchemas = ["PhysxJointAPI", "PhysicsJointStateAPI:angular", "PhysicsDriveAPI:angular"]
        )
        {
            float drive:angular:physics:damping = 0
            float drive:angular:physics:maxForce = 60
            float drive:angular:physics:stiffness = 0
            uniform token drive:angular:physics:type = "force"
            uniform token physics:axis = "X"
            rel physics:body0 = </quadruped_robot/trunk>
            rel physics:body1 = </quadruped_robot/FL_hip>
            float physics:breakForce = 3.4028235e38
            float physics:breakTorque = 3.4028235e38
            point3f physics:localPos0 = (0.42366126, 0.20792854, -0.118104234)
            point3f physics:localPos1 = (0, 0, 0)
            quatf physics:localRot0 = (1, 0, 0, 0)
            quatf physics:localRot1 = (1, 0, 0, 0)
            float physics:lowerLimit = -180
            float physics:upperLimit = 180
            float physxJoint:maxJointVelocity = 3002.2988
        }

        def PhysicsRevoluteJoint "FR_hip_joint" (
            apiSchemas = ["PhysxJointAPI", "PhysicsJointStateAPI:angular", "PhysicsDriveAPI:angular"]
        )
        {
            float drive:angular:physics:damping = 0
            float drive:angular:physics:maxForce = 60
            float drive:angular:physics:stiffness = 0
            uniform token drive:angular:physics:type = "force"
            uniform token physics:axis = "X"
            rel physics:body0 = </quadruped_robot/trunk>
            rel physics:body1 = </quadruped_robot/FR_hip>
            float physics:breakForce = 3.4028235e38
            float physics:breakTorque = 3.4028235e38
            point3f physics:localPos0 = (0.42366126, -0.20792854, -0.118104234)
            point3f physics:localPos1 = (0, 0, 0)
            quatf physics:localRot0 = (1, 0, 0, 0)
            quatf physics:localRot1 = (1, 0, 0, 0)
            float physics:lowerLimit = -180
            float physics:upperLimit = 180
            float physxJoint:maxJointVelocity = 3002.2988
        }

        def PhysicsRevoluteJoint "RL_hip_joint" (
            apiSchemas = ["PhysxJointAPI", "PhysicsJointStateAPI:angular", "PhysicsDriveAPI:angular"]
        )
        {
            float drive:angular:physics:damping = 0
            float drive:angular:physics:maxForce = 60
            float drive:angular:physics:stiffness = 0
            uniform token drive:angular:physics:type = "force"
            uniform token physics:axis = "X"
            rel physics:body0 = </quadruped_robot/trunk>
            rel physics:body1 = </quadruped_robot/RL_hip>
            float physics:breakForce = 3.4028235e38
            float physics:breakTorque = 3.4028235e38
            point3f physics:localPos0 = (-0.42366126, 0.20792854, -0.118104234)
            point3f physics:localPos1 = (0, 0, 0)
            quatf physics:localRot0 = (1, 0, 0, 0)
            quatf physics:localRot1 = (1, 0, 0, 0)
            float physics:lowerLimit = -180
            float physics:upperLimit = 180
            float physxJoint:maxJointVelocity = 3002.2988
        }

        def PhysicsRevoluteJoint "RR_hip_joint" (
            apiSchemas = ["PhysxJointAPI", "PhysicsJointStateAPI:angular", "PhysicsDriveAPI:angular"]
        )
        {
            float drive:angular:physics:damping = 0
            float drive:angular:physics:maxForce = 60
            float drive:angular:physics:stiffness = 0
            uniform token drive:angular:physics:type = "force"
            uniform token physics:axis = "X"
            rel physics:body0 = </quadruped_robot/trunk>
            rel physics:body1 = </quadruped_robot/RR_hip>
            float physics:breakForce = 3.4028235e38
            float physics:breakTorque = 3.4028235e38
            point3f physics:localPos0 = (-0.42366126, -0.20792854, -0.118104234)
            point3f physics:localPos1 = (0, 0, 0)
            quatf physics:localRot0 = (1, 0, 0, 0)
            quatf physics:localRot1 = (1, 0, 0, 0)
            float physics:lowerLimit = -180
            float physics:upperLimit = 180
            float physxJoint:maxJointVelocity = 3002.2988
        }
    }

    def Xform "FL_hip" (
        apiSchemas = ["PhysicsRigidBodyAPI", "PhysicsMassAPI"]
    )
    {
        point3f physics:centerOfMass = (0, 0, 0.104507506)
        float3 physics:diagonalInertia = (0.008679305, 0.008679305, 0.008679305)
        float physics:mass = 1.9866897
        quatf physics:principalAxes = (1, 0, 0, 0)
        quatd xformOp:orient = (1, 0, 0, 0)
        double3 xformOp:scale = (1, 1, 1)
        double3 xformOp:translate = (0.4236612617969513, 0.20792853832244873, -0.1181042343378067)
        uniform token[] xformOpOrder = ["xformOp:translate", "xformOp:orient", "xformOp:scale"]

        def Sphere "visuals"
        {
            float3[] extent = [(-0.104507506, -0.104507506, -0.104507506), (0.104507506, 0.104507506, 0.104507506)]
            double radius = 0.10450750589370728
            quatd xformOp:orient = (1, 0, 0, 0)
            double3 xformOp:scale = (1, 1, 1)
            double3 xformOp:translate = (0, 0, 0)
            uniform token[] xformOpOrder = ["xformOp:translate", "xformOp:orient", "xformOp:scale"]
        }

        def Sphere "collisions" (
            apiSchemas = ["PhysicsCollisionAPI"]
        )
        {
            float3[] extent = [(-0.104507506, -0.104507506, -0.104507506), (0.104507506, 0.104507506, 0.104507506)]
            uniform token purpose = "guide"
            double radius = 0.10450750589370728
            quatd xformOp:orient = (1, 0, 0, 0)
            double3 xformOp:scale = (1, 1, 1)
            double3 xformOp:translate = (0, 0, 0)
            uniform token[] xformOpOrder = ["xformOp:translate", "xformOp:orient", "xformOp:scale"]
        }

        def PhysicsRevoluteJoint "FL_thigh_joint" (
            apiSchemas = ["PhysxJointAPI", "PhysicsJointStateAPI:angular", "PhysicsDriveAPI:angular"]
        )
        {
            float drive:angular:physics:damping = 0
            float drive:angular:physics:maxForce = 60
            float drive:angular:physics:stiffness = 0
            uniform token drive:angular:physics:type = "force"
            uniform token physics:axis = "Y"
            rel physics:body0 = </quadruped_robot/FL_hip>
            rel physics:body1 = </quadruped_robot/FL_thigh>
            float physics:breakForce = 3.4028235e38
            float physics:breakTorque = 3.4028235e38
            point3f physics:localPos0 = (0, 0, 0)
            point3f physics:localPos1 = (0, 0, 0)
            quatf physics:localRot0 = (1, 0, 0, 0)
            quatf physics:localRot1 = (1, 0, 0, 0)
            float physics:lowerLimit = -180
            float physics:upperLimit = 180
            float physxJoint:maxJointVelocity = 3002.2988
        }
    }

    def Xform "FL_thigh" (
        apiSchemas = ["PhysicsRigidBodyAPI", "PhysicsMassAPI"]
    )
    {
        point3f physics:centerOfMass = (0, 0, -0.2191248)
        float3 physics:diagonalInertia = (0.033479147, 0.033479147, 0.009758204)
        float physics:mass = 1.7869192
        quatf physics:principalAxes = (1, 0, 0, 0)
        quatd xformOp:orient = (1, 0, 0, 0)
        double3 xformOp:scale = (1, 1, 1)
        double3 xformOp:translate = (0.4236612617969513, 0.20792853832244873, -0.1181042343378067)
        uniform token[] xformOpOrder = ["xformOp:translate", "xformOp:orient", "xformOp:scale"]

        def Cylinder "visuals"
        {
            uniform token axis = "Z"
            float3[] extent = [(-0.104507506, -0.104507506, -0.2191248), (0.104507506, 0.104507506, 0.2191248)]
            double height = 0.4382495880126953
            double radius = 0.10450750589370728
            quatd xformOp:orient = (1, 0, 0, 0)
            double3 xformOp:scale = (1, 1, 1)
            double3 xformOp:translate = (0, 0, -0.21912479400634766)
            uniform token[] xformOpOrder = ["xformOp:translate", "xformOp:orient", "xformOp:scale"]
        }

        def Cylinder "collisions" (
            apiSchemas = ["PhysicsCollisionAPI"]
        )
        {
            uniform token axis = "Z"
            float3[] extent = [(-0.104507506, -0.104507506, -0.2191248), (0.104507506, 0.104507506, 0.2191248)]
            double height = 0.4382495880126953
            uniform token purpose = "guide"
            double radius = 0.10450750589370728
            quatd xformOp:orient = (1, 0, 0, 0)
            double3 xformOp:scale = (1, 1, 1)
            double3 xformOp:translate = (0, 0, -0.21912479400634766)
            uniform token[] xformOpOrder = ["xformOp:translate", "xformOp:orient", "xformOp:scale"]
        }

        def PhysicsFixedJoint "FL_knee_joint"
        {
            rel physics:body0 = </quadruped_robot/FL_thigh>
            rel physics:body1 = </quadruped_robot/FL_knee>
            float physics:breakForce = 3.4028235e38
            float physics:breakTorque = 3.4028235e38
            point3f physics:localPos0 = (0, 0, -0.4382496)
            point3f physics:localPos1 = (0, 0, 0)
            quatf physics:localRot0 = (1, 0, 0, 0)
            quatf physics:localRot1 = (1, 0, 0, 0)
        }
    }

    def Xform "FL_knee" (
        apiSchemas = ["PhysicsRigidBodyAPI", "PhysicsMassAPI"]
    )
    {
        point3f physics:centerOfMass = (0, 0, 0.104507506)
        float3 physics:diagonalInertia = (0.00550471, 0.00550471, 0.00550471)
        float physics:mass = 1.260026
        quatf physics:principalAxes = (1, 0, 0, 0)
        quatd xformOp:orient = (1, 0, 0, 0)
        double3 xformOp:scale = (1, 1, 1)
        double3 xformOp:translate = (0.4236612617969513, 0.20792853832244873, -0.5563538074493408)
        uniform token[] xformOpOrder = ["xformOp:translate", "xformOp:orient", "xformOp:scale"]

        def Sphere "visuals"
        {
            float3[] extent = [(-0.104507506, -0.104507506, -0.104507506), (0.104507506, 0.104507506, 0.104507506)]
            double radius = 0.10450750589370728
            quatd xformOp:orient = (1, 0, 0, 0)
            double3 xformOp:scale = (1, 1, 1)
            double3 xformOp:translate = (0, 0, 0)
            uniform token[] xformOpOrder = ["xformOp:translate", "xformOp:orient", "xformOp:scale"]
        }

        def Sphere "collisions" (
            apiSchemas = ["PhysicsCollisionAPI"]
        )
        {
            float3[] extent = [(-0.104507506, -0.104507506, -0.104507506), (0.104507506, 0.104507506, 0.104507506)]
            uniform token purpose = "guide"
            double radius = 0.10450750589370728
            quatd xformOp:orient = (1, 0, 0, 0)
            double3 xformOp:scale = (1, 1, 1)
            double3 xformOp:translate = (0, 0, 0)
            uniform token[] xformOpOrder = ["xformOp:translate", "xformOp:orient", "xformOp:scale"]
        }

        def PhysicsRevoluteJoint "FL_calf_joint" (
            apiSchemas = ["PhysxJointAPI", "PhysicsJointStateAPI:angular", "PhysicsDriveAPI:angular"]
        )
        {
            float drive:angular:physics:damping = 0
            float drive:angular:physics:maxForce = 60
            float drive:angular:physics:stiffness = 0
            uniform token drive:angular:physics:type = "force"
            uniform token physics:axis = "Y"
            rel physics:body0 = </quadruped_robot/FL_knee>
            rel physics:body1 = </quadruped_robot/FL_calf>
            float physics:breakForce = 3.4028235e38
            float physics:breakTorque = 3.4028235e38
            point3f physics:localPos0 = (0, 0, 0)
            point3f physics:localPos1 = (0, 0, 0)
            quatf physics:localRot0 = (1, 0, 0, 0)
            quatf physics:localRot1 = (1, 0, 0, 0)
            float physics:lowerLimit = -180
            float physics:upperLimit = 180
            float physxJoint:maxJointVelocity = 3002.2988
        }
    }

    def Xform "FL_calf" (
        apiSchemas = ["PhysicsRigidBodyAPI", "PhysicsMassAPI"]
    )
    {
        point3f physics:centerOfMass = (0, 0, -0.23920994)
        float3 physics:diagonalInertia = (0.018886056, 0.018886056, 0.004186415)
        float physics:mass = 0.8804145
        quatf physics:principalAxes = (1, 0, 0, 0)
        quatd xformOp:orient = (1, 0, 0, 0)
        double3 xformOp:scale = (1, 1, 1)
        double3 xformOp:translate = (0.4236612617969513, 0.20792853832244873, -0.5563538074493408)
        uniform token[] xformOpOrder = ["xformOp:translate", "xformOp:orient", "xformOp:scale"]

        def Cylinder "visuals"
        {
            uniform token axis = "Z"
            float3[] extent = [(-0.09751975, -0.09751975, -0.23920994), (0.09751975, 0.09751975, 0.23920994)]
            double height = 0.47841987013816833
            double radius = 0.09751974791288376
            quatd xformOp:orient = (1, 0, 0, 0)
            double3 xformOp:scale = (1, 1, 1)
            double3 xformOp:translate = (0, 0, -0.23920993506908417)
            uniform token[] xformOpOrder = ["xformOp:translate", "xformOp:orient", "xformOp:scale"]
        }

        def Cylinder "collisions" (
            apiSchemas = ["PhysicsCollisionAPI"]
        )
        {
            uniform token axis = "Z"
            float3[] extent = [(-0.09751975, -0.09751975, -0.23920994), (0.09751975, 0.09751975, 0.23920994)]
            double height = 0.47841987013816833
            uniform token purpose = "guide"
            double radius = 0.09751974791288376
            quatd xformOp:orient = (1, 0, 0, 0)
            double3 xformOp:scale = (1, 1, 1)
            double3 xformOp:translate = (0, 0, -0.23920993506908417)
            uniform token[] xformOpOrder = ["xformOp:translate", "xformOp:orient", "xformOp:scale"]
        }

        def PhysicsFixedJoint "FL_foot_joint"
        {
            rel physics:body0 = </quadruped_robot/FL_calf>
            rel physics:body1 = </quadruped_robot/FL_foot>
            float physics:breakForce = 3.4028235e38
            float physics:breakTorque = 3.4028235e38
            point3f physics:localPos0 = (0, 0, -0.47841987)
            point3f physics:localPos1 = (0, 0, 0)
            quatf physics:localRot0 = (1, 0, 0, 0)
            quatf physics:localRot1 = (1, 0, 0, 0)
        }
    }

    def Xform "FL_foot" (
        apiSchemas = ["PhysicsRigidBodyAPI", "PhysicsMassAPI"]
    )
    {
        point3f physics:centerOfMass = (0, 0, 0.06826382)
        float3 physics:diagonalInertia = (0.0018221273, 0.0018221273, 0.0018221273)
        float physics:mass = 0.9775467
        quatf physics:principalAxes = (1, 0, 0, 0)
        quatd xformOp:orient = (1, 0, 0, 0)
        double3 xformOp:scale = (1, 1, 1)
        double3 xformOp:translate = (0.4236612617969513, 0.20792853832244873, -1.0347737073898315)
        uniform token[] xformOpOrder = ["xformOp:translate", "xformOp:orient", "xformOp:scale"]

        def Sphere "visuals"
        {
            float3[] extent = [(-0.06826382, -0.06826382, -0.06826382), (0.06826382, 0.06826382, 0.06826382)]
            double radius = 0.06826382130384445
            quatd xformOp:orient = (1, 0, 0, 0)
            double3 xformOp:scale = (1, 1, 1)
            double3 xformOp:translate = (0, 0, 0)
            uniform token[] xformOpOrder = ["xformOp:translate", "xformOp:orient", "xformOp:scale"]
        }

        def Sphere "collisions" (
            apiSchemas = ["PhysicsCollisionAPI"]
        )
        {
            float3[] extent = [(-0.06826382, -0.06826382, -0.06826382), (0.06826382, 0.06826382, 0.06826382)]
            uniform token purpose = "guide"
            double radius = 0.06826382130384445
            quatd xformOp:orient = (1, 0, 0, 0)
            double3 xformOp:scale = (1, 1, 1)
            double3 xformOp:translate = (0, 0, 0)
            uniform token[] xformOpOrder = ["xformOp:translate", "xformOp:orient", "xformOp:scale"]
        }
    }

    def Xform "FR_hip" (
        apiSchemas = ["PhysicsRigidBodyAPI", "PhysicsMassAPI"]
    )
    {
        point3f physics:centerOfMass = (0, 0, 0.104507506)
        float3 physics:diagonalInertia = (0.00531471, 0.00531471, 0.00531471)
        float physics:mass = 1.2165351
        quatf physics:principalAxes = (1, 0, 0, 0)
        quatd xformOp:orient = (1, 0, 0, 0)
        double3 xformOp:scale = (1, 1, 1)
        double3 xformOp:translate = (0.4236612617969513, -0.20792853832244873, -0.1181042343378067)
        uniform token[] xformOpOrder = ["xformOp:translate", "xformOp:orient", "xformOp:scale"]

        def Sphere "visuals"
        {
            float3[] extent = [(-0.104507506, -0.104507506, -0.104507506), (0.104507506, 0.104507506, 0.104507506)]
            double radius = 0.10450750589370728
            quatd xformOp:orient = (1, 0, 0, 0)
            double3 xformOp:scale = (1, 1, 1)
            double3 xformOp:translate = (0, 0, 0)
            uniform token[] xformOpOrder = ["xformOp:translate", "xformOp:orient", "xformOp:scale"]
        }

        def Sphere "collisions" (
            apiSchemas = ["PhysicsCollisionAPI"]
        )
        {
            float3[] extent = [(-0.104507506, -0.104507506, -0.104507506), (0.104507506, 0.104507506, 0.104507506)]
            uniform token purpose = "guide"
            double radius = 0.10450750589370728
            quatd xformOp:orient = (1, 0, 0, 0)
            double3 xformOp:scale = (1, 1, 1)
            double3 xformOp:translate = (0, 0, 0)
            uniform token[] xformOpOrder = ["xformOp:translate", "xformOp:orient", "xformOp:scale"]
        }

        def PhysicsRevoluteJoint "FR_thigh_joint" (
            apiSchemas = ["PhysxJointAPI", "PhysicsJointStateAPI:angular", "PhysicsDriveAPI:angular"]
        )
        {
            float drive:angular:physics:damping = 0
            float drive:angular:physics:maxForce = 60
            float drive:angular:physics:stiffness = 0
            uniform token drive:angular:physics:type = "force"
            uniform token physics:axis = "Y"
            rel physics:body0 = </quadruped_robot/FR_hip>
            rel physics:body1 = </quadruped_robot/FR_thigh>
            float physics:breakForce = 3.4028235e38
            float physics:breakTorque = 3.4028235e38
            point3f physics:localPos0 = (0, 0, 0)
            point3f physics:localPos1 = (0, 0, 0)
            quatf physics:localRot0 = (1, 0, 0, 0)
            quatf physics:localRot1 = (1, 0, 0, 0)
            float physics:lowerLimit = -180
            float physics:upperLimit = 180
            float physxJoint:maxJointVelocity = 3002.2988
        }
    }

    def Xform "FR_thigh" (
        apiSchemas = ["PhysicsRigidBodyAPI", "PhysicsMassAPI"]
    )
    {
        point3f physics:centerOfMass = (0, 0, -0.2191248)
        float3 physics:diagonalInertia = (0.01086859, 0.01086859, 0.0031678802)
        float physics:mass = 0.58010125
        quatf physics:principalAxes = (1, 0, 0, 0)
        quatd xformOp:orient = (1, 0, 0, 0)
        double3 xformOp:scale = (1, 1, 1)
        double3 xformOp:translate = (0.4236612617969513, -0.20792853832244873, -0.1181042343378067)
        uniform token[] xformOpOrder = ["xformOp:translate", "xformOp:orient", "xformOp:scale"]

        def Cylinder "visuals"
        {
            uniform token axis = "Z"
            float3[] extent = [(-0.104507506, -0.104507506, -0.2191248), (0.104507506, 0.104507506, 0.2191248)]
            double height = 0.4382495880126953
            double radius = 0.10450750589370728
            quatd xformOp:orient = (1, 0, 0, 0)
            double3 xformOp:scale = (1, 1, 1)
            double3 xformOp:translate = (0, 0, -0.21912479400634766)
            uniform token[] xformOpOrder = ["xformOp:translate", "xformOp:orient", "xformOp:scale"]
        }

        def Cylinder "collisions" (
            apiSchemas = ["PhysicsCollisionAPI"]
        )
        {
            uniform token axis = "Z"
            float3[] extent = [(-0.104507506, -0.104507506, -0.2191248), (0.104507506, 0.104507506, 0.2191248)]
            double height = 0.4382495880126953
            uniform token purpose = "guide"
            double radius = 0.10450750589370728
            quatd xformOp:orient = (1, 0, 0, 0)
            double3 xformOp:scale = (1, 1, 1)
            double3 xformOp:translate = (0, 0, -0.21912479400634766)
            uniform token[] xformOpOrder = ["xformOp:translate", "xformOp:orient", "xformOp:scale"]
        }

        def PhysicsFixedJoint "FR_knee_joint"
        {
            rel physics:body0 = </quadruped_robot/FR_thigh>
            rel physics:body1 = </quadruped_robot/FR_knee>
            float physics:breakForce = 3.4028235e38
            float physics:breakTorque = 3.4028235e38
            point3f physics:localPos0 = (0, 0, -0.4382496)
            point3f physics:localPos1 = (0, 0, 0)
            quatf physics:localRot0 = (1, 0, 0, 0)
            quatf physics:localRot1 = (1, 0, 0, 0)
        }
    }

    def Xform "FR_knee" (
        apiSchemas = ["PhysicsRigidBodyAPI", "PhysicsMassAPI"]
    )
    {
        point3f physics:centerOfMass = (0, 0, 0.104507506)
        float3 physics:diagonalInertia = (0.008455066, 0.008455066, 0.008455066)
        float physics:mass = 1.9353613
        quatf physics:principalAxes = (1, 0, 0, 0)
        quatd xformOp:orient = (1, 0, 0, 0)
        double3 xformOp:scale = (1, 1, 1)
        double3 xformOp:translate = (0.4236612617969513, -0.20792853832244873, -0.5563538074493408)
        uniform token[] xformOpOrder = ["xformOp:translate", "xformOp:orient", "xformOp:scale"]

        def Sphere "visuals"
        {
            float3[] extent = [(-0.104507506, -0.104507506, -0.104507506), (0.104507506, 0.104507506, 0.104507506)]
            double radius = 0.10450750589370728
            quatd xformOp:orient = (1, 0, 0, 0)
            double3 xformOp:scale = (1, 1, 1)
            double3 xformOp:translate = (0, 0, 0)
            uniform token[] xformOpOrder = ["xformOp:translate", "xformOp:orient", "xformOp:scale"]
        }

        def Sphere "collisions" (
            apiSchemas = ["PhysicsCollisionAPI"]
        )
        {
            float3[] extent = [(-0.104507506, -0.104507506, -0.104507506), (0.104507506, 0.104507506, 0.104507506)]
            uniform token purpose = "guide"
            double radius = 0.10450750589370728
            quatd xformOp:orient = (1, 0, 0, 0)
            double3 xformOp:scale = (1, 1, 1)
            double3 xformOp:translate = (0, 0, 0)
            uniform token[] xformOpOrder = ["xformOp:translate", "xformOp:orient", "xformOp:scale"]
        }

        def PhysicsRevoluteJoint "FR_calf_joint" (
            apiSchemas = ["PhysxJointAPI", "PhysicsJointStateAPI:angular", "PhysicsDriveAPI:angular"]
        )
        {
            float drive:angular:physics:damping = 0
            float drive:angular:physics:maxForce = 60
            float drive:angular:physics:stiffness = 0
            uniform token drive:angular:physics:type = "force"
            uniform token physics:axis = "Y"
            rel physics:body0 = </quadruped_robot/FR_knee>
            rel physics:body1 = </quadruped_robot/FR_calf>
            float physics:breakForce = 3.4028235e38
            float physics:breakTorque = 3.4028235e38
            point3f physics:localPos0 = (0, 0, 0)
            point3f physics:localPos1 = (0, 0, 0)
            quatf physics:localRot0 = (1, 0, 0, 0)
            quatf physics:localRot1 = (1, 0, 0, 0)
            float physics:lowerLimit = -180
            float physics:upperLimit = 180
            float physxJoint:maxJointVelocity = 3002.2988
        }
    }

    def Xform "FR_calf" (
        apiSchemas = ["PhysicsRigidBodyAPI", "PhysicsMassAPI"]
    )
    {
        point3f physics:centerOfMass = (0, 0, -0.23920994)
        float3 physics:diagonalInertia = (0.041337453, 0.041337453, 0.009163149)
        float physics:mass = 1.927035
        quatf physics:principalAxes = (1, 0, 0, 0)
        quatd xformOp:orient = (1, 0, 0, 0)
        double3 xformOp:scale = (1, 1, 1)
        double3 xformOp:translate = (0.4236612617969513, -0.20792853832244873, -0.5563538074493408)
        uniform token[] xformOpOrder = ["xformOp:translate", "xformOp:orient", "xformOp:scale"]

        def Cylinder "visuals"
        {
            uniform token axis = "Z"
            float3[] extent = [(-0.09751975, -0.09751975, -0.23920994), (0.09751975, 0.09751975, 0.23920994)]
            double height = 0.47841987013816833
            double radius = 0.09751974791288376
            quatd xformOp:orient = (1, 0, 0, 0)
            double3 xformOp:scale = (1, 1, 1)
            double3 xformOp:translate = (0, 0, -0.23920993506908417)
            uniform token[] xformOpOrder = ["xformOp:translate", "xformOp:orient", "xformOp:scale"]
        }

        def Cylinder "collisions" (
            apiSchemas = ["PhysicsCollisionAPI"]
        )
        {
            uniform token axis = "Z"
            float3[] extent = [(-0.09751975, -0.09751975, -0.23920994), (0.09751975, 0.09751975, 0.23920994)]
            double height = 0.47841987013816833
            uniform token purpose = "guide"
            double radius = 0.09751974791288376
            quatd xformOp:orient = (1, 0, 0, 0)
            double3 xformOp:scale = (1, 1, 1)
            double3 xformOp:translate = (0, 0, -0.23920993506908417)
            uniform token[] xformOpOrder = ["xformOp:translate", "xformOp:orient", "xformOp:scale"]
        }

        def PhysicsFixedJoint "FR_foot_joint"
        {
            rel physics:body0 = </quadruped_robot/FR_calf>
            rel physics:body1 = </quadruped_robot/FR_foot>
            float physics:breakForce = 3.4028235e38
            float physics:breakTorque = 3.4028235e38
            point3f physics:localPos0 = (0, 0, -0.47841987)
            point3f physics:localPos1 = (0, 0, 0)
            quatf physics:localRot0 = (1, 0, 0, 0)
            quatf physics:localRot1 = (1, 0, 0, 0)
        }
    }

    def Xform "FR_foot" (
        apiSchemas = ["PhysicsRigidBodyAPI", "PhysicsMassAPI"]
    )
    {
        point3f physics:centerOfMass = (0, 0, 0.06826382)
        float3 physics:diagonalInertia = (0.0018735921, 0.0018735921, 0.0018735921)
        float physics:mass = 1.0051569
        quatf physics:principalAxes = (1, 0, 0, 0)
        quatd xformOp:orient = (1, 0, 0, 0)
        double3 xformOp:scale = (1, 1, 1)
        double3 xformOp:translate = (0.4236612617969513, -0.20792853832244873, -1.0347737073898315)
        uniform token[] xformOpOrder = ["xformOp:translate", "xformOp:orient", "xformOp:scale"]

        def Sphere "visuals"
        {
            float3[] extent = [(-0.06826382, -0.06826382, -0.06826382), (0.06826382, 0.06826382, 0.06826382)]
            double radius = 0.06826382130384445
            quatd xformOp:orient = (1, 0, 0, 0)
            double3 xformOp:scale = (1, 1, 1)
            double3 xformOp:translate = (0, 0, 0)
            uniform token[] xformOpOrder = ["xformOp:translate", "xformOp:orient", "xformOp:scale"]
        }

        def Sphere "collisions" (
            apiSchemas = ["PhysicsCollisionAPI"]
        )
        {
            float3[] extent = [(-0.06826382, -0.06826382, -0.06826382), (0.06826382, 0.06826382, 0.06826382)]
            uniform token purpose = "guide"
            double radius = 0.06826382130384445
            quatd xformOp:orient = (1, 0, 0, 0)
            double3 xformOp:scale = (1, 1, 1)
            double3 xformOp:translate = (0, 0, 0)
            uniform token[] xformOpOrder = ["xformOp:translate", "xformOp:orient", "xformOp:scale"]
        }
    }

    def Xform "RL_hip" (
        apiSchemas = ["PhysicsRigidBodyAPI", "PhysicsMassAPI"]
    )
    {
        point3f physics:centerOfMass = (0, 0, 0.10261395)
        float3 physics:diagonalInertia = (0.0031985564, 0.0031985564, 0.0031985564)
        float physics:mass = 0.75941855
        quatf physics:principalAxes = (1, 0, 0, 0)
        quatd xformOp:orient = (1, 0, 0, 0)
        double3 xformOp:scale = (1, 1, 1)
        double3 xformOp:translate = (-0.4236612617969513, 0.20792853832244873, -0.1181042343378067)
        uniform token[] xformOpOrder = ["xformOp:translate", "xformOp:orient", "xformOp:scale"]

        def Sphere "visuals"
        {
            float3[] extent = [(-0.10261395, -0.10261395, -0.10261395), (0.10261395, 0.10261395, 0.10261395)]
            double radius = 0.10261394828557968
            quatd xformOp:orient = (1, 0, 0, 0)
            double3 xformOp:scale = (1, 1, 1)
            double3 xformOp:translate = (0, 0, 0)
            uniform token[] xformOpOrder = ["xformOp:translate", "xformOp:orient", "xformOp:scale"]
        }

        def Sphere "collisions" (
            apiSchemas = ["PhysicsCollisionAPI"]
        )
        {
            float3[] extent = [(-0.10261395, -0.10261395, -0.10261395), (0.10261395, 0.10261395, 0.10261395)]
            uniform token purpose = "guide"
            double radius = 0.10261394828557968
            quatd xformOp:orient = (1, 0, 0, 0)
            double3 xformOp:scale = (1, 1, 1)
            double3 xformOp:translate = (0, 0, 0)
            uniform token[] xformOpOrder = ["xformOp:translate", "xformOp:orient", "xformOp:scale"]
        }

        def PhysicsRevoluteJoint "RL_thigh_joint" (
            apiSchemas = ["PhysxJointAPI", "PhysicsJointStateAPI:angular", "PhysicsDriveAPI:angular"]
        )
        {
            float drive:angular:physics:damping = 0
            float drive:angular:physics:maxForce = 60
            float drive:angular:physics:stiffness = 0
            uniform token drive:angular:physics:type = "force"
            uniform token physics:axis = "Y"
            rel physics:body0 = </quadruped_robot/RL_hip>
            rel physics:body1 = </quadruped_robot/RL_thigh>
            float physics:breakForce = 3.4028235e38
            float physics:breakTorque = 3.4028235e38
            point3f physics:localPos0 = (0, 0, 0)
            point3f physics:localPos1 = (0, 0, 0)
            quatf physics:localRot0 = (1, 0, 0, 0)
            quatf physics:localRot1 = (1, 0, 0, 0)
            float physics:lowerLimit = -180
            float physics:upperLimit = 180
            float physxJoint:maxJointVelocity = 3002.2988
        }
    }

    def Xform "RL_thigh" (
        apiSchemas = ["PhysicsRigidBodyAPI", "PhysicsMassAPI"]
    )
    {
        point3f physics:centerOfMass = (0, 0, -0.15347417)
        float3 physics:diagonalInertia = (0.013403852, 0.013403852, 0.00673119)
        float physics:mass = 1.2785244
        quatf physics:principalAxes = (1, 0, 0, 0)
        quatd xformOp:orient = (1, 0, 0, 0)
        double3 xformOp:scale = (1, 1, 1)
        double3 xformOp:translate = (-0.4236612617969513, 0.20792853832244873, -0.1181042343378067)
        uniform token[] xformOpOrder = ["xformOp:translate", "xformOp:orient", "xformOp:scale"]

        def Cylinder "visuals"
        {
            uniform token axis = "Z"
            float3[] extent = [(-0.10261395, -0.10261395, -0.15347417), (0.10261395, 0.10261395, 0.15347417)]
            double height = 0.30694833397865295
            double radius = 0.10261394828557968
            quatd xformOp:orient = (1, 0, 0, 0)
            double3 xformOp:scale = (1, 1, 1)
            double3 xformOp:translate = (0, 0, -0.15347416698932648)
            uniform token[] xformOpOrder = ["xformOp:translate", "xformOp:orient", "xformOp:scale"]
        }

        def Cylinder "collisions" (
            apiSchemas = ["PhysicsCollisionAPI"]
        )
        {
            uniform token axis = "Z"
            float3[] extent = [(-0.10261395, -0.10261395, -0.15347417), (0.10261395, 0.10261395, 0.15347417)]
            double height = 0.30694833397865295
            uniform token purpose = "guide"
            double radius = 0.10261394828557968
            quatd xformOp:orient = (1, 0, 0, 0)
            double3 xformOp:scale = (1, 1, 1)
            double3 xformOp:translate = (0, 0, -0.15347416698932648)
            uniform token[] xformOpOrder = ["xformOp:translate", "xformOp:orient", "xformOp:scale"]
        }

        def PhysicsFixedJoint "RL_knee_joint"
        {
            rel physics:body0 = </quadruped_robot/RL_thigh>
            rel physics:body1 = </quadruped_robot/RL_knee>
            float physics:breakForce = 3.4028235e38
            float physics:breakTorque = 3.4028235e38
            point3f physics:localPos0 = (0, 0, -0.30694833)
            point3f physics:localPos1 = (0, 0, 0)
            quatf physics:localRot0 = (1, 0, 0, 0)
            quatf physics:localRot1 = (1, 0, 0, 0)
        }
    }

    def Xform "RL_knee" (
        apiSchemas = ["PhysicsRigidBodyAPI", "PhysicsMassAPI"]
    )
    {
        point3f physics:centerOfMass = (0, 0, 0.10954718)
        float3 physics:diagonalInertia = (0.0077983313, 0.0077983313, 0.0077983313)
        float physics:mass = 1.6245732
        quatf physics:principalAxes = (1, 0, 0, 0)
        quatd xformOp:orient = (1, 0, 0, 0)
        double3 xformOp:scale = (1, 1, 1)
        double3 xformOp:translate = (-0.4236612617969513, 0.20792853832244873, -0.42505258321762085)
        uniform token[] xformOpOrder = ["xformOp:translate", "xformOp:orient", "xformOp:scale"]

        def Sphere "visuals"
        {
            float3[] extent = [(-0.10954718, -0.10954718, -0.10954718), (0.10954718, 0.10954718, 0.10954718)]
            double radius = 0.10954718291759491
            quatd xformOp:orient = (1, 0, 0, 0)
            double3 xformOp:scale = (1, 1, 1)
            double3 xformOp:translate = (0, 0, 0)
            uniform token[] xformOpOrder = ["xformOp:translate", "xformOp:orient", "xformOp:scale"]
        }

        def Sphere "collisions" (
            apiSchemas = ["PhysicsCollisionAPI"]
        )
        {
            float3[] extent = [(-0.10954718, -0.10954718, -0.10954718), (0.10954718, 0.10954718, 0.10954718)]
            uniform token purpose = "guide"
            double radius = 0.10954718291759491
            quatd xformOp:orient = (1, 0, 0, 0)
            double3 xformOp:scale = (1, 1, 1)
            double3 xformOp:translate = (0, 0, 0)
            uniform token[] xformOpOrder = ["xformOp:translate", "xformOp:orient", "xformOp:scale"]
        }

        def PhysicsRevoluteJoint "RL_calf_joint" (
            apiSchemas = ["PhysxJointAPI", "PhysicsJointStateAPI:angular", "PhysicsDriveAPI:angular"]
        )
        {
            float drive:angular:physics:damping = 0
            float drive:angular:physics:maxForce = 60
            float drive:angular:physics:stiffness = 0
            uniform token drive:angular:physics:type = "force"
            uniform token physics:axis = "Y"
            rel physics:body0 = </quadruped_robot/RL_knee>
            rel physics:body1 = </quadruped_robot/RL_calf>
            float physics:breakForce = 3.4028235e38
            float physics:breakTorque = 3.4028235e38
            point3f physics:localPos0 = (0, 0, 0)
            point3f physics:localPos1 = (0, 0, 0)
            quatf physics:localRot0 = (1, 0, 0, 0)
            quatf physics:localRot1 = (1, 0, 0, 0)
            float physics:lowerLimit = -180
            float physics:upperLimit = 180
            float physxJoint:maxJointVelocity = 3002.2988
        }
    }

    def Xform "RL_calf" (
        apiSchemas = ["PhysicsRigidBodyAPI", "PhysicsMassAPI"]
    )
    {
        point3f physics:centerOfMass = (0, 0, -0.2611862)
        float3 physics:diagonalInertia = (0.030768838, 0.030768838, 0.0071726954)
        float physics:mass = 1.195391
        quatf physics:principalAxes = (1, 0, 0, 0)
        quatd xformOp:orient = (1, 0, 0, 0)
        double3 xformOp:scale = (1, 1, 1)
        double3 xformOp:translate = (-0.4236612617969513, 0.20792853832244873, -0.42505258321762085)
        uniform token[] xformOpOrder = ["xformOp:translate", "xformOp:orient", "xformOp:scale"]

        def Cylinder "visuals"
        {
            uniform token axis = "Z"
            float3[] extent = [(-0.10954718, -0.10954718, -0.2611862), (0.10954718, 0.10954718, 0.2611862)]
            double height = 0.5223724246025085
            double radius = 0.10954718291759491
            quatd xformOp:orient = (1, 0, 0, 0)
            double3 xformOp:scale = (1, 1, 1)
            double3 xformOp:translate = (0, 0, -0.2611862123012543)
            uniform token[] xformOpOrder = ["xformOp:translate", "xformOp:orient", "xformOp:scale"]
        }

        def Cylinder "collisions" (
            apiSchemas = ["PhysicsCollisionAPI"]
        )
        {
            uniform token axis = "Z"
            float3[] extent = [(-0.10954718, -0.10954718, -0.2611862), (0.10954718, 0.10954718, 0.2611862)]
            double height = 0.5223724246025085
            uniform token purpose = "guide"
            double radius = 0.10954718291759491
            quatd xformOp:orient = (1, 0, 0, 0)
            double3 xformOp:scale = (1, 1, 1)
            double3 xformOp:translate = (0, 0, -0.2611862123012543)
            uniform token[] xformOpOrder = ["xformOp:translate", "xformOp:orient", "xformOp:scale"]
        }

        def PhysicsFixedJoint "RL_foot_joint"
        {
            rel physics:body0 = </quadruped_robot/RL_calf>
            rel physics:body1 = </quadruped_robot/RL_foot>
            float physics:breakForce = 3.4028235e38
            float physics:breakTorque = 3.4028235e38
            point3f physics:localPos0 = (0, 0, -0.5223724)
            point3f physics:localPos1 = (0, 0, 0)
            quatf physics:localRot0 = (1, 0, 0, 0)
            quatf physics:localRot1 = (1, 0, 0, 0)
        }
    }

    def Xform "RL_foot" (
        apiSchemas = ["PhysicsRigidBodyAPI", "PhysicsMassAPI"]
    )
    {
        point3f physics:centerOfMass = (0, 0, 0.06826382)
        float3 physics:diagonalInertia = (0.001157642, 0.001157642, 0.001157642)
        float physics:mass = 0.6210593
        quatf physics:principalAxes = (1, 0, 0, 0)
        quatd xformOp:orient = (1, 0, 0, 0)
        double3 xformOp:scale = (1, 1, 1)
        double3 xformOp:translate = (-0.4236612617969513, 0.20792853832244873, -0.9474250078201294)
        uniform token[] xformOpOrder = ["xformOp:translate", "xformOp:orient", "xformOp:scale"]

        def Sphere "visuals"
        {
            float3[] extent = [(-0.06826382, -0.06826382, -0.06826382), (0.06826382, 0.06826382, 0.06826382)]
            double radius = 0.06826382130384445
            quatd xformOp:orient = (1, 0, 0, 0)
            double3 xformOp:scale = (1, 1, 1)
            double3 xformOp:translate = (0, 0, 0)
            uniform token[] xformOpOrder = ["xformOp:translate", "xformOp:orient", "xformOp:scale"]
        }

        def Sphere "collisions" (
            apiSchemas = ["PhysicsCollisionAPI"]
        )
        {
            float3[] extent = [(-0.06826382, -0.06826382, -0.06826382), (0.06826382, 0.06826382, 0.06826382)]
            uniform token purpose = "guide"
            double radius = 0.06826382130384445
            quatd xformOp:orient = (1, 0, 0, 0)
            double3 xformOp:scale = (1, 1, 1)
            double3 xformOp:translate = (0, 0, 0)
            uniform token[] xformOpOrder = ["xformOp:translate", "xformOp:orient", "xformOp:scale"]
        }
    }

    def Xform "RR_hip" (
        apiSchemas = ["PhysicsRigidBodyAPI", "PhysicsMassAPI"]
    )
    {
        point3f physics:centerOfMass = (0, 0, 0.10261395)
        float3 physics:diagonalInertia = (0.00559425, 0.00559425, 0.00559425)
        float physics:mass = 1.328217
        quatf physics:principalAxes = (1, 0, 0, 0)
        quatd xformOp:orient = (1, 0, 0, 0)
        double3 xformOp:scale = (1, 1, 1)
        double3 xformOp:translate = (-0.4236612617969513, -0.20792853832244873, -0.1181042343378067)
        uniform token[] xformOpOrder = ["xformOp:translate", "xformOp:orient", "xformOp:scale"]

        def Sphere "visuals"
        {
            float3[] extent = [(-0.10261395, -0.10261395, -0.10261395), (0.10261395, 0.10261395, 0.10261395)]
            double radius = 0.10261394828557968
            quatd xformOp:orient = (1, 0, 0, 0)
            double3 xformOp:scale = (1, 1, 1)
            double3 xformOp:translate = (0, 0, 0)
            uniform token[] xformOpOrder = ["xformOp:translate", "xformOp:orient", "xformOp:scale"]
        }

        def Sphere "collisions" (
            apiSchemas = ["PhysicsCollisionAPI"]
        )
        {
            float3[] extent = [(-0.10261395, -0.10261395, -0.10261395), (0.10261395, 0.10261395, 0.10261395)]
            uniform token purpose = "guide"
            double radius = 0.10261394828557968
            quatd xformOp:orient = (1, 0, 0, 0)
            double3 xformOp:scale = (1, 1, 1)
            double3 xformOp:translate = (0, 0, 0)
            uniform token[] xformOpOrder = ["xformOp:translate", "xformOp:orient", "xformOp:scale"]
        }

        def PhysicsRevoluteJoint "RR_thigh_joint" (
            apiSchemas = ["PhysxJointAPI", "PhysicsJointStateAPI:angular", "PhysicsDriveAPI:angular"]
        )
        {
            float drive:angular:physics:damping = 0
            float drive:angular:physics:maxForce = 60
            float drive:angular:physics:stiffness = 0
            uniform token drive:angular:physics:type = "force"
            uniform token physics:axis = "Y"
            rel physics:body0 = </quadruped_robot/RR_hip>
            rel physics:body1 = </quadruped_robot/RR_thigh>
            float physics:breakForce = 3.4028235e38
            float physics:breakTorque = 3.4028235e38
            point3f physics:localPos0 = (0, 0, 0)
            point3f physics:localPos1 = (0, 0, 0)
            quatf physics:localRot0 = (1, 0, 0, 0)
            quatf physics:localRot1 = (1, 0, 0, 0)
            float physics:lowerLimit = -180
            float physics:upperLimit = 180
            float physxJoint:maxJointVelocity = 3002.2988
        }
    }

    def Xform "RR_thigh" (
        apiSchemas = ["PhysicsRigidBodyAPI", "PhysicsMassAPI"]
    )
    {
        point3f physics:centerOfMass = (0, 0, -0.15347417)
        float3 physics:diagonalInertia = (0.017602382, 0.017602382, 0.008839621)
        float physics:mass = 1.6790005
        quatf physics:principalAxes = (1, 0, 0, 0)
        quatd xformOp:orient = (1, 0, 0, 0)
        double3 xformOp:scale = (1, 1, 1)
        double3 xformOp:translate = (-0.4236612617969513, -0.20792853832244873, -0.1181042343378067)
        uniform token[] xformOpOrder = ["xformOp:translate", "xformOp:orient", "xformOp:scale"]

        def Cylinder "visuals"
        {
            uniform token axis = "Z"
            float3[] extent = [(-0.10261395, -0.10261395, -0.15347417), (0.10261395, 0.10261395, 0.15347417)]
            double height = 0.30694833397865295
            double radius = 0.10261394828557968
            quatd xformOp:orient = (1, 0, 0, 0)
            double3 xformOp:scale = (1, 1, 1)
            double3 xformOp:translate = (0, 0, -0.15347416698932648)
            uniform token[] xformOpOrder = ["xformOp:translate", "xformOp:orient", "xformOp:scale"]
        }

        def Cylinder "collisions" (
            apiSchemas = ["PhysicsCollisionAPI"]
        )
        {
            uniform token axis = "Z"
            float3[] extent = [(-0.10261395, -0.10261395, -0.15347417), (0.10261395, 0.10261395, 0.15347417)]
            double height = 0.30694833397865295
            uniform token purpose = "guide"
            double radius = 0.10261394828557968
            quatd xformOp:orient = (1, 0, 0, 0)
            double3 xformOp:scale = (1, 1, 1)
            double3 xformOp:translate = (0, 0, -0.15347416698932648)
            uniform token[] xformOpOrder = ["xformOp:translate", "xformOp:orient", "xformOp:scale"]
        }

        def PhysicsFixedJoint "RR_knee_joint"
        {
            rel physics:body0 = </quadruped_robot/RR_thigh>
            rel physics:body1 = </quadruped_robot/RR_knee>
            float physics:breakForce = 3.4028235e38
            float physics:breakTorque = 3.4028235e38
            point3f physics:localPos0 = (0, 0, -0.30694833)
            point3f physics:localPos1 = (0, 0, 0)
            quatf physics:localRot0 = (1, 0, 0, 0)
            quatf physics:localRot1 = (1, 0, 0, 0)
        }
    }

    def Xform "RR_knee" (
        apiSchemas = ["PhysicsRigidBodyAPI", "PhysicsMassAPI"]
    )
    {
        point3f physics:centerOfMass = (0, 0, 0.10954718)
        float3 physics:diagonalInertia = (0.0027693184, 0.0027693184, 0.0027693184)
        float physics:mass = 0.57691324
        quatf physics:principalAxes = (1, 0, 0, 0)
        quatd xformOp:orient = (1, 0, 0, 0)
        double3 xformOp:scale = (1, 1, 1)
        double3 xformOp:translate = (-0.4236612617969513, -0.20792853832244873, -0.42505258321762085)
        uniform token[] xformOpOrder = ["xformOp:translate", "xformOp:orient", "xformOp:scale"]

        def Sphere "visuals"
        {
            float3[] extent = [(-0.10954718, -0.10954718, -0.10954718), (0.10954718, 0.10954718, 0.10954718)]
            double radius = 0.10954718291759491
            quatd xformOp:orient = (1, 0, 0, 0)
            double3 xformOp:scale = (1, 1, 1)
            double3 xformOp:translate = (0, 0, 0)
            uniform token[] xformOpOrder = ["xformOp:translate", "xformOp:orient", "xformOp:scale"]
        }

        def Sphere "collisions" (
            apiSchemas = ["PhysicsCollisionAPI"]
        )
        {
            float3[] extent = [(-0.10954718, -0.10954718, -0.10954718), (0.10954718, 0.10954718, 0.10954718)]
            uniform token purpose = "guide"
            double radius = 0.10954718291759491
            quatd xformOp:orient = (1, 0, 0, 0)
            double3 xformOp:scale = (1, 1, 1)
            double3 xformOp:translate = (0, 0, 0)
            uniform token[] xformOpOrder = ["xformOp:translate", "xformOp:orient", "xformOp:scale"]
        }

        def PhysicsRevoluteJoint "RR_calf_joint" (
            apiSchemas = ["PhysxJointAPI", "PhysicsJointStateAPI:angular", "PhysicsDriveAPI:angular"]
        )
        {
            float drive:angular:physics:damping = 0
            float drive:angular:physics:maxForce = 60
            float drive:angular:physics:stiffness = 0
            uniform token drive:angular:physics:type = "force"
            uniform token physics:axis = "Y"
            rel physics:body0 = </quadruped_robot/RR_knee>
            rel physics:body1 = </quadruped_robot/RR_calf>
            float physics:breakForce = 3.4028235e38
            float physics:breakTorque = 3.4028235e38
            point3f physics:localPos0 = (0, 0, 0)
            point3f physics:localPos1 = (0, 0, 0)
            quatf physics:localRot0 = (1, 0, 0, 0)
            quatf physics:localRot1 = (1, 0, 0, 0)
            float physics:lowerLimit = -180
            float physics:upperLimit = 180
            float physxJoint:maxJointVelocity = 3002.2988
        }
    }

    def Xform "RR_calf" (
        apiSchemas = ["PhysicsRigidBodyAPI", "PhysicsMassAPI"]
    )
    {
        point3f physics:centerOfMass = (0, 0, -0.2611862)
        float3 physics:diagonalInertia = (0.015701534, 0.015701534, 0.0036602726)
        float physics:mass = 0.6100157
        quatf physics:principalAxes = (1, 0, 0, 0)
        quatd xformOp:orient = (1, 0, 0, 0)
        double3 xformOp:scale = (1, 1, 1)
        double3 xformOp:translate = (-0.4236612617969513, -0.20792853832244873, -0.42505258321762085)
        uniform token[] xformOpOrder = ["xformOp:translate", "xformOp:orient", "xformOp:scale"]

        def Cylinder "visuals"
        {
            uniform token axis = "Z"
            float3[] extent = [(-0.10954718, -0.10954718, -0.2611862), (0.10954718, 0.10954718, 0.2611862)]
            double height = 0.5223724246025085
            double radius = 0.10954718291759491
            quatd xformOp:orient = (1, 0, 0, 0)
            double3 xformOp:scale = (1, 1, 1)
            double3 xformOp:translate = (0, 0, -0.2611862123012543)
            uniform token[] xformOpOrder = ["xformOp:translate", "xformOp:orient", "xformOp:scale"]
        }

        def Cylinder "collisions" (
            apiSchemas = ["PhysicsCollisionAPI"]
        )
        {
            uniform token axis = "Z"
            float3[] extent = [(-0.10954718, -0.10954718, -0.2611862), (0.10954718, 0.10954718, 0.2611862)]
            double height = 0.5223724246025085
            uniform token purpose = "guide"
            double radius = 0.10954718291759491
            quatd xformOp:orient = (1, 0, 0, 0)
            double3 xformOp:scale = (1, 1, 1)
            double3 xformOp:translate = (0, 0, -0.2611862123012543)
            uniform token[] xformOpOrder = ["xformOp:translate", "xformOp:orient", "xformOp:scale"]
        }

        def PhysicsFixedJoint "RR_foot_joint"
        {
            rel physics:body0 = </quadruped_robot/RR_calf>
            rel physics:body1 = </quadruped_robot/RR_foot>
            float physics:breakForce = 3.4028235e38
            float physics:breakTorque = 3.4028235e38
            point3f physics:localPos0 = (0, 0, -0.5223724)
            point3f physics:localPos1 = (0, 0, 0)
            quatf physics:localRot0 = (1, 0, 0, 0)
            quatf physics:localRot1 = (1, 0, 0, 0)
        }
    }

    def Xform "RR_foot" (
        apiSchemas = ["PhysicsRigidBodyAPI", "PhysicsMassAPI"]
    )
    {
        point3f physics:centerOfMass = (0, 0, 0.06826382)
        float3 physics:diagonalInertia = (0.0026255508, 0.0026255508, 0.0026255508)
        float physics:mass = 1.4085726
        quatf physics:principalAxes = (1, 0, 0, 0)
        quatd xformOp:orient = (1, 0, 0, 0)
        double3 xformOp:scale = (1, 1, 1)
        double3 xformOp:translate = (-0.4236612617969513, -0.20792853832244873, -0.9474250078201294)
        uniform token[] xformOpOrder = ["xformOp:translate", "xformOp:orient", "xformOp:scale"]

        def Sphere "visuals"
        {
            float3[] extent = [(-0.06826382, -0.06826382, -0.06826382), (0.06826382, 0.06826382, 0.06826382)]
            double radius = 0.06826382130384445
            quatd xformOp:orient = (1, 0, 0, 0)
            double3 xformOp:scale = (1, 1, 1)
            double3 xformOp:translate = (0, 0, 0)
            uniform token[] xformOpOrder = ["xformOp:translate", "xformOp:orient", "xformOp:scale"]
        }

        def Sphere "collisions" (
            apiSchemas = ["PhysicsCollisionAPI"]
        )
        {
            float3[] extent = [(-0.06826382, -0.06826382, -0.06826382), (0.06826382, 0.06826382, 0.06826382)]
            uniform token purpose = "guide"
            double radius = 0.06826382130384445
            quatd xformOp:orient = (1, 0, 0, 0)
            double3 xformOp:scale = (1, 1, 1)
            double3 xformOp:translate = (0, 0, 0)
            uniform token[] xformOpOrder = ["xformOp:translate", "xformOp:orient", "xformOp:scale"]
        }
    }
}

